{"op":"mcm","clk":"11742740098","pt":1722416208308,"mc":[{"id":"1.231282333","marketDefinition":{"bspMarket":false,"turnInPlayEnabled":true,"persistenceEnabled":true,"marketBaseRate":5.0,"eventId":"33457836","eventTypeId":"4","numberOfWinners":1,"bettingType":"ODDS","marketType":"MATCH_ODDS","marketTime":"2024-08-03T15:00:00.000Z","suspendTime":"2024-08-03T15:00:00.000Z","bspReconciled":false,"complete":true,"inPlay":false,"crossMatching":true,"runnersVoidable":false,"numberOfActiveRunners":2,"betDelay":0,"status":"OPEN","runners":[{"status":"ACTIVE","sortPriority":1,"id":25173012,"name":"Brampton Wolves"},{"status":"ACTIVE","sortPriority":2,"id":71847983,"name":"Mississauga Bangla Tigers"}],"regulators":["MR_INT"],"countryCode":"GB","discountAllowed":false,"timezone":"GMT","openDate":"2024-08-03T15:00:00.000Z","version":6048540610,"name":"Match Odds","eventName":"Brampton Wolves v Mississauga Bangla Tigers"},"rc":[{"batb":[[0,1.02,200],[1,1.01,220]],"ltp":0.0,"tv":0.0,"id":71847983},{"batb":[[0,1.03,200],[1,1.02,200],[2,1.01,220]],"ltp":0.0,"tv":0.0,"id":25173012}]}]}
{"op":"mcm","clk":"11742740105","pt":1722416208410,"mc":[{"id":"1.231282333","rc":[{"batb":[[0,1.03,200],[1,1.02,200],[2,1.01,220]],"ltp":0.0,"tv":0.0,"id":71847983}]}]}
{"op":"mcm","clk":"11742740173","pt":1722416209415,"mc":[{"id":"1.231282333","marketDefinition":{"bspMarket":false,"turnInPlayEnabled":true,"persistenceEnabled":true,"marketBaseRate":5.0,"eventId":"33457836","eventTypeId":"4","numberOfWinners":1,"bettingType":"ODDS","marketType":"MATCH_ODDS","marketTime":"2024-08-03T15:00:00.000Z","suspendTime":"2024-08-03T15:00:00.000Z","bspReconciled":false,"complete":true,"inPlay":false,"crossMatching":true,"runnersVoidable":false,"numberOfActiveRunners":2,"betDelay":0,"status":"OPEN","runners":[{"status":"ACTIVE","sortPriority":1,"id":25173012,"name":"Brampton Wolves"},{"status":"ACTIVE","sortPriority":2,"id":71847983,"name":"Mississauga Bangla Tigers"}],"regulators":["MR_INT"],"countryCode":"GB","discountAllowed":true,"timezone":"GMT","openDate":"2024-08-03T15:00:00.000Z","version":6048540610,"name":"Match Odds","eventName":"Brampton Wolves v Mississauga Bangla Tigers"}}]}
{"op":"mcm","clk":"11742743498","pt":1722416291343,"mc":[{"id":"1.231282333","rc":[{"batb":[[2,1.01,6315.2]],"ltp":0.0,"tv":0.0,"id":25173012}]}]}
{"op":"mcm","clk":"11742743527","pt":1722416292220,"mc":[{"id":"1.231282333","rc":[{"batb":[[0,1.04,1606.57],[1,1.03,2326.37],[2,1.02,3339.85]],"ltp":0.0,"tv":0.0,"id":71847983},{"batb":[[0,1.04,1606.57],[1,1.03,2326.37],[2,1.02,3339.85]],"ltp":0.0,"tv":0.0,"id":25173012}]}]}
{"op":"mcm","clk":"11742870371","pt":1722418367802,"mc":[{"id":"1.231282333","rc":[{"batb":[[0,1.05,100],[1,1.04,1608.88],[2,1.03,2329.42]],"ltp":0.0,"tv":0.0,"id":71847983},{"batb":[[0,1.05,100],[1,1.04,1608.88],[2,1.03,2329.42]],"ltp":0.0,"tv":0.0,"id":25173012}]}]}
{"op":"mcm","clk":"11743635919","pt":1722431575021,"mc":[{"id":"1.231282333","rc":[{"batb":[[1,1.04,1609.28],[2,1.03,2329.96]],"ltp":0.0,"tv":0.0,"id":71847983},{"batb":[[1,1.04,1609.28],[2,1.03,2329.96]],"ltp":0.0,"tv":0.0,"id":25173012}]}]}
{"op":"mcm","clk":"11743980446","pt":1722436975022,"mc":[{"id":"1.231282333","rc":[{"batb":[[1,1.04,1610.23],[2,1.03,2331.22]],"ltp":0.0,"tv":0.0,"id":71847983},{"batb":[[1,1.04,1610.23],[2,1.03,2331.22]],"ltp":0.0,"tv":0.0,"id":25173012}]}]}
{"op":"mcm","clk":"11744182821","pt":1722439188902,"mc":[{"id":"1.231282333","rc":[{"batb":[[1,1.04,1606.44],[2,1.03,2326.19]],"ltp":0.0,"tv":0.0,"id":71847983},{"batb":[[0,1.05,100.91],[1,1.04,1606.44],[2,1.03,2326.19]],"ltp":0.0,"tv":0.0,"id":25173012}]}]}
{"op":"mcm","clk":"11744184033","pt":1722439199905,"mc":[{"id":"1.231282333","rc":[{"batb":[[0,1.05,100.91]],"ltp":0.0,"tv":0.0,"id":71847983}]}]}
{"op":"mcm","clk":"11744516992","pt":1722442375028,"mc":[{"id":"1.231282333","rc":[{"batb":[[1,1.04,1607.52],[2,1.03,2327.62]],"ltp":0.0,"tv":0.0,"id":71847983},{"batb":[[1,1.04,1607.52],[2,1.03,2327.62]],"ltp":0.0,"tv":0.0,"id":25173012}]}]}
{"op":"mcm","clk":"11744979018","pt":1722446316862,"mc":[{"id":"1.231282333","rc":[{"batb":[[0,1.25,200],[1,1.05,100.91],[2,1.04,1605.89]],"ltp":0.0,"tv":0.0,"id":71847983},{"batb":[[0,1.25,200],[1,1.05,100.91],[2,1.04,1605.89]],"ltp":0.0,"tv":0.0,"id":25173012}]}]}
{"op":"mcm","clk":"11745251196","pt":1722447782386,"mc":[{"id":"1.231282333","rc":[{"batb":[[0,1.26,7.6],[1,1.25,200],[2,1.05,100.91]],"ltp":0.0,"tv":0.0,"id":71847983},{"batb":[[0,1.26,6.87],[1,1.25,200],[2,1.05,100.91]],"ltp":0.0,"tv":0.0,"id":25173012}]}]}
{"op":"mcm","clk":"11746345546","pt":1722453175036,"mc":[{"id":"1.231282333","rc":[{"batb":[[0,1.26,7.59],[2,1.05,100.91]],"ltp":0.0,"tv":0.0,"id":71847983},{"batb":[[0,1.26,6.86],[2,1.05,100.91]],"ltp":0.0,"tv":0.0,"id":25173012}]}]}
{"op":"mcm","clk":"11746374432","pt":1722453320277,"mc":[{"id":"1.231282333","rc":[{"batb":[[0,1.27,10],[1,1.26,7.59],[2,1.25,200]],"ltp":0.0,"tv":0.0,"id":71847983},{"batb":[[0,1.27,10],[1,1.26,6.86],[2,1.25,200]],"ltp":0.0,"tv":0.0,"id":25173012}]}]}
{"op":"mcm","clk":"11746444539","pt":1722453711754,"mc":[{"id":"1.231282333","rc":[{"batl":[[0,5,0.78]],"ltp":0.0,"tv":0.0,"id":71847983},{"batl":[[0,5,0.78]],"ltp":0.0,"tv":0.0,"id":25173012}]}]}
{"op":"mcm","clk":"11746445778","pt":1722453718973,"mc":[{"id":"1.231282333","rc":[{"batl":[[0,6,1.56]],"ltp":0.0,"tv":0.0,"id":71847983},{"batl":[[0,6,1.56]],"ltp":0.0,"tv":0.0,"id":25173012}]}]}
{"op":"mcm","clk":"11746447157","pt":1722453725892,"mc":[{"id":"1.231282333","rc":[{"batl":[[1,7,0.78]],"ltp":0.0,"tv":0.0,"id":71847983},{"batl":[[1,7,0.78]],"ltp":0.0,"tv":0.0,"id":25173012}]}]}
{"op":"mcm","clk":"11746811577","pt":1722456105369,"mc":[{"id":"1.231282333","rc":[{"batb":[[1,1.26,7.58]],"ltp":0.0,"tv":0.0,"id":71847983},{"batb":[[1,1.26,6.86]],"ltp":0.0,"tv":0.0,"id":25173012}]}]}
{"op":"mcm","clk":"11747412787","pt":1722463975047,"mc":[{"id":"1.231282333","rc":[{"batb":[[1,1.26,7.58]],"ltp":0.0,"tv":0.0,"id":71847983},{"batb":[[1,1.26,6.86]],"ltp":0.0,"tv":0.0,"id":25173012}]}]}
{"op":"mcm","clk":"11747702571","pt":1722469375005,"mc":[{"id":"1.231282333","rc":[{"batb":[[1,1.26,7.58]],"ltp":0.0,"tv":0.0,"id":71847983},{"batb":[[1,1.26,6.86]],"ltp":0.0,"tv":0.0,"id":25173012}]}]}
{"op":"mcm","clk":"11747988973","pt":1722474775019,"mc":[{"id":"1.231282333","rc":[{"batb":[[1,1.26,7.59]],"ltp":0.0,"tv":0.0,"id":71847983},{"batb":[[1,1.26,6.86]],"ltp":0.0,"tv":0.0,"id":25173012}]}]}
{"op":"mcm","clk":"11748592840","pt":1722490975048,"mc":[{"id":"1.231282333","rc":[{"batb":[[1,1.26,7.59]],"ltp":0.0,"tv":0.0,"id":71847983},{"batb":[[1,1.26,6.86]],"ltp":0.0,"tv":0.0,"id":25173012}]}]}
{"op":"mcm","clk":"11748731952","pt":1722496375022,"mc":[{"id":"1.231282333","rc":[{"batb":[[1,1.26,7.61]],"batl":[[0,6,1.56],[1,7,0.78]],"ltp":0.0,"tv":0.0,"id":71847983},{"batb":[[1,1.26,6.89]],"batl":[[0,6,1.56],[1,7,0.78]],"ltp":0.0,"tv":0.0,"id":25173012}]}]}
{"op":"mcm","clk":"11748842042","pt":1722500082803,"mc":[{"id":"1.231282333","rc":[{"batb":[[0,1.27,10.91],[1,1.26,7.62]],"batl":[[0,6,1.56]],"ltp":0.0,"tv":0.0,"id":71847983},{"batb":[[1,1.26,6.9]],"batl":[[0,6,1.56]],"ltp":0.0,"tv":0.0,"id":25173012}]}]}
{"op":"mcm","clk":"11749138987","pt":1722507175097,"mc":[{"id":"1.231282333","rc":[{"batb":[[0,1.27,10.91],[1,1.26,7.64]],"batl":[[0,6,1.57],[1,7,0.78]],"ltp":0.0,"tv":0.0,"id":71847983},{"batb":[[1,1.26,6.91]],"batl":[[0,6,1.57],[1,7,0.78]],"ltp":0.0,"tv":0.0,"id":25173012}]}]}
{"op":"mcm","clk":"11749471923","pt":1722512575141,"mc":[{"id":"1.231282333","rc":[{"batb":[[0,1.27,10.91],[1,1.26,7.63]],"batl":[[0,6,1.57],[1,7,0.78]],"ltp":0.0,"tv":0.0,"id":71847983},{"batb":[[1,1.26,6.9]],"batl":[[0,6,1.57],[1,7,0.78]],"ltp":0.0,"tv":0.0,"id":25173012}]}]}
{"op":"mcm","clk":"11749818238","pt":1722517975125,"mc":[{"id":"1.231282333","rc":[{"batb":[[0,1.27,10.91],[1,1.26,7.61]],"batl":[[0,6,1.56],[1,7,0.78]],"ltp":0.0,"tv":0.0,"id":71847983},{"batb":[[1,1.26,6.89]],"batl":[[0,6,1.56],[1,7,0.78]],"ltp":0.0,"tv":0.0,"id":25173012}]}]}
{"op":"mcm","clk":"11750313268","pt":1722523375112,"mc":[{"id":"1.231282333","rc":[{"batb":[[1,1.26,7.6]],"batl":[[0,6,1.56]],"ltp":0.0,"tv":0.0,"id":71847983},{"batb":[[1,1.26,6.88]],"batl":[[0,6,1.56]],"ltp":0.0,"tv":0.0,"id":25173012}]}]}
{"op":"mcm","clk":"11750568494","pt":1722525647606,"mc":[{"id":"1.231282333","rc":[{"batb":[[0,1.27,10.91],[1,1.26,7.62],[2,1.05,100]],"batl":[[0,6,1.56],[1,7,0.78]],"ltp":0.0,"tv":0.0,"id":71847983},{"batb":[[1,1.26,6.89],[2,1.05,100]],"batl":[[0,6,1.56],[1,7,0.78]],"ltp":0.0,"tv":0.0,"id":25173012}]}]}
{"op":"mcm","clk":"11750583999","pt":1722525776677,"mc":[{"id":"1.231282333","rc":[{"batb":[[2,1.25,40]],"ltp":0.0,"tv":0.0,"id":71847983},{"batb":[[2,1.25,40]],"ltp":0.0,"tv":0.0,"id":25173012}]}]}
{"op":"mcm","clk":"11750608595","pt":1722525995745,"mc":[{"id":"1.231282333","rc":[{"batb":[[0,1.27,10.55]],"ltp":0.0,"tv":0.0,"id":25173012}]}]}
{"op":"mcm","clk":"11750609694","pt":1722526004741,"mc":[{"id":"1.231282333","rc":[{"batb":[[0,1.3,1.46],[1,1.27,10],[2,1.26,7.62]],"ltp":0.0,"tv":0.0,"id":71847983}]}]}
{"op":"mcm","clk":"11750631276","pt":1722526200916,"mc":[{"id":"1.231282333","rc":[{"batb":[[2,1.25,40]],"ltp":0.0,"tv":0.0,"id":71847983},{"batb":[[1,1.25,40],[2,1.05,100]],"ltp":0.0,"tv":0.0,"id":25173012}]}]}
{"op":"mcm","clk":"11750727072","pt":1722526947864,"mc":[{"id":"1.231282333","rc":[{"batb":[[0,1.27,10.91],[1,1.25,40],[2,1.05,100]],"ltp":0.0,"tv":0.0,"id":71847983},{"batb":[[0,1.27,10]],"ltp":0.0,"tv":0.0,"id":25173012}]}]}
{"op":"mcm","clk":"11750961956","pt":1722528775151,"mc":[{"id":"1.231282333","rc":[{"batb":[[0,1.27,10.91]],"batl":[[0,6,1.57],[1,7,0.78]],"ltp":0.0,"tv":0.0,"id":71847983},{"batl":[[0,6,1.57],[1,7,0.78]],"ltp":0.0,"tv":0.0,"id":25173012}]}]}
{"op":"mcm","clk":"11751660879","pt":1722534175131,"mc":[{"id":"1.231282333","rc":[{"batb":[[0,1.27,10.91]],"batl":[[0,6,1.57],[1,7,0.78]],"ltp":0.0,"tv":0.0,"id":71847983},{"batl":[[0,6,1.57],[1,7,0.78]],"ltp":0.0,"tv":0.0,"id":25173012}]}]}
{"op":"mcm","clk":"11752018820","pt":1722536640785,"mc":[{"id":"1.231282333","rc":[{"batb":[[0,1.27,10.55]],"ltp":0.0,"tv":0.0,"id":25173012}]}]}
{"op":"mcm","clk":"11752020316","pt":1722536649783,"mc":[{"id":"1.231282333","rc":[{"batb":[[0,1.3,1.46],[1,1.27,10],[2,1.25,40]],"ltp":0.0,"tv":0.0,"id":71847983}]}]}
{"op":"mcm","clk":"11752028918","pt":1722536707084,"mc":[{"id":"1.231282333","rc":[{"trd":[[1.4,0.14]],"batb":[[0,1.3,1.39]],"ltp":1.4,"tv":0.14,"id":71847983}],"tv":0.14}]}
{"op":"mcm","clk":"11752225919","pt":1722537898364,"mc":[{"id":"1.231282333","rc":[{"trd":[[1.4,0.28]],"batb":[[0,1.3,1.32]],"ltp":1.4,"tv":0.28,"id":71847983}],"tv":0.28}]}
{"op":"mcm","clk":"11752393309","pt":1722539119492,"mc":[{"id":"1.231282333","rc":[{"trd":[[1.4,0.42]],"batb":[[0,1.3,1.25]],"batl":[[0,6,1.57]],"ltp":1.4,"tv":0.42,"id":71847983},{"batl":[[0,6,1.57]],"ltp":0.0,"tv":0.0,"id":25173012}],"tv":0.42}]}
{"op":"mcm","clk":"11752413366","pt":1722539251685,"mc":[{"id":"1.231282333","rc":[{"batl":[[0,1.77,200],[1,6,1.57],[2,7,0.79]],"ltp":0.0,"tv":0.0,"id":25173012}]}]}
{"op":"mcm","clk":"11752414826","pt":1722539262093,"mc":[{"id":"1.231282333","rc":[{"batl":[[0,6,1.57],[1,7,0.79],[2,7,0]],"ltp":0.0,"tv":0.0,"id":25173012}]}]}
{"op":"mcm","clk":"11752467166","pt":1722539581005,"mc":[{"id":"1.231282333","rc":[{"batl":[[0,2.26,100],[1,6,1.57],[2,7,0.79]],"ltp":1.4,"tv":0.42,"id":71847983}]}]}
{"op":"mcm","clk":"11752529397","pt":1722540048806,"mc":[{"id":"1.231282333","rc":[{"batl":[[0,6,1.57],[1,7,0.79],[2,7,0]],"ltp":1.4,"tv":0.42,"id":71847983}]}]}
{"op":"mcm","clk":"11752566514","pt":1722540317160,"mc":[{"id":"1.231282333","rc":[{"trd":[[1.4,0.56]],"batb":[[0,1.3,1.18]],"ltp":1.4,"tv":0.56,"id":71847983}],"tv":0.56}]}
{"op":"mcm","clk":"11752674834","pt":1722541214969,"mc":[{"id":"1.231282333","rc":[{"batb":[[0,1.31,10.27],[1,1.25,40.91],[2,1.05,100]],"ltp":1.4,"tv":0.56,"id":71847983}]}]}
{"op":"mcm","clk":"11752885380","pt":1722543338767,"mc":[{"id":"1.231282333","rc":[{"batb":[[0,1.32,26.87],[1,1.31,10],[2,1.25,40.91]],"batl":[[0,6,1.57]],"ltp":1.4,"tv":0.56,"id":71847983},{"batb":[[0,1.28,30.95],[1,1.27,10],[2,1.25,40]],"batl":[[0,6,1.57]],"ltp":0.0,"tv":0.0,"id":25173012}]}]}
{"op":"mcm","clk":"11752918611","pt":1722543790354,"mc":[{"id":"1.231282333","rc":[{"batb":[[0,1.32,36.87],[1,1.25,40.91],[2,1.05,100]],"ltp":1.4,"tv":0.56,"id":71847983},{"batb":[[0,1.29,10.55],[1,1.28,30.4]],"ltp":0.0,"tv":0.0,"id":25173012}]}]}
{"op":"mcm","clk":"11753011081","pt":1722545139240,"mc":[{"id":"1.231282333","rc":[{"batb":[[0,1.32,10.27]],"ltp":1.4,"tv":0.56,"id":71847983},{"batb":[[1,1.25,40],[2,1.05,100]],"ltp":0.0,"tv":0.0,"id":25173012}]}]}
{"op":"mcm","clk":"11753018578","pt":1722545282147,"mc":[{"id":"1.231282333","rc":[{"batb":[[0,1.33,26.06],[1,1.32,10],[2,1.25,40.91]],"ltp":1.4,"tv":0.56,"id":71847983},{"batb":[[0,1.3,28.92],[1,1.29,10],[2,1.25,40]],"ltp":0.0,"tv":0.0,"id":25173012}]}]}
{"op":"mcm","clk":"11753034883","pt":1722545610836,"mc":[{"id":"1.231282333","rc":[{"batb":[[0,1.34,10.27],[1,1.33,25.79]],"ltp":1.4,"tv":0.56,"id":71847983},{"batb":[[0,1.31,10.55],[1,1.3,28.37]],"ltp":0.0,"tv":0.0,"id":25173012}]}]}
{"op":"mcm","clk":"11753098277","pt":1722547082370,"mc":[{"id":"1.231282333","rc":[{"batb":[[1,1.25,40.91],[2,1.05,100]],"ltp":1.4,"tv":0.56,"id":71847983},{"batb":[[1,1.3,28.38]],"ltp":0.0,"tv":0.0,"id":25173012}]}]}
{"op":"mcm","clk":"11753098291","pt":1722547082575,"mc":[{"id":"1.231282333","rc":[{"batb":[[1,1.25,40],[2,1.05,100]],"ltp":0.0,"tv":0.0,"id":25173012}]}]}
{"op":"mcm","clk":"11753098657","pt":1722547092097,"mc":[{"id":"1.231282333","rc":[{"batb":[[0,1.36,15.27],[1,1.34,10],[2,1.25,40.91]],"ltp":1.4,"tv":0.56,"id":71847983},{"batb":[[0,1.32,12.55],[1,1.31,10],[2,1.25,40]],"ltp":0.0,"tv":0.0,"id":25173012}]}]}
{"op":"mcm","clk":"11753102655","pt":1722547199234,"mc":[{"id":"1.231282333","rc":[{"batb":[[0,1.37,23.28],[1,1.36,15],[2,1.34,10]],"ltp":1.4,"tv":0.56,"id":71847983},{"batb":[[0,1.33,26.35],[1,1.32,12],[2,1.31,10]],"ltp":0.0,"tv":0.0,"id":25173012}]}]}
{"op":"mcm","clk":"11753116231","pt":1722547602824,"mc":[{"id":"1.231282333","rc":[{"batb":[[0,1.34,7.79],[1,1.33,25.8],[2,1.32,12]],"ltp":0.0,"tv":0.0,"id":25173012}]}]}
{"op":"mcm","clk":"11753167539","pt":1722548915532,"mc":[{"id":"1.231282333","rc":[{"batb":[[0,1.38,10.27],[1,1.37,23.01],[2,1.36,15]],"ltp":1.4,"tv":0.56,"id":71847983}]}]}
{"op":"mcm","clk":"11753167731","pt":1722548920658,"mc":[{"id":"1.231282333","rc":[{"batb":[[0,1.35,10.55],[1,1.34,7.24],[2,1.33,25.8]],"ltp":0.0,"tv":0.0,"id":25173012}]}]}
{"op":"mcm","clk":"11753170663","pt":1722548999404,"mc":[{"id":"1.231282333","rc":[{"batb":[[2,1.32,12]],"ltp":0.0,"tv":0.0,"id":25173012}]}]}
{"op":"mcm","clk":"11753170673","pt":1722548999610,"mc":[{"id":"1.231282333","rc":[{"batb":[[1,1.36,15],[2,1.25,40.91]],"ltp":1.4,"tv":0.56,"id":71847983}]}]}
{"op":"mcm","clk":"11753175015","pt":1722549104927,"mc":[{"id":"1.231282333","rc":[{"batb":[[0,1.39,22.1],[1,1.38,10],[2,1.36,15]],"ltp":1.4,"tv":0.56,"id":71847983},{"batb":[[0,1.36,24.2],[1,1.35,10],[2,1.34,7.24]],"ltp":0.0,"tv":0.0,"id":25173012}]}]}
{"op":"mcm","clk":"11753188362","pt":1722549502841,"mc":[{"id":"1.231282333","rc":[{"batb":[[0,1.4,10.27],[1,1.39,21.83]],"ltp":1.4,"tv":0.56,"id":71847983},{"batb":[[0,1.37,10.55],[1,1.36,23.65]],"ltp":0.0,"tv":0.0,"id":25173012}]}]}
{"op":"mcm","clk":"11753203483","pt":1722549909000,"mc":[{"id":"1.231282333","rc":[{"trd":[[1.4,0.7]],"batb":[[0,1.4,10.2]],"ltp":1.4,"tv":0.7,"id":71847983}],"tv":0.7}]}
{"op":"mcm","clk":"11753204042","pt":1722549921229,"mc":[{"id":"1.231282333","rc":[{"batb":[[2,1.32,12]],"ltp":0.0,"tv":0.0,"id":25173012}]}]}
{"op":"mcm","clk":"11753250686","pt":1722550913393,"mc":[{"id":"1.231282333","rc":[{"batb":[[1,1.36,15],[2,1.25,40.91]],"ltp":1.4,"tv":0.7,"id":71847983},{"batb":[[1,1.32,12],[2,1.26,7.24]],"ltp":0.0,"tv":0.0,"id":25173012}]}]}
{"op":"mcm","clk":"11753253867","pt":1722551000229,"mc":[{"id":"1.231282333","rc":[{"batb":[[0,1.41,20.77],[1,1.4,10.2],[2,1.36,15]],"ltp":1.4,"tv":0.7,"id":71847983},{"batb":[[0,1.38,22.96],[1,1.37,10],[2,1.32,12]],"ltp":0.0,"tv":0.0,"id":25173012}]}]}
{"op":"mcm","clk":"11753297035","pt":1722552335356,"mc":[{"id":"1.231282333","rc":[{"batb":[[1,1.32,12],[2,1.25,40]],"ltp":0.0,"tv":0.0,"id":25173012}]}]}
{"op":"mcm","clk":"11753297038","pt":1722552335458,"mc":[{"id":"1.231282333","rc":[{"batb":[[0,1.39,10.55],[1,1.38,22.41],[2,1.32,12]],"ltp":0.0,"tv":0.0,"id":25173012}]}]}
{"op":"mcm","clk":"11753297372","pt":1722552345864,"mc":[{"id":"1.231282333","rc":[{"batb":[[0,1.42,10],[1,1.41,20.77],[2,1.36,15.2]],"ltp":1.4,"tv":0.7,"id":71847983}]}]}
{"op":"mcm","clk":"11753314595","pt":1722552800586,"mc":[{"id":"1.231282333","rc":[{"batb":[[1,1.36,15.2],[2,1.25,40.91]],"ltp":1.4,"tv":0.7,"id":71847983},{"batb":[[1,1.32,12],[2,1.25,40]],"ltp":0.0,"tv":0.0,"id":25173012}]}]}
{"op":"mcm","clk":"11753317731","pt":1722552887107,"mc":[{"id":"1.231282333","rc":[{"batb":[[0,1.43,19.8],[1,1.42,10],[2,1.36,15.2]],"ltp":1.4,"tv":0.7,"id":71847983},{"batb":[[0,1.4,21.84],[1,1.39,10],[2,1.32,12]],"ltp":0.0,"tv":0.0,"id":25173012}]}]}
{"op":"mcm","clk":"11753339336","pt":1722553508385,"mc":[{"id":"1.231282333","rc":[{"trd":[[1.5,0.14]],"batb":[[0,1.4,21.77]],"ltp":1.5,"tv":0.14,"id":25173012}],"tv":0.84}]}
{"op":"mcm","clk":"11753381864","pt":1722554687358,"mc":[{"id":"1.231282333","rc":[{"batb":[[0,1.42,10],[1,1.36,15.2],[2,1.25,40.91]],"ltp":1.4,"tv":0.7,"id":71847983}]}]}
{"op":"mcm","clk":"11753381873","pt":1722554687614,"mc":[{"id":"1.231282333","rc":[{"batb":[[0,1.39,10.48],[1,1.32,12],[2,1.25,40]],"ltp":1.5,"tv":0.14,"id":25173012}]}]}
{"op":"mcm","clk":"11753384423","pt":1722554763628,"mc":[{"id":"1.231282333","rc":[{"batb":[[0,1.43,19.8],[1,1.42,10],[2,1.36,15.2]],"ltp":1.4,"tv":0.7,"id":71847983},{"batb":[[0,1.4,21.77],[1,1.39,10],[2,1.32,12]],"ltp":1.5,"tv":0.14,"id":25173012}]}]}
{"op":"mcm","clk":"11753432394","pt":1722555908862,"mc":[{"id":"1.231282333","rc":[{"trd":[[1.5,0.28]],"batb":[[0,1.4,21.7]],"ltp":1.5,"tv":0.28,"id":25173012}],"tv":0.98}]}
{"op":"mcm","clk":"11753459327","pt":1722556564030,"mc":[{"id":"1.231282333","rc":[{"batb":[[0,1.42,10],[1,1.36,15.2],[2,1.25,40.91]],"ltp":1.4,"tv":0.7,"id":71847983},{"batb":[[0,1.39,10.41],[1,1.32,12],[2,1.25,40]],"ltp":1.5,"tv":0.28,"id":25173012}]}]}
{"op":"mcm","clk":"11753461643","pt":1722556631241,"mc":[{"id":"1.231282333","rc":[{"batb":[[0,1.43,19.8],[1,1.42,10],[2,1.36,15.2]],"ltp":1.4,"tv":0.7,"id":71847983},{"batb":[[0,1.4,21.7],[1,1.39,10],[2,1.32,12]],"ltp":1.5,"tv":0.28,"id":25173012}]}]}
{"op":"mcm","clk":"11753482735","pt":1722557110246,"mc":[{"id":"1.231282333","rc":[{"batb":[[0,1.43,19.81]],"ltp":1.4,"tv":0.7,"id":71847983},{"trd":[[1.5,0.42]],"batb":[[0,1.4,21.63]],"ltp":1.5,"tv":0.42,"id":25173012}],"tv":1.12}]}
{"op":"mcm","clk":"11753537032","pt":1722558307643,"mc":[{"id":"1.231282333","rc":[{"trd":[[1.5,0.56]],"batb":[[0,1.4,21.56]],"ltp":1.5,"tv":0.56,"id":25173012}],"tv":1.26}]}
{"op":"mcm","clk":"11753543064","pt":1722558433138,"mc":[{"id":"1.231282333","rc":[{"batb":[[0,1.42,10],[1,1.36,15.2],[2,1.25,40.91]],"ltp":1.4,"tv":0.7,"id":71847983},{"batb":[[0,1.39,10.27],[1,1.32,12],[2,1.25,40]],"ltp":1.5,"tv":0.56,"id":25173012}]}]}
{"op":"mcm","clk":"11753545210","pt":1722558485045,"mc":[{"id":"1.231282333","rc":[{"batb":[[0,1.43,19.81],[1,1.42,10],[2,1.36,15.2]],"ltp":1.4,"tv":0.7,"id":71847983},{"batb":[[0,1.4,21.56],[1,1.39,10],[2,1.32,12]],"ltp":1.5,"tv":0.56,"id":25173012}]}]}
{"op":"mcm","clk":"11753588725","pt":1722559510643,"mc":[{"id":"1.231282333","rc":[{"trd":[[1.5,0.7]],"batb":[[0,1.4,21.49]],"ltp":1.5,"tv":0.7,"id":25173012}],"tv":1.4}]}
{"op":"mcm","clk":"11753621048","pt":1722560285302,"mc":[{"id":"1.231282333","rc":[{"batb":[[0,1.42,10],[1,1.36,15.2],[2,1.25,40.91]],"ltp":1.4,"tv":0.7,"id":71847983},{"batb":[[0,1.39,10.2],[1,1.32,12],[2,1.25,40]],"ltp":1.5,"tv":0.7,"id":25173012}]}]}
{"op":"mcm","clk":"11753623270","pt":1722560334257,"mc":[{"id":"1.231282333","rc":[{"batb":[[0,1.43,19.81],[1,1.42,10],[2,1.36,15.2]],"ltp":1.4,"tv":0.7,"id":71847983},{"batb":[[0,1.4,21.49],[1,1.39,10],[2,1.32,12]],"ltp":1.5,"tv":0.7,"id":25173012}]}]}
{"op":"mcm","clk":"11753641499","pt":1722560708886,"mc":[{"id":"1.231282333","rc":[{"batb":[[0,1.43,19.82]],"ltp":1.4,"tv":0.7,"id":71847983},{"trd":[[1.5,0.84]],"batb":[[0,1.4,21.44]],"ltp":1.5,"tv":0.84,"id":25173012}],"tv":1.54}]}
{"op":"mcm","clk":"11753706817","pt":1722561908240,"mc":[{"id":"1.231282333","rc":[{"trd":[[1.5,0.98]],"batb":[[0,1.4,21.37]],"ltp":1.5,"tv":0.98,"id":25173012}],"tv":1.68}]}
{"op":"mcm","clk":"11753717327","pt":1722562134723,"mc":[{"id":"1.231282333","rc":[{"batb":[[0,1.42,10],[1,1.36,15.2],[2,1.25,40.92]],"ltp":1.4,"tv":0.7,"id":71847983},{"batb":[[0,1.39,10.06],[1,1.32,12],[2,1.25,40]],"ltp":1.5,"tv":0.98,"id":25173012}]}]}
{"op":"mcm","clk":"11753720389","pt":1722562198694,"mc":[{"id":"1.231282333","rc":[{"batb":[[0,1.43,19.82],[1,1.42,10],[2,1.36,15.2]],"ltp":1.4,"tv":0.7,"id":71847983},{"batb":[[0,1.4,21.37],[1,1.39,10],[2,1.32,12]],"ltp":1.5,"tv":0.98,"id":25173012}]}]}
{"op":"mcm","clk":"11753767396","pt":1722563109488,"mc":[{"id":"1.231282333","rc":[{"trd":[[1.4,0.02],[1.5,1.1]],"batb":[[0,1.4,21.3]],"ltp":1.4,"tv":1.11,"id":25173012}],"tv":1.82}]}
{"op":"mcm","clk":"11753817053","pt":1722563999269,"mc":[{"id":"1.231282333","rc":[{"batb":[[0,1.39,10],[1,1.32,12],[2,1.25,40]],"ltp":1.4,"tv":1.11,"id":25173012}]}]}
{"op":"mcm","clk":"11753817063","pt":1722563999472,"mc":[{"id":"1.231282333","rc":[{"batb":[[0,1.42,10],[1,1.36,15.2],[2,1.25,40.92]],"ltp":1.4,"tv":0.7,"id":71847983}]}]}
{"op":"mcm","clk":"11753819961","pt":1722564037932,"mc":[{"id":"1.231282333","rc":[{"batb":[[0,1.43,19.82],[1,1.42,10],[2,1.36,15.2]],"ltp":1.4,"tv":0.7,"id":71847983}]}]}
{"op":"mcm","clk":"11753951103","pt":1722565838574,"mc":[{"id":"1.231282333","rc":[{"batb":[[0,1.42,10],[1,1.36,15.2],[2,1.25,40]],"ltp":1.4,"tv":0.7,"id":71847983}]}]}
{"op":"mcm","clk":"11753953049","pt":1722565865322,"mc":[{"id":"1.231282333","rc":[{"batb":[[0,1.43,19.82],[1,1.42,10],[2,1.36,15.2]],"ltp":1.4,"tv":0.7,"id":71847983}]}]}
{"op":"mcm","clk":"11753996892","pt":1722566465782,"mc":[{"id":"1.231282333","rc":[{"batb":[[0,1.39,10.92]],"ltp":1.4,"tv":1.11,"id":25173012}]}]}
{"op":"mcm","clk":"11753997703","pt":1722566475785,"mc":[{"id":"1.231282333","rc":[{"batb":[[0,1.43,20.74]],"ltp":1.4,"tv":0.7,"id":71847983}]}]}
{"op":"mcm","clk":"11754042134","pt":1722566910783,"mc":[{"id":"1.231282333","rc":[{"batb":[[2,1.36,15]],"ltp":1.4,"tv":0.7,"id":71847983}]}]}
{"op":"mcm","clk":"11754043520","pt":1722566929787,"mc":[{"id":"1.231282333","rc":[{"batb":[[0,1.45,1.46],[1,1.43,19.82],[2,1.42,10]],"ltp":1.4,"tv":0.7,"id":71847983}]}]}
{"op":"mcm","clk":"11754046663","pt":1722566971745,"mc":[{"id":"1.231282333","rc":[{"batb":[[0,1.4,1.46],[1,1.39,10],[2,1.32,12]],"ltp":1.4,"tv":1.11,"id":25173012}]}]}
{"op":"mcm","clk":"11754095998","pt":1722567665489,"mc":[{"id":"1.231282333","rc":[{"batb":[[1,1.42,10],[2,1.36,15]],"ltp":1.4,"tv":0.7,"id":71847983}]}]}
{"op":"mcm","clk":"11754097745","pt":1722567688852,"mc":[{"id":"1.231282333","rc":[{"batb":[[1,1.43,19.82],[2,1.42,10]],"ltp":1.4,"tv":0.7,"id":71847983}]}]}
{"op":"mcm","clk":"11754112566","pt":1722567917915,"mc":[{"id":"1.231282333","rc":[{"trd":[[1.5,1.24]],"batb":[[0,1.4,1.39]],"ltp":1.5,"tv":1.25,"id":25173012}],"tv":1.96}]}
{"op":"mcm","clk":"11754196326","pt":1722569117331,"mc":[{"id":"1.231282333","rc":[{"trd":[[1.5,1.38]],"batb":[[0,1.4,1.32]],"ltp":1.5,"tv":1.4,"id":25173012}],"tv":2.1}]}
{"op":"mcm","clk":"11754218423","pt":1722569490467,"mc":[{"id":"1.231282333","rc":[{"batb":[[1,1.42,10],[2,1.36,15]],"ltp":1.4,"tv":0.7,"id":71847983}]}]}
{"op":"mcm","clk":"11754218931","pt":1722569499474,"mc":[{"id":"1.231282333","rc":[{"batb":[[1,1.43,19.82],[2,1.42,10]],"ltp":1.4,"tv":0.7,"id":71847983}]}]}
{"op":"mcm","clk":"11754274773","pt":1722570317521,"mc":[{"id":"1.231282333","rc":[{"trd":[[1.5,1.52]],"batb":[[0,1.4,1.25]],"ltp":1.5,"tv":1.54,"id":25173012}],"tv":2.24}]}
{"op":"mcm","clk":"11754312194","pt":1722570897832,"mc":[{"id":"1.231282333","rc":[{"trd":[[3,0.17],[3.5,0.37]],"batb":[[0,1.5,1.12],[1,1.43,20.74]],"ltp":3.5,"tv":1.23,"id":71847983},{"trd":[[1.4,0.94],[1.5,1.86]],"batb":[[0,1.39,10],[1,1.32,12],[2,1.25,40]],"ltp":1.4,"tv":2.79,"id":25173012}],"tv":4.02}]}
{"op":"mcm","clk":"11754312578","pt":1722570904136,"mc":[{"id":"1.231282333","rc":[{"batb":[[0,1.45,1.46],[1,1.43,19.82]],"ltp":3.5,"tv":1.23,"id":71847983}]}]}
{"op":"mcm","clk":"11754313517","pt":1722570919085,"mc":[{"id":"1.231282333","rc":[{"batb":[[0,3.5,1.1],[1,1.45,1.46],[2,1.43,19.82]],"ltp":3.5,"tv":1.23,"id":71847983}]}]}
{"op":"mcm","clk":"11754315432","pt":1722570950095,"mc":[{"id":"1.231282333","rc":[{"batb":[[0,1.45,1.46],[1,1.43,19.82],[2,1.42,10]],"ltp":3.5,"tv":1.23,"id":71847983}]}]}
{"op":"mcm","clk":"11754323209","pt":1722571087751,"mc":[{"id":"1.231282333","rc":[{"batb":[[0,1.39,10.55]],"ltp":1.4,"tv":2.79,"id":25173012}]}]}
{"op":"mcm","clk":"11754336289","pt":1722571300315,"mc":[{"id":"1.231282333","rc":[{"batb":[[1,1.42,10],[2,1.36,15]],"ltp":3.5,"tv":1.23,"id":71847983}]}]}
{"op":"mcm","clk":"11754336848","pt":1722571308830,"mc":[{"id":"1.231282333","rc":[{"batb":[[1,1.43,19.83],[2,1.42,10]],"ltp":3.5,"tv":1.23,"id":71847983}]}]}
{"op":"mcm","clk":"11754421958","pt":1722572580938,"mc":[{"id":"1.231282333","rc":[{"batb":[[0,1.39,10.73]],"ltp":1.4,"tv":2.79,"id":25173012}]}]}
{"op":"mcm","clk":"11754455141","pt":1722573109306,"mc":[{"id":"1.231282333","rc":[{"batb":[[1,1.42,10],[2,1.36,15]],"ltp":3.5,"tv":1.23,"id":71847983}]}]}
{"op":"mcm","clk":"11754455218","pt":1722573110689,"mc":[{"id":"1.231282333","rc":[{"batb":[[1,1.43,19.83],[2,1.42,10]],"ltp":3.5,"tv":1.23,"id":71847983}]}]}
{"op":"mcm","clk":"11754546506","pt":1722574910930,"mc":[{"id":"1.231282333","rc":[{"batb":[[1,1.42,10],[2,1.36,15]],"ltp":3.5,"tv":1.23,"id":71847983}]}]}
{"op":"mcm","clk":"11754554933","pt":1722575057402,"mc":[{"id":"1.231282333","rc":[{"batb":[[1,1.43,19.83],[2,1.42,10]],"ltp":3.5,"tv":1.23,"id":71847983}]}]}
{"op":"mcm","clk":"11754641188","pt":1722576857667,"mc":[{"id":"1.231282333","rc":[{"batb":[[1,1.42,10],[2,1.36,15]],"ltp":3.5,"tv":1.23,"id":71847983}]}]}
{"op":"mcm","clk":"11754641688","pt":1722576868766,"mc":[{"id":"1.231282333","rc":[{"batb":[[0,1.4,1.65],[1,1.39,10],[2,1.32,12]],"ltp":1.4,"tv":2.79,"id":25173012}]}]}
{"op":"mcm","clk":"11754642275","pt":1722576883978,"mc":[{"id":"1.231282333","rc":[{"batb":[[0,1.41,1.65]],"ltp":1.4,"tv":2.79,"id":25173012}]}]}
{"op":"mcm","clk":"11754642596","pt":1722576892008,"mc":[{"id":"1.231282333","rc":[{"batb":[[0,1.4,1.65]],"ltp":1.4,"tv":2.79,"id":25173012}]}]}
{"op":"mcm","clk":"11754647337","pt":1722577002211,"mc":[{"id":"1.231282333","rc":[{"batb":[[1,1.43,19.83],[2,1.42,10]],"ltp":3.5,"tv":1.23,"id":71847983}]}]}
{"op":"mcm","clk":"11754679253","pt":1722577518972,"mc":[{"id":"1.231282333","rc":[{"trd":[[1.45,0.14]],"batb":[[0,1.4,1.58]],"ltp":1.45,"tv":2.93,"id":25173012}],"tv":4.17}]}
{"op":"mcm","clk":"11754681437","pt":1722577571822,"mc":[{"id":"1.231282333","rc":[{"batl":[[0,5,1.75],[1,7,1.57]],"ltp":3.5,"tv":1.23,"id":71847983}]}]}
{"op":"mcm","clk":"11754681879","pt":1722577581828,"mc":[{"id":"1.231282333","rc":[{"batl":[[0,5,1.75],[1,7,1.57]],"ltp":1.45,"tv":2.93,"id":25173012}]}]}
{"op":"mcm","clk":"11754686847","pt":1722577719944,"mc":[{"id":"1.231282333","rc":[{"batb":[[0,1.39,10.92],[1,1.32,12],[2,1.25,40]],"ltp":1.45,"tv":2.93,"id":25173012}]}]}
{"op":"mcm","clk":"11754687420","pt":1722577734841,"mc":[{"id":"1.231282333","rc":[{"batb":[[0,1.4,1.43],[1,1.39,10],[2,1.32,12]],"ltp":1.45,"tv":2.93,"id":25173012}]}]}
{"op":"mcm","clk":"11754690410","pt":1722577808829,"mc":[{"id":"1.231282333","rc":[{"batb":[[0,1.51,15.55],[1,1.43,20.75]],"ltp":3.5,"tv":1.23,"id":71847983},{"batb":[[0,1.51,12.51],[1,1.39,10.92],[2,1.25,40]],"ltp":1.45,"tv":2.93,"id":25173012}]}]}
{"op":"mcm","clk":"11754714322","pt":1722578352483,"mc":[{"id":"1.231282333","rc":[{"batl":[[0,2.98,1.96],[1,6,1.57],[2,7,0.79]],"ltp":3.5,"tv":1.23,"id":71847983}]}]}
{"op":"mcm","clk":"11754720565","pt":1722578466811,"mc":[{"id":"1.231282333","rc":[{"batb":[[1,1.43,20.74]],"batl":[[1,6,1.57]],"ltp":3.5,"tv":1.23,"id":71847983},{"trd":[[1.55,1.02]],"batb":[[0,1.51,12]],"batl":[[0,2.98,1.55],[1,6,1.57],[2,7,0.79]],"ltp":1.55,"tv":3.95,"id":25173012}],"tv":5.19}]}
{"op":"mcm","clk":"11754721066","pt":1722578475240,"mc":[{"id":"1.231282333","rc":[{"batl":[[0,5,1.75],[1,7,1.57],[2,7,0]],"ltp":1.55,"tv":3.95,"id":25173012}]}]}
{"op":"mcm","clk":"11754721609","pt":1722578485453,"mc":[{"id":"1.231282333","rc":[{"batl":[[0,1.57,1.1],[1,5,1.75],[2,7,1.57]],"ltp":1.55,"tv":3.95,"id":25173012}]}]}
{"op":"mcm","clk":"11754722024","pt":1722578493560,"mc":[{"id":"1.231282333","rc":[{"batl":[[0,5,1.75],[1,7,1.57],[2,7,0]],"ltp":1.55,"tv":3.95,"id":25173012}]}]}
{"op":"mcm","clk":"11754724206","pt":1722578535704,"mc":[{"id":"1.231282333","rc":[{"batl":[[0,1.55,1.1],[1,5,1.75],[2,7,1.57]],"ltp":1.55,"tv":3.95,"id":25173012}]}]}
{"op":"mcm","clk":"11754724764","pt":1722578546335,"mc":[{"id":"1.231282333","rc":[{"batl":[[0,5,1.75],[1,7,1.57],[2,7,0]],"ltp":1.55,"tv":3.95,"id":25173012}]}]}
{"op":"mcm","clk":"11754737679","pt":1722578802495,"mc":[{"id":"1.231282333","rc":[{"batb":[[1,1.42,10.91],[2,1.25,40]],"ltp":3.5,"tv":1.23,"id":71847983}]}]}
{"op":"mcm","clk":"11754744824","pt":1722578949770,"mc":[{"id":"1.231282333","rc":[{"batb":[[0,1.52,16.95],[1,1.51,15],[2,1.42,10.91]],"ltp":3.5,"tv":1.23,"id":71847983}]}]}
{"op":"mcm","clk":"11754783738","pt":1722579750910,"mc":[{"id":"1.231282333","rc":[{"batb":[[2,1.26,6.93]],"ltp":1.55,"tv":3.95,"id":25173012}]}]}
{"op":"mcm","clk":"11754829428","pt":1722580749954,"mc":[{"id":"1.231282333","rc":[{"batb":[[0,1.51,15.55],[1,1.42,10.91],[2,1.25,40]],"ltp":3.5,"tv":1.23,"id":71847983}]}]}
{"op":"mcm","clk":"11754837378","pt":1722580898520,"mc":[{"id":"1.231282333","rc":[{"batb":[[0,1.52,16.95],[1,1.51,15],[2,1.42,10.91]],"ltp":3.5,"tv":1.23,"id":71847983}]}]}
{"op":"mcm","clk":"11754880909","pt":1722582073237,"mc":[{"id":"1.231282333","rc":[{"batb":[[0,1.53,10.55],[1,1.52,16.39],[2,1.51,15]],"ltp":3.5,"tv":1.23,"id":71847983},{"batb":[[0,1.52,10],[1,1.51,12],[2,1.26,7.85]],"batl":[[0,5,1.75]],"ltp":1.55,"tv":3.95,"id":25173012}],"tv":5.19}]}
{"op":"mcm","clk":"11754904749","pt":1722582698712,"mc":[{"id":"1.231282333","rc":[{"batb":[[1,1.51,15],[2,1.25,40.92]],"ltp":3.5,"tv":1.23,"id":71847983}]}]}
{"op":"mcm","clk":"11754919375","pt":1722582841605,"mc":[{"id":"1.231282333","rc":[{"batb":[[0,1.54,16.34],[1,1.53,10],[2,1.51,15]],"ltp":3.5,"tv":1.23,"id":71847983}]}]}
{"op":"mcm","clk":"11754928207","pt":1722583053995,"mc":[{"id":"1.231282333","rc":[{"batb":[[0,1.54,15.79]],"ltp":3.5,"tv":1.23,"id":71847983}]}]}
{"op":"mcm","clk":"11754928742","pt":1722583067037,"mc":[{"id":"1.231282333","rc":[{"batl":[[0,2.98,1.51],[1,6,1.57],[2,7,0.79]],"ltp":1.55,"tv":3.95,"id":25173012}]}]}
{"op":"mcm","clk":"11754991207","pt":1722584641741,"mc":[{"id":"1.231282333","rc":[{"batb":[[0,1.53,10],[1,1.51,15],[2,1.25,40.92]],"ltp":3.5,"tv":1.23,"id":71847983}]}]}
{"op":"mcm","clk":"11754996401","pt":1722584783775,"mc":[{"id":"1.231282333","rc":[{"batb":[[0,1.54,15.79],[1,1.53,10],[2,1.51,15]],"ltp":3.5,"tv":1.23,"id":71847983}]}]}
{"op":"mcm","clk":"11755025823","pt":1722585523945,"mc":[{"id":"1.231282333","rc":[{"batb":[[0,1.54,25.79],[1,1.51,15],[2,1.25,40.92]],"ltp":3.5,"tv":1.23,"id":71847983},{"batb":[[0,1.54,10]],"ltp":1.55,"tv":3.95,"id":25173012}]}]}
{"op":"mcm","clk":"11755032697","pt":1722585669996,"mc":[{"id":"1.231282333","rc":[{"batb":[[0,1.71,21.2],[1,1.54,25.82],[2,1.51,15]],"batl":[[0,2.98,1.96],[1,6,1.57]],"ltp":3.5,"tv":1.23,"id":71847983},{"trd":[[1.4,0.94],[1.5,1.86],[1.55,1.03]],"batb":[[0,1.63,19.91],[1,1.54,10],[2,1.51,12]],"batl":[[0,2.98,1.51],[1,6,1.57]],"ltp":1.55,"tv":3.96,"id":25173012}],"tv":5.19}]}
{"op":"mcm","clk":"11755044602","pt":1722585929104,"mc":[{"id":"1.231282333","rc":[{"batl":[[0,5,1.75],[1,7,1.57],[2,7,0]],"ltp":1.55,"tv":3.96,"id":25173012}]}]}
{"op":"mcm","clk":"11755073038","pt":1722586552004,"mc":[{"id":"1.231282333","rc":[{"batb":[[0,1.71,21.75]],"ltp":3.5,"tv":1.23,"id":71847983}]}]}
{"op":"mcm","clk":"11755074595","pt":1722586584055,"mc":[{"id":"1.231282333","rc":[{"batb":[[1,1.54,10]],"ltp":3.5,"tv":1.23,"id":71847983}]}]}
{"op":"mcm","clk":"11755189599","pt":1722588503217,"mc":[{"id":"1.231282333","rc":[{"batb":[[0,1.54,10.55],[1,1.51,15],[2,1.25,40]],"ltp":3.5,"tv":1.23,"id":71847983},{"batb":[[0,1.54,10],[1,1.51,12],[2,1.25,40]],"ltp":1.55,"tv":3.96,"id":25173012}]}]}
{"op":"mcm","clk":"11755189955","pt":1722588507787,"mc":[{"id":"1.231282333","rc":[{"batb":[[0,1.55,16.08],[1,1.54,10],[2,1.51,15]],"ltp":3.5,"tv":1.23,"id":71847983}]}]}
{"op":"mcm","clk":"11755198742","pt":1722588639034,"mc":[{"id":"1.231282333","rc":[{"batl":[[0,2.98,1]],"ltp":3.5,"tv":1.23,"id":71847983}]}]}
{"op":"mcm","clk":"11755198931","pt":1722588642313,"mc":[{"id":"1.231282333","rc":[{"batl":[[0,6,1.57],[1,7,0.79]],"ltp":1.55,"tv":3.96,"id":25173012}]}]}
{"op":"mcm","clk":"11755204311","pt":1722588721130,"mc":[{"id":"1.231282333","rc":[{"batb":[[0,1.58,23.54],[1,1.55,15.53],[2,1.54,10]],"ltp":3.5,"tv":1.23,"id":71847983},{"batb":[[0,1.6,20.31],[1,1.54,10],[2,1.51,12]],"ltp":1.55,"tv":3.96,"id":25173012}]}]}
{"op":"mcm","clk":"11755237629","pt":1722589177217,"mc":[{"id":"1.231282333","rc":[{"batb":[[0,1.55,16.08],[1,1.54,10],[2,1.51,15]],"ltp":3.5,"tv":1.23,"id":71847983},{"batb":[[0,1.54,10],[1,1.51,12],[2,1.25,40]],"ltp":1.55,"tv":3.96,"id":25173012}]}]}
{"op":"mcm","clk":"11755247609","pt":1722589307473,"mc":[{"id":"1.231282333","rc":[{"batb":[[0,1.58,23.54],[1,1.55,15.52],[2,1.54,10]],"batl":[[1,6,1.57],[2,7,0.79]],"ltp":3.5,"tv":1.23,"id":71847983},{"trd":[[1.4,0.94],[1.5,1.86],[1.55,1.02]],"batb":[[0,1.61,20.18],[1,1.54,10],[2,1.51,12]],"batl":[[0,6,1.57],[1,7,0.79]],"ltp":1.55,"tv":3.95,"id":25173012}],"tv":5.19}]}
{"op":"mcm","clk":"11755307890","pt":1722590067237,"mc":[{"id":"1.231282333","rc":[{"batb":[[0,1.58,22.99]],"ltp":3.5,"tv":1.23,"id":71847983}]}]}
{"op":"mcm","clk":"11755313545","pt":1722590136981,"mc":[{"id":"1.231282333","rc":[{"batb":[[0,1.58,23.54]],"ltp":3.5,"tv":1.23,"id":71847983}]}]}
{"op":"mcm","clk":"11755330046","pt":1722590307924,"mc":[{"id":"1.231282333","rc":[{"batb":[[1,1.54,10],[2,1.51,15]],"ltp":3.5,"tv":1.23,"id":71847983}]}]}
{"op":"mcm","clk":"11755339970","pt":1722590440699,"mc":[{"id":"1.231282333","rc":[{"batb":[[0,1.59,15.01],[1,1.58,22.99],[2,1.54,10]],"ltp":3.5,"tv":1.23,"id":71847983}]}]}
{"op":"mcm","clk":"11755345053","pt":1722590507674,"mc":[{"id":"1.231282333","rc":[{"batb":[[0,1.71,21.18],[1,1.59,15.01]],"ltp":3.5,"tv":1.23,"id":71847983}]}]}
{"op":"mcm","clk":"11755483345","pt":1722592240936,"mc":[{"id":"1.231282333","rc":[{"batb":[[1,1.54,10.55],[2,1.51,15]],"ltp":3.5,"tv":1.23,"id":71847983}]}]}
{"op":"mcm","clk":"11755618717","pt":1722593575194,"mc":[{"id":"1.231282333","tv":5.19}]}
{"op":"mcm","clk":"11755638644","pt":1722593759835,"mc":[{"id":"1.231282333","rc":[{"batb":[[0,1.72,5],[1,1.71,21.18],[2,1.54,10.55]],"ltp":3.5,"tv":1.23,"id":71847983},{"batb":[[0,1.62,5],[1,1.61,20.18],[2,1.54,10]],"ltp":1.55,"tv":3.95,"id":25173012}]}]}
{"op":"mcm","clk":"11755643761","pt":1722593807932,"mc":[{"id":"1.231282333","rc":[{"batb":[[0,1.73,20.93],[1,1.72,5]],"ltp":3.5,"tv":1.23,"id":71847983},{"batb":[[0,1.63,19.89],[1,1.62,5]],"ltp":1.55,"tv":3.95,"id":25173012}]}]}
{"op":"mcm","clk":"11755649692","pt":1722593864210,"mc":[{"id":"1.231282333","rc":[{"batb":[[0,1.64,5],[1,1.63,19.89]],"ltp":1.55,"tv":3.95,"id":25173012}]}]}
{"op":"mcm","clk":"11755671790","pt":1722594107642,"mc":[{"id":"1.231282333","rc":[{"batb":[[0,1.69,19.17],[1,1.64,5]],"ltp":1.55,"tv":3.95,"id":25173012}]}]}
{"op":"mcm","clk":"11755707151","pt":1722594502555,"mc":[{"id":"1.231282333","rc":[{"batb":[[0,1.7,5],[1,1.69,19.17]],"ltp":1.55,"tv":3.95,"id":25173012}]}]}
{"op":"mcm","clk":"11755727025","pt":1722594707657,"mc":[{"id":"1.231282333","rc":[{"batb":[[0,1.73,18.72],[1,1.7,5]],"ltp":1.55,"tv":3.95,"id":25173012}]}]}
{"op":"mcm","clk":"11755802664","pt":1722595496134,"mc":[{"id":"1.231282333","rc":[{"batb":[[0,1.74,5],[1,1.73,18.72]],"ltp":1.55,"tv":3.95,"id":25173012}]}]}
{"op":"mcm","clk":"11755813110","pt":1722595607645,"mc":[{"id":"1.231282333","rc":[{"batb":[[0,1.78,18.19],[1,1.74,5]],"ltp":1.55,"tv":3.95,"id":25173012}]}]}
{"op":"mcm","clk":"11755859415","pt":1722596138866,"mc":[{"id":"1.231282333","rc":[{"trd":[[2.12,2.14]],"batb":[[0,1.73,20.96]],"ltp":2.12,"tv":3.37,"id":71847983},{"batb":[[0,1.74,5],[1,1.54,10],[2,1.51,12]],"ltp":1.55,"tv":3.95,"id":25173012}],"tv":7.32}]}
{"op":"mcm","clk":"11755859975","pt":1722596144867,"mc":[{"id":"1.231282333","rc":[{"batb":[[0,1.73,20.93]],"ltp":2.12,"tv":3.37,"id":71847983}]}]}
{"op":"mcm","clk":"11755860242","pt":1722596148244,"mc":[{"id":"1.231282333","rc":[{"trd":[[1.73,5.58]],"batb":[[0,1.73,18.14]],"ltp":1.73,"tv":8.95,"id":71847983}],"tv":12.91}]}
{"op":"mcm","clk":"11755860257","pt":1722596148450,"mc":[{"id":"1.231282333","rc":[{"batb":[[0,1.88,17.12],[1,1.74,5],[2,1.54,10]],"ltp":1.55,"tv":3.95,"id":25173012}]}]}
{"op":"mcm","clk":"11755862531","pt":1722596172676,"mc":[{"id":"1.231282333","rc":[{"batb":[[0,1.89,1.1],[1,1.73,18.14],[2,1.72,5]],"ltp":1.73,"tv":8.95,"id":71847983}]}]}
{"op":"mcm","clk":"11755863697","pt":1722596185809,"mc":[{"id":"1.231282333","rc":[{"batb":[[0,1.73,18.14],[1,1.72,5],[2,1.54,10.55]],"ltp":1.73,"tv":8.95,"id":71847983}]}]}
{"op":"mcm","clk":"11755866773","pt":1722596219921,"mc":[{"id":"1.231282333","rc":[{"batl":[[0,1.85,1.1],[1,2.98,1],[2,6,1.57]],"ltp":1.73,"tv":8.95,"id":71847983}]}]}
{"op":"mcm","clk":"11755867955","pt":1722596231622,"mc":[{"id":"1.231282333","rc":[{"batl":[[0,2.98,1],[1,6,1.57],[2,7,0.78]],"ltp":1.73,"tv":8.95,"id":71847983}]}]}
{"op":"mcm","clk":"11755938251","pt":1722596867732,"mc":[{"id":"1.231282333","rc":[{"batb":[[0,1.74,17.32],[1,1.73,18.14],[2,1.72,5]],"ltp":1.73,"tv":8.95,"id":71847983},{"batb":[[1,1.74,22.32]],"ltp":1.55,"tv":3.95,"id":25173012}],"tv":12.91}]}
{"op":"mcm","clk":"11755956627","pt":1722597058934,"mc":[{"id":"1.231282333","rc":[{"batb":[[0,1.75,20.57],[1,1.74,17.32]],"ltp":1.73,"tv":8.95,"id":71847983},{"batb":[[0,1.75,18.4]],"ltp":1.55,"tv":3.95,"id":25173012}]}]}
{"op":"mcm","clk":"11756020499","pt":1722597715032,"mc":[{"id":"1.231282333","rc":[{"batb":[[0,1.8,5],[1,1.75,18.4],[2,1.74,17.32]],"ltp":1.55,"tv":3.95,"id":25173012}]}]}
{"op":"mcm","clk":"11756044319","pt":1722597959181,"mc":[{"id":"1.231282333","rc":[{"batb":[[0,1.9,16.94],[1,1.8,5]],"ltp":1.55,"tv":3.95,"id":25173012}]}]}
{"op":"mcm","clk":"11756416727","pt":1722601687043,"mc":[{"id":"1.231282333","rc":[{"batb":[[0,1.91,5],[1,1.9,16.94]],"ltp":1.55,"tv":3.95,"id":25173012}],"tv":12.91}]}
{"op":"mcm","clk":"11756436105","pt":1722601859176,"mc":[{"id":"1.231282333","rc":[{"batb":[[0,1.92,16.76],[1,1.91,5]],"ltp":1.55,"tv":3.95,"id":25173012}]}]}
{"op":"mcm","clk":"11756499597","pt":1722602519548,"mc":[{"id":"1.231282333","rc":[{"batb":[[0,1.93,5],[1,1.92,16.76]],"ltp":1.55,"tv":3.95,"id":25173012}]}]}
{"op":"mcm","clk":"11756522233","pt":1722602769757,"mc":[{"id":"1.231282333","rc":[{"batb":[[1,1.74,17.32],[2,1.54,10]],"ltp":1.55,"tv":3.95,"id":25173012}]}]}
{"op":"mcm","clk":"11756553814","pt":1722603059031,"mc":[{"id":"1.231282333","rc":[{"batb":[[0,1.93,21.67]],"ltp":1.55,"tv":3.95,"id":25173012}]}]}
{"op":"mcm","clk":"11756581529","pt":1722603332211,"mc":[{"id":"1.231282333","rc":[{"batb":[[0,1.85,50.78],[1,1.75,20.57],[2,1.74,17.32]],"ltp":1.73,"tv":8.95,"id":71847983},{"batb":[[0,2.08,39.96],[1,1.93,21.67],[2,1.74,17.32]],"ltp":1.55,"tv":3.95,"id":25173012}]}]}
{"op":"mcm","clk":"11756584487","pt":1722603359354,"mc":[{"id":"1.231282333","rc":[{"batb":[[1,1.74,17.32],[2,1.72,5]],"ltp":1.73,"tv":8.95,"id":71847983},{"batb":[[1,1.93,5]],"ltp":1.55,"tv":3.95,"id":25173012}]}]}
{"op":"mcm","clk":"11756624541","pt":1722603748564,"mc":[{"id":"1.231282333","rc":[{"trd":[[1.4,0.7],[1.73,5.57],[2.12,2.13],[3.5,0.37]],"batb":[[2,1.51,15.55]],"batl":[[1,6,1.56],[2,7,0.78]],"ltp":1.73,"tv":8.93,"id":71847983},{"trd":[[1.4,0.93],[1.5,1.85],[1.55,1.02]],"batb":[[1,1.74,17.32],[2,1.51,12]],"batl":[[0,6,1.56],[1,7,0.78]],"ltp":1.55,"tv":3.94,"id":25173012}],"tv":12.87}]}
{"op":"mcm","clk":"11756659794","pt":1722604051143,"mc":[{"id":"1.231282333","rc":[{"batb":[[2,1.51,15]],"ltp":1.73,"tv":8.93,"id":71847983},{"trd":[[2.08,1.96]],"batb":[[0,2.08,38.98]],"ltp":2.08,"tv":5.9,"id":25173012}],"tv":14.83}]}
{"op":"mcm","clk":"11756660326","pt":1722604055927,"mc":[{"id":"1.231282333","rc":[{"batb":[[0,2.08,39.96]],"ltp":2.08,"tv":5.9,"id":25173012}]}]}
{"op":"mcm","clk":"11756933503","pt":1722606693381,"mc":[{"id":"1.231282333","rc":[{"trd":[[1.85,1.98]],"batb":[[0,1.85,49.79]],"ltp":1.85,"tv":10.91,"id":71847983}],"tv":16.81}]}
{"op":"mcm","clk":"11756933795","pt":1722606696256,"mc":[{"id":"1.231282333","rc":[{"batb":[[0,1.85,50.78]],"ltp":1.85,"tv":10.91,"id":71847983}]}]}
{"op":"mcm","clk":"11756934822","pt":1722606706284,"mc":[{"id":"1.231282333","rc":[{"trd":[[2.08,3.72]],"ltp":2.08,"tv":7.66,"id":25173012}],"tv":18.57}]}
{"op":"mcm","clk":"11757122725","pt":1722608508983,"mc":[{"id":"1.231282333","rc":[{"trd":[[1.73,5.56],[1.85,1.98],[2.12,2.13]],"batb":[[0,1.85,52.33]],"batl":[[1,6,1.56],[2,7,0.78]],"ltp":1.85,"tv":10.9,"id":71847983},{"trd":[[1.4,0.93],[1.5,1.85],[1.55,1.02]],"batb":[[0,2.08,41.19]],"batl":[[0,6,1.56],[1,7,0.78]],"ltp":2.08,"tv":7.65,"id":25173012}],"tv":18.56}]}
{"op":"mcm","clk":"11757324172","pt":1722610374941,"mc":[{"id":"1.231282333","rc":[{"batb":[[2,1.25,40]],"ltp":1.85,"tv":10.9,"id":71847983},{"batb":[[2,1.25,40]],"ltp":2.08,"tv":7.65,"id":25173012}]}]}
{"op":"mcm","clk":"11757754982","pt":1722613912661,"mc":[{"id":"1.231282333","rc":[{"trd":[[1.73,5.57],[1.85,1.98],[2.12,2.13]],"batl":[[1,6,1.56],[2,7,0.78]],"ltp":1.85,"tv":10.91,"id":71847983},{"trd":[[1.4,0.93],[1.5,1.85],[1.55,1.02]],"batl":[[0,6,1.56],[1,7,0.78]],"ltp":2.08,"tv":7.66,"id":25173012}],"tv":18.57}]}
{"op":"mcm","clk":"11757934760","pt":1722615175121,"mc":[{"id":"1.231282333","rc":[{"trd":[[1.73,5.57],[1.85,1.98]],"ltp":1.85,"tv":10.92,"id":71847983},{"trd":[[1.5,1.85],[2.08,3.72]],"ltp":2.08,"tv":7.66,"id":25173012}],"tv":18.58}]}
{"op":"mcm","clk":"11758273619","pt":1722617262930,"mc":[{"id":"1.231282333","rc":[{"trd":[[2.08,4.95]],"batb":[[0,2.08,40.58]],"ltp":2.08,"tv":8.88,"id":25173012}],"tv":19.81}]}
{"op":"mcm","clk":"11758274365","pt":1722617267854,"mc":[{"id":"1.231282333","rc":[{"batb":[[0,2.08,41.19]],"ltp":2.08,"tv":8.88,"id":25173012}]}]}
{"op":"mcm","clk":"11758284101","pt":1722617332843,"mc":[{"id":"1.231282333","rc":[{"batl":[[0,6,1.56],[1,7,0.78],[2,7,0]],"ltp":1.85,"tv":10.92,"id":71847983}]}]}
{"op":"mcm","clk":"11758293325","pt":1722617392555,"mc":[{"id":"1.231282333","rc":[{"batb":[[1,1.8,32],[2,1.74,17.32]],"ltp":1.85,"tv":10.92,"id":71847983}]}]}
{"op":"mcm","clk":"11758294764","pt":1722617402082,"mc":[{"id":"1.231282333","rc":[{"batl":[[0,1.96,25.6],[1,6,1.56],[2,7,0.78]],"ltp":1.85,"tv":10.92,"id":71847983}]}]}
{"op":"mcm","clk":"11758302962","pt":1722617457050,"mc":[{"id":"1.231282333","rc":[{"batb":[[2,1.03,201.56]],"ltp":2.08,"tv":8.88,"id":25173012}]}]}
{"op":"mcm","clk":"11758910092","pt":1722620575231,"mc":[{"id":"1.231282333","rc":[{"trd":[[1.73,5.57],[1.85,1.99]],"ltp":1.85,"tv":10.92,"id":71847983},{"trd":[[2.08,4.95]],"ltp":2.08,"tv":8.89,"id":25173012}],"tv":19.82}]}
{"op":"mcm","clk":"11759968635","pt":1722625975165,"mc":[{"id":"1.231282333","rc":[{"trd":[[1.73,5.57],[1.85,1.99],[2.12,2.13]],"batl":[[1,6,1.56],[2,7,0.78]],"ltp":1.85,"tv":10.91,"id":71847983},{"trd":[[1.4,0.93],[1.5,1.85],[1.55,1.02],[2.08,4.95]],"batb":[[2,1.03,201.56]],"batl":[[0,6,1.56],[1,7,0.78]],"ltp":2.08,"tv":8.88,"id":25173012}],"tv":19.8}]}
{"op":"mcm","clk":"11760115413","pt":1722626843340,"mc":[{"id":"1.231282333","rc":[{"batl":[[1,2.2,2.73],[2,6,1.56]],"ltp":1.85,"tv":10.91,"id":71847983}]}]}
{"op":"mcm","clk":"11760117157","pt":1722626854163,"mc":[{"id":"1.231282333","rc":[{"batl":[[1,6,1.56],[2,7,0.78]],"ltp":1.85,"tv":10.91,"id":71847983}]}]}
{"op":"mcm","clk":"11760547434","pt":1722630487605,"mc":[{"id":"1.231282333","rc":[{"trd":[[1.85,1.99]],"ltp":1.85,"tv":10.92,"id":71847983},{"trd":[[2.08,4.95]],"ltp":2.08,"tv":8.88,"id":25173012}],"tv":19.81}]}
{"op":"mcm","clk":"11760747580","pt":1722635009273,"mc":[{"id":"1.231282333","rc":[{"trd":[[1.85,1.99]],"ltp":1.85,"tv":10.91,"id":71847983},{"trd":[[2.08,5.97]],"batb":[[0,2.08,40.68]],"ltp":2.08,"tv":9.9,"id":25173012}],"tv":20.82}]}
{"op":"mcm","clk":"11760747633","pt":1722635010910,"mc":[{"id":"1.231282333","rc":[{"batb":[[0,2.08,41.19]],"ltp":2.08,"tv":9.9,"id":25173012}]}]}
{"op":"mcm","clk":"11760799217","pt":1722636764865,"mc":[{"id":"1.231282333","rc":[{"batl":[[0,1.93,303.85],[1,1.96,25.6],[2,6,1.56]],"ltp":1.85,"tv":10.91,"id":71847983},{"trd":[[2.08,5.97]],"ltp":2.08,"tv":9.9,"id":25173012}],"tv":20.82}]}
{"op":"mcm","clk":"11760799400","pt":1722636772493,"mc":[{"id":"1.231282333","rc":[{"batl":[[0,1.93,607.7]],"ltp":1.85,"tv":10.91,"id":71847983}]}]}
{"op":"mcm","clk":"11760841855","pt":1722637752357,"mc":[{"id":"1.231282333","rc":[{"batl":[[0,1.92,17.1],[1,1.93,607.7],[2,1.96,25.6]],"ltp":1.85,"tv":10.91,"id":71847983}]}]}
{"op":"mcm","clk":"11760867554","pt":1722638609276,"mc":[{"id":"1.231282333","rc":[{"batl":[[1,1.96,25.6],[2,6,1.56]],"ltp":1.85,"tv":10.91,"id":71847983}]}]}
{"op":"mcm","clk":"11760867625","pt":1722638611585,"mc":[{"id":"1.231282333","rc":[{"batl":[[0,1.96,25.6],[1,6,1.56],[2,7,0.78]],"ltp":1.85,"tv":10.91,"id":71847983}]}]}
{"op":"mcm","clk":"11760868627","pt":1722638646551,"mc":[{"id":"1.231282333","rc":[{"batl":[[0,6,1.56],[1,7,0.78],[2,7,0]],"ltp":1.85,"tv":10.91,"id":71847983}]}]}
{"op":"mcm","clk":"11760868817","pt":1722638653685,"mc":[{"id":"1.231282333","rc":[{"batl":[[0,1.93,25.66],[1,6,1.56],[2,7,0.78]],"ltp":1.85,"tv":10.91,"id":71847983}]}]}
{"op":"mcm","clk":"11760886008","pt":1722639267315,"mc":[{"id":"1.231282333","rc":[{"batb":[[0,1.89,49.98]],"ltp":1.85,"tv":10.91,"id":71847983},{"batb":[[0,2.02,43.61]],"ltp":2.08,"tv":9.9,"id":25173012}]}]}
{"op":"mcm","clk":"11760909081","pt":1722640118004,"mc":[{"id":"1.231282333","rc":[{"trd":[[1.93,0.54]],"batl":[[0,1.93,25.12]],"ltp":1.93,"tv":11.45,"id":71847983},{"trd":[[2.06,0.51]],"ltp":2.06,"tv":10.41,"id":25173012}],"tv":21.87}]}
{"op":"mcm","clk":"11760911128","pt":1722640193622,"mc":[{"id":"1.231282333","rc":[{"batl":[[0,1.96,25.12]],"ltp":1.93,"tv":11.45,"id":71847983}]}]}
{"op":"mcm","clk":"11761315604","pt":1722650500961,"mc":[{"id":"1.231282333","rc":[{"trd":[[1.89,7.28]],"batb":[[0,1.89,46.34]],"ltp":1.89,"tv":18.73,"id":71847983}],"tv":29.15}]}
{"op":"mcm","clk":"11761315656","pt":1722650502395,"mc":[{"id":"1.231282333","rc":[{"batb":[[0,1.89,49.98]],"ltp":1.89,"tv":18.73,"id":71847983}]}]}
{"op":"mcm","clk":"11761402227","pt":1722652571483,"mc":[{"id":"1.231282333","rc":[{"batl":[[2,9,3.32]],"ltp":1.89,"tv":18.73,"id":71847983}]}]}
{"op":"mcm","clk":"11761558989","pt":1722655789964,"mc":[{"id":"1.231282333","rc":[{"trd":[[1.96,0.28]],"batl":[[0,1.96,24.84]],"ltp":1.96,"tv":19.01,"id":71847983},{"trd":[[2.04,0.27]],"ltp":2.04,"tv":10.68,"id":25173012}],"tv":29.7}]}
{"op":"mcm","clk":"11761559493","pt":1722655802991,"mc":[{"id":"1.231282333","rc":[{"batl":[[0,5,1.05],[1,7,1.56]],"ltp":2.04,"tv":10.68,"id":25173012}]}]}
{"op":"mcm","clk":"11761560085","pt":1722655816003,"mc":[{"id":"1.231282333","rc":[{"batl":[[0,3,1.18],[1,6,1.56],[2,7,0.78]],"ltp":2.04,"tv":10.68,"id":25173012}]}]}
{"op":"mcm","clk":"11761560549","pt":1722655827014,"mc":[{"id":"1.231282333","rc":[{"batl":[[1,5,1.05],[2,7,1.56]],"ltp":2.04,"tv":10.68,"id":25173012}]}]}
{"op":"mcm","clk":"11761560933","pt":1722655838020,"mc":[{"id":"1.231282333","rc":[{"batl":[[1,5,1.33]],"ltp":2.04,"tv":10.68,"id":25173012}]}]}
{"op":"mcm","clk":"11761561459","pt":1722655853922,"mc":[{"id":"1.231282333","rc":[{"batl":[[2,6.6,1.51]],"ltp":2.04,"tv":10.68,"id":25173012}]}]}
{"op":"mcm","clk":"11761568811","pt":1722656041138,"mc":[{"id":"1.231282333","rc":[{"batl":[[1,5,1.33],[2,7,1.56]],"ltp":1.96,"tv":19.01,"id":71847983}]}]}
{"op":"mcm","clk":"11761569282","pt":1722656053956,"mc":[{"id":"1.231282333","rc":[{"batl":[[1,5,1.6]],"ltp":1.96,"tv":19.01,"id":71847983}]}]}
{"op":"mcm","clk":"11761569750","pt":1722656065949,"mc":[{"id":"1.231282333","rc":[{"batl":[[1,3,1.73],[2,6,1.56]],"ltp":1.96,"tv":19.01,"id":71847983}]}]}
{"op":"mcm","clk":"11761570219","pt":1722656077990,"mc":[{"id":"1.231282333","rc":[{"batl":[[2,6,1.74]],"ltp":1.96,"tv":19.01,"id":71847983}]}]}
{"op":"mcm","clk":"11761570709","pt":1722656088914,"mc":[{"id":"1.231282333","rc":[{"batl":[[2,5,1.14]],"ltp":1.96,"tv":19.01,"id":71847983}]}]}
{"op":"mcm","clk":"11761949846","pt":1722665517962,"mc":[{"id":"1.231282333","rc":[{"trd":[[1.89,8.3]],"batb":[[0,1.89,49.47]],"ltp":1.89,"tv":20.03,"id":71847983}],"tv":30.72}]}
{"op":"mcm","clk":"11761949971","pt":1722665520957,"mc":[{"id":"1.231282333","rc":[{"batb":[[0,1.89,49.98]],"ltp":1.89,"tv":20.03,"id":71847983}]}]}
{"op":"mcm","clk":"11762044876","pt":1722667959181,"mc":[{"id":"1.231282333","rc":[{"batl":[[0,1.96,632.54]],"ltp":1.89,"tv":20.03,"id":71847983}]}]}
{"op":"mcm","clk":"11762076655","pt":1722668779417,"mc":[{"id":"1.231282333","rc":[{"batl":[[0,1.95,16.9],[1,1.96,632.54],[2,3,1.73]],"ltp":1.89,"tv":20.03,"id":71847983},{"batb":[[0,2.06,16.25],[1,2.02,43.61],[2,1.74,17.32]],"ltp":2.04,"tv":10.68,"id":25173012}]}]}
{"op":"mcm","clk":"11762289159","pt":1722672265870,"mc":[{"id":"1.231282333","rc":[{"batb":[[0,1.8,32],[1,1.74,17.32],[2,1.05,5.19]],"ltp":1.89,"tv":20.03,"id":71847983},{"batb":[[1,1.74,17.32],[2,1.03,201.56]],"ltp":2.04,"tv":10.68,"id":25173012}]}]}
{"op":"mcm","clk":"11762325862","pt":1722672795287,"mc":[{"id":"1.231282333","rc":[{"batl":[[1,1.96,24.84]],"ltp":1.89,"tv":20.03,"id":71847983}]}]}
{"op":"mcm","clk":"11762326067","pt":1722672797877,"mc":[{"id":"1.231282333","rc":[{"batl":[[0,1.96,24.84],[1,3,1.73],[2,5,1.14]],"ltp":1.89,"tv":20.03,"id":71847983},{"batb":[[0,1.74,17.32],[1,1.03,201.56],[2,1.02,296.83]],"ltp":2.04,"tv":10.68,"id":25173012}]}]}
{"op":"mcm","clk":"11762529893","pt":1722675104009,"mc":[{"id":"1.231282333","rc":[{"batl":[[0,1.96,26.66]],"ltp":1.89,"tv":20.03,"id":71847983}]}]}
{"op":"mcm","clk":"11762530945","pt":1722675111101,"mc":[{"id":"1.231282333","rc":[{"batl":[[0,1.95,1.82],[1,1.96,24.84],[2,3,1.73]],"ltp":1.89,"tv":20.03,"id":71847983}]}]}
{"op":"mcm","clk":"11762549314","pt":1722675302331,"mc":[{"id":"1.231282333","rc":[{"batb":[[0,1.89,49.98],[1,1.8,32],[2,1.74,17.32]],"ltp":1.89,"tv":20.03,"id":71847983},{"batb":[[0,2.02,43.61],[1,1.74,17.32],[2,1.03,201.56]],"ltp":2.04,"tv":10.68,"id":25173012}]}]}
{"op":"mcm","clk":"11762875299","pt":1722678259023,"mc":[{"id":"1.231282333","rc":[{"batb":[[1,1.8,82.99],[2,1.74,17.32]],"ltp":2.04,"tv":10.68,"id":25173012}]}]}
{"op":"mcm","clk":"11762876182","pt":1722678266917,"mc":[{"id":"1.231282333","rc":[{"batb":[[2,1.75,88.52]],"ltp":1.89,"tv":20.03,"id":71847983}]}]}
{"op":"mcm","clk":"11762916140","pt":1722678621952,"mc":[{"id":"1.231282333","rc":[{"batl":[[0,1.96,24.84],[1,3,1.73],[2,5,1.14]],"ltp":1.89,"tv":20.03,"id":71847983}]}]}
{"op":"mcm","clk":"11762984825","pt":1722679263062,"mc":[{"id":"1.231282333","rc":[{"trd":[[1.96,4.44]],"batl":[[0,1.96,20.68]],"ltp":1.96,"tv":24.19,"id":71847983},{"trd":[[2.04,4.27]],"ltp":2.04,"tv":14.68,"id":25173012}],"tv":38.88}]}
{"op":"mcm","clk":"11763066448","pt":1722679887510,"mc":[{"id":"1.231282333","rc":[{"trd":[[1.89,108.26]],"batb":[[0,1.8,32],[1,1.75,88.52],[2,1.74,17.32]],"batl":[[0,1.89,434.67],[1,1.96,20.68],[2,3,1.73]],"ltp":1.89,"tv":124.15,"id":71847983}],"tv":138.84}]}
{"op":"mcm","clk":"11763066676","pt":1722679889234,"mc":[{"id":"1.231282333","rc":[{"batb":[[0,1.85,52.33],[1,1.8,32],[2,1.75,88.52]],"ltp":1.89,"tv":124.15,"id":71847983}]}]}
{"op":"mcm","clk":"11763069153","pt":1722679908162,"mc":[{"id":"1.231282333","rc":[{"batl":[[0,1.96,20.68],[1,3,1.73],[2,5,1.14]],"ltp":1.89,"tv":124.15,"id":71847983}]}]}
{"op":"mcm","clk":"11763115034","pt":1722680160094,"mc":[{"id":"1.231282333","rc":[{"batb":[[0,1.83,53.59]],"ltp":1.89,"tv":124.15,"id":71847983},{"batb":[[0,2.1,40.44]],"ltp":2.04,"tv":14.68,"id":25173012}]}]}
{"op":"mcm","clk":"11763391510","pt":1722682131466,"mc":[{"id":"1.231282333","rc":[{"batb":[[1,1.8,37]],"ltp":1.89,"tv":124.15,"id":71847983}]}]}
{"op":"mcm","clk":"11763462958","pt":1722682705349,"mc":[{"id":"1.231282333","rc":[{"batb":[[0,1.9,24.23],[1,1.83,53.59],[2,1.8,37]],"ltp":1.89,"tv":124.15,"id":71847983}]}]}
{"op":"mcm","clk":"11763462972","pt":1722682705453,"mc":[{"id":"1.231282333","rc":[{"trd":[[1.9,11.16]],"batb":[[0,1.9,13.07]],"ltp":1.9,"tv":135.31,"id":71847983},{"trd":[[2.12,10]],"ltp":2.12,"tv":24.68,"id":25173012}],"tv":160.0}]}
{"op":"mcm","clk":"11763541096","pt":1722683193318,"mc":[{"id":"1.231282333","rc":[{"trd":[[1.9,22.32]],"batb":[[0,1.9,1.91]],"ltp":1.9,"tv":146.47,"id":71847983},{"trd":[[2.12,20]],"ltp":2.12,"tv":34.68,"id":25173012}],"tv":181.16}]}
{"op":"mcm","clk":"11763576252","pt":1722683395593,"mc":[{"id":"1.231282333","rc":[{"trd":[[1.9,24.23]],"batb":[[0,1.83,53.59],[1,1.8,37],[2,1.75,88.52]],"ltp":1.9,"tv":148.38,"id":71847983},{"trd":[[2.12,21.71]],"batb":[[0,2.14,2],[1,2.12,8.29],[2,2.1,40.44]],"ltp":2.12,"tv":36.39,"id":25173012}],"tv":184.78}]}
{"op":"mcm","clk":"11763576636","pt":1722683397788,"mc":[{"id":"1.231282333","rc":[{"batb":[[0,2.12,8.29],[1,2.1,40.44],[2,1.8,82.99]],"ltp":2.12,"tv":36.39,"id":25173012}]}]}
{"op":"mcm","clk":"11763576802","pt":1722683398681,"mc":[{"id":"1.231282333","rc":[{"batb":[[0,2.1,40.44],[1,1.8,82.99],[2,1.74,17.32]],"ltp":2.12,"tv":36.39,"id":25173012}]}]}
{"op":"mcm","clk":"11763643007","pt":1722683782649,"mc":[{"id":"1.231282333","rc":[{"batl":[[0,1.9,151.92],[1,1.96,20.68],[2,3,1.73]],"ltp":1.9,"tv":148.38,"id":71847983},{"batb":[[0,2.12,12],[1,2.1,40.44],[2,1.8,82.99]],"ltp":2.12,"tv":36.39,"id":25173012}]}]}
{"op":"mcm","clk":"11763643455","pt":1722683784934,"mc":[{"id":"1.231282333","rc":[{"batb":[[0,2.12,10]],"ltp":2.12,"tv":36.39,"id":25173012}]}]}
{"op":"mcm","clk":"11763643596","pt":1722683785839,"mc":[{"id":"1.231282333","rc":[{"batb":[[0,2.1,40.44],[1,1.8,82.99],[2,1.74,17.32]],"ltp":2.12,"tv":36.39,"id":25173012}]}]}
{"op":"mcm","clk":"11763714159","pt":1722684222237,"mc":[{"id":"1.231282333","rc":[{"batb":[[0,2.12,12],[1,2.1,40.44],[2,1.8,82.99]],"ltp":2.12,"tv":36.39,"id":25173012}]}]}
{"op":"mcm","clk":"11763714564","pt":1722684224607,"mc":[{"id":"1.231282333","rc":[{"batb":[[0,2.12,10]],"ltp":2.12,"tv":36.39,"id":25173012}]}]}
{"op":"mcm","clk":"11763714710","pt":1722684225544,"mc":[{"id":"1.231282333","rc":[{"batb":[[0,2.1,40.44],[1,1.8,82.99],[2,1.74,17.32]],"ltp":2.12,"tv":36.39,"id":25173012}]}]}
{"op":"mcm","clk":"11763727978","pt":1722684306999,"mc":[{"id":"1.231282333","rc":[{"batb":[[0,2.12,12],[1,2.1,40.44],[2,1.8,82.99]],"ltp":2.12,"tv":36.39,"id":25173012}]}]}
{"op":"mcm","clk":"11763728576","pt":1722684310322,"mc":[{"id":"1.231282333","rc":[{"batb":[[0,2.1,40.44],[1,1.8,82.99],[2,1.74,17.32]],"ltp":2.12,"tv":36.39,"id":25173012}]}]}
{"op":"mcm","clk":"11763752189","pt":1722684457707,"mc":[{"id":"1.231282333","rc":[{"batb":[[0,2.12,12],[1,2.1,40.44],[2,1.8,82.99]],"ltp":2.12,"tv":36.39,"id":25173012}]}]}
{"op":"mcm","clk":"11763752553","pt":1722684459981,"mc":[{"id":"1.231282333","rc":[{"batb":[[0,2.12,10]],"ltp":2.12,"tv":36.39,"id":25173012}]}]}
{"op":"mcm","clk":"11763752707","pt":1722684460941,"mc":[{"id":"1.231282333","rc":[{"batb":[[0,2.1,40.44],[1,1.8,82.99],[2,1.74,17.32]],"ltp":2.12,"tv":36.39,"id":25173012}]}]}
{"op":"mcm","clk":"11763761552","pt":1722684515528,"mc":[{"id":"1.231282333","rc":[{"batl":[[0,1.89,7.46],[1,1.9,151.92],[2,1.96,20.68]],"ltp":1.9,"tv":148.38,"id":71847983},{"batb":[[0,2.14,12],[1,2.12,8.73],[2,2.1,40.44]],"ltp":2.12,"tv":36.39,"id":25173012}]}]}
{"op":"mcm","clk":"11763761920","pt":1722684517832,"mc":[{"id":"1.231282333","rc":[{"batb":[[0,2.14,10]],"ltp":2.12,"tv":36.39,"id":25173012}]}]}
{"op":"mcm","clk":"11763762063","pt":1722684518734,"mc":[{"id":"1.231282333","rc":[{"batb":[[0,2.12,8.73],[1,2.1,40.44],[2,1.8,82.99]],"ltp":2.12,"tv":36.39,"id":25173012}]}]}
{"op":"mcm","clk":"11763778357","pt":1722684617743,"mc":[{"id":"1.231282333","rc":[{"batl":[[0,1.9,151.92],[1,1.96,20.68],[2,3,1.73]],"ltp":1.9,"tv":148.38,"id":71847983},{"batb":[[0,2.12,12]],"ltp":2.12,"tv":36.39,"id":25173012}]}]}
{"op":"mcm","clk":"11763778793","pt":1722684620125,"mc":[{"id":"1.231282333","rc":[{"batb":[[0,2.12,10]],"ltp":2.12,"tv":36.39,"id":25173012}]}]}
{"op":"mcm","clk":"11763779003","pt":1722684621137,"mc":[{"id":"1.231282333","rc":[{"batb":[[0,2.1,40.44],[1,1.8,82.99],[2,1.74,17.32]],"ltp":2.12,"tv":36.39,"id":25173012}]}]}
{"op":"mcm","clk":"11763784028","pt":1722684650959,"mc":[{"id":"1.231282333","rc":[{"trd":[[1.83,53.59]],"batb":[[0,1.8,37],[1,1.75,88.52],[2,1.74,17.32]],"ltp":1.83,"tv":201.97,"id":71847983},{"trd":[[2.22,44.18]],"batb":[[0,2.24,12],[1,2.22,1894.22],[2,2.1,40.44]],"ltp":2.22,"tv":80.57,"id":25173012}],"tv":282.55}]}
{"op":"mcm","clk":"11763784441","pt":1722684653163,"mc":[{"id":"1.231282333","rc":[{"batb":[[0,2.24,10]],"ltp":2.22,"tv":80.57,"id":25173012}]}]}
{"op":"mcm","clk":"11763784584","pt":1722684654062,"mc":[{"id":"1.231282333","rc":[{"batb":[[0,2.22,1894.22],[1,1.8,82.99],[2,1.74,17.32]],"ltp":2.22,"tv":80.57,"id":25173012}]}]}
{"op":"mcm","clk":"11763912098","pt":1722685349755,"mc":[{"id":"1.231282333","rc":[{"trd":[[1.82,259.67]],"ltp":1.82,"tv":461.64,"id":71847983},{"trd":[[2.22,257.06]],"batb":[[0,2.24,12],[1,2.22,1681.34],[2,1.8,82.99]],"ltp":2.22,"tv":293.45,"id":25173012}],"tv":755.1}]}
{"op":"mcm","clk":"11763912485","pt":1722685351955,"mc":[{"id":"1.231282333","rc":[{"batb":[[0,2.24,10]],"ltp":2.22,"tv":293.45,"id":25173012}]}]}
{"op":"mcm","clk":"11763912686","pt":1722685353187,"mc":[{"id":"1.231282333","rc":[{"batb":[[0,2.22,1681.34],[1,1.8,82.99],[2,1.74,17.32]],"ltp":2.22,"tv":293.45,"id":25173012}]}]}
{"op":"mcm","clk":"11763913496","pt":1722685357890,"mc":[{"id":"1.231282333","rc":[{"batb":[[0,2.24,12],[1,2.22,1681.34],[2,1.8,82.99]],"ltp":2.22,"tv":293.45,"id":25173012}]}]}
{"op":"mcm","clk":"11763913888","pt":1722685360135,"mc":[{"id":"1.231282333","rc":[{"batb":[[0,2.24,10]],"ltp":2.22,"tv":293.45,"id":25173012}]}]}
{"op":"mcm","clk":"11763914049","pt":1722685361139,"mc":[{"id":"1.231282333","rc":[{"batb":[[0,2.22,1681.34],[1,1.8,82.99],[2,1.74,17.32]],"ltp":2.22,"tv":293.45,"id":25173012}]}]}
{"op":"mcm","clk":"11763942145","pt":1722685460760,"mc":[{"id":"1.231282333","rc":[{"batb":[[0,1.81,12]],"ltp":2.22,"tv":293.45,"id":25173012}]}]}
{"op":"mcm","clk":"11763942284","pt":1722685461649,"mc":[{"id":"1.231282333","rc":[{"batb":[[1,1.79,56.31],[2,1.75,88.52]],"ltp":1.82,"tv":461.64,"id":71847983},{"batb":[[0,2.1,40.44],[1,1.81,12],[2,1.8,82.99]],"ltp":2.22,"tv":293.45,"id":25173012}]}]}
{"op":"mcm","clk":"11763942492","pt":1722685462929,"mc":[{"id":"1.231282333","rc":[{"batb":[[1,1.81,10]],"ltp":2.22,"tv":293.45,"id":25173012}]}]}
{"op":"mcm","clk":"11763942673","pt":1722685464033,"mc":[{"id":"1.231282333","rc":[{"batb":[[1,1.8,82.99],[2,1.74,17.32]],"ltp":2.22,"tv":293.45,"id":25173012}]}]}
{"op":"mcm","clk":"11764035130","pt":1722686103358,"mc":[{"id":"1.231282333","rc":[{"batl":[[0,1.89,11.41],[1,1.9,151.92],[2,1.96,20.68]],"ltp":1.82,"tv":461.64,"id":71847983},{"batb":[[0,2.12,12],[1,2.1,40.44],[2,1.8,82.99]],"ltp":2.22,"tv":293.45,"id":25173012}]}]}
{"op":"mcm","clk":"11764035475","pt":1722686105583,"mc":[{"id":"1.231282333","rc":[{"batb":[[0,2.12,10]],"ltp":2.22,"tv":293.45,"id":25173012}]}]}
{"op":"mcm","clk":"11764035658","pt":1722686106755,"mc":[{"id":"1.231282333","rc":[{"batb":[[0,2.1,40.44],[1,1.8,82.99],[2,1.74,17.32]],"ltp":2.22,"tv":293.45,"id":25173012}]}]}
{"op":"mcm","clk":"11764043665","pt":1722686163739,"mc":[{"id":"1.231282333","rc":[{"batb":[[0,2.14,12],[1,2.12,13.36],[2,2.1,40.44]],"ltp":2.22,"tv":293.45,"id":25173012}]}]}
{"op":"mcm","clk":"11764043957","pt":1722686166135,"mc":[{"id":"1.231282333","rc":[{"batb":[[0,2.14,10]],"ltp":2.22,"tv":293.45,"id":25173012}]}]}
{"op":"mcm","clk":"11764044063","pt":1722686167036,"mc":[{"id":"1.231282333","rc":[{"batb":[[0,2.12,13.36],[1,2.1,40.44],[2,1.8,82.99]],"ltp":2.22,"tv":293.45,"id":25173012}]}]}
{"op":"mcm","clk":"11764170876","pt":1722686947816,"mc":[{"id":"1.231282333","rc":[{"batb":[[0,2.14,12],[1,2.12,13.36],[2,2.1,40.44]],"ltp":2.22,"tv":293.45,"id":25173012}]}]}
{"op":"mcm","clk":"11764171310","pt":1722686950114,"mc":[{"id":"1.231282333","rc":[{"batb":[[0,2.14,10]],"ltp":2.22,"tv":293.45,"id":25173012}]}]}
{"op":"mcm","clk":"11764171527","pt":1722686951238,"mc":[{"id":"1.231282333","rc":[{"batb":[[0,2.12,13.36],[1,2.1,40.44],[2,1.8,82.99]],"ltp":2.22,"tv":293.45,"id":25173012}]}]}
{"op":"mcm","clk":"11764184091","pt":1722687014625,"mc":[{"id":"1.231282333","rc":[{"batb":[[0,2.14,12],[1,2.12,13.36],[2,2.1,40.44]],"ltp":2.22,"tv":293.45,"id":25173012}]}]}
{"op":"mcm","clk":"11764184565","pt":1722687016900,"mc":[{"id":"1.231282333","rc":[{"batb":[[0,2.14,10]],"ltp":2.22,"tv":293.45,"id":25173012}]}]}
{"op":"mcm","clk":"11764184792","pt":1722687018021,"mc":[{"id":"1.231282333","rc":[{"batb":[[0,2.12,13.36],[1,2.1,40.44],[2,1.8,82.99]],"ltp":2.22,"tv":293.45,"id":25173012}]}]}
{"op":"mcm","clk":"11764239227","pt":1722687303620,"mc":[{"id":"1.231282333","rc":[{"batb":[[0,2.14,12],[1,2.12,13.36],[2,2.1,40.44]],"ltp":2.22,"tv":293.45,"id":25173012}]}]}
{"op":"mcm","clk":"11764239648","pt":1722687305814,"mc":[{"id":"1.231282333","rc":[{"batb":[[0,2.14,10]],"ltp":2.22,"tv":293.45,"id":25173012}]}]}
{"op":"mcm","clk":"11764239886","pt":1722687306928,"mc":[{"id":"1.231282333","rc":[{"batb":[[0,2.12,13.36],[1,2.1,40.44],[2,1.8,82.99]],"ltp":2.22,"tv":293.45,"id":25173012}]}]}
{"op":"mcm","clk":"11764247264","pt":1722687344963,"mc":[{"id":"1.231282333","rc":[{"batl":[[0,1.88,1.8],[1,1.89,11.41],[2,1.9,151.92]],"ltp":1.82,"tv":461.64,"id":71847983},{"batb":[[0,2.14,12],[1,2.12,13.36],[2,2.1,40.44]],"ltp":2.22,"tv":293.45,"id":25173012}]}]}
{"op":"mcm","clk":"11764247696","pt":1722687347165,"mc":[{"id":"1.231282333","rc":[{"batb":[[0,2.14,10]],"ltp":2.22,"tv":293.45,"id":25173012}]}]}
{"op":"mcm","clk":"11764247907","pt":1722687348277,"mc":[{"id":"1.231282333","rc":[{"batb":[[0,2.12,13.36],[1,2.1,40.44],[2,1.8,82.99]],"ltp":2.22,"tv":293.45,"id":25173012}]}]}
{"op":"mcm","clk":"11764256659","pt":1722687391922,"mc":[{"id":"1.231282333","rc":[{"batb":[[0,2.14,12],[1,2.12,13.36],[2,2.1,40.44]],"ltp":2.22,"tv":293.45,"id":25173012}]}]}
{"op":"mcm","clk":"11764257115","pt":1722687394204,"mc":[{"id":"1.231282333","rc":[{"batb":[[0,2.14,10]],"ltp":2.22,"tv":293.45,"id":25173012}]}]}
{"op":"mcm","clk":"11764257326","pt":1722687395313,"mc":[{"id":"1.231282333","rc":[{"batb":[[0,2.12,13.36],[1,2.1,40.44],[2,1.8,82.99]],"ltp":2.22,"tv":293.45,"id":25173012}]}]}
{"op":"mcm","clk":"11764308730","pt":1722687677098,"mc":[{"id":"1.231282333","rc":[{"batb":[[0,2.14,12],[1,2.12,13.36],[2,2.1,40.44]],"ltp":2.22,"tv":293.45,"id":25173012}]}]}
{"op":"mcm","clk":"11764309265","pt":1722687679837,"mc":[{"id":"1.231282333","rc":[{"batb":[[0,2.14,10]],"ltp":2.22,"tv":293.45,"id":25173012}]}]}
{"op":"mcm","clk":"11764309421","pt":1722687680643,"mc":[{"id":"1.231282333","rc":[{"batb":[[0,2.12,13.36],[1,2.1,40.44],[2,1.8,82.99]],"ltp":2.22,"tv":293.45,"id":25173012}]}]}
{"op":"mcm","clk":"11764370475","pt":1722688013083,"mc":[{"id":"1.231282333","rc":[{"batl":[[1,1.89,36.84]],"ltp":1.82,"tv":461.64,"id":71847983},{"batb":[[0,2.14,12],[1,2.12,13.36],[2,2.1,40.44]],"ltp":2.22,"tv":293.45,"id":25173012}]}]}
{"op":"mcm","clk":"11764370835","pt":1722688015285,"mc":[{"id":"1.231282333","rc":[{"batb":[[0,2.14,10]],"ltp":2.22,"tv":293.45,"id":25173012}]}]}
{"op":"mcm","clk":"11764371027","pt":1722688016505,"mc":[{"id":"1.231282333","rc":[{"batb":[[0,2.12,13.36],[1,2.1,40.44],[2,1.8,82.99]],"ltp":2.22,"tv":293.45,"id":25173012}]}]}
{"op":"mcm","clk":"11764372262","pt":1722688023784,"mc":[{"id":"1.231282333","rc":[{"trd":[[2.16,2.72]],"batb":[[0,2.14,12],[1,2.12,13.36],[2,2.1,40.44]],"ltp":2.16,"tv":296.18,"id":25173012}],"tv":757.82}]}
{"op":"mcm","clk":"11764372628","pt":1722688026022,"mc":[{"id":"1.231282333","rc":[{"batb":[[0,2.14,10]],"ltp":2.16,"tv":296.18,"id":25173012}]}]}
{"op":"mcm","clk":"11764372759","pt":1722688026923,"mc":[{"id":"1.231282333","rc":[{"batb":[[0,2.12,13.36],[1,2.1,40.44],[2,1.8,82.99]],"ltp":2.16,"tv":296.18,"id":25173012}]}]}
{"op":"mcm","clk":"11764374519","pt":1722688037212,"mc":[{"id":"1.231282333","rc":[{"batb":[[0,2.14,12],[1,2.12,13.36],[2,2.1,40.44]],"ltp":2.16,"tv":296.18,"id":25173012}]}]}
{"op":"mcm","clk":"11764374915","pt":1722688039306,"mc":[{"id":"1.231282333","rc":[{"batb":[[0,2.14,10]],"ltp":2.16,"tv":296.18,"id":25173012}]}]}
{"op":"mcm","clk":"11764375207","pt":1722688041328,"mc":[{"id":"1.231282333","rc":[{"trd":[[1.8,3.28]],"batb":[[0,1.8,35.36]],"ltp":1.8,"tv":464.92,"id":71847983},{"batb":[[0,2.12,13.36],[1,2.1,40.44],[2,1.8,82.99]],"ltp":2.16,"tv":296.18,"id":25173012}],"tv":761.1}]}
{"op":"mcm","clk":"11764375284","pt":1722688041803,"mc":[{"id":"1.231282333","rc":[{"batb":[[0,2.14,2],[1,2.12,13.36],[2,2.1,40.44]],"ltp":2.16,"tv":296.18,"id":25173012}]}]}
{"op":"mcm","clk":"11764375721","pt":1722688044257,"mc":[{"id":"1.231282333","rc":[{"batb":[[0,2.12,13.36],[1,2.1,40.44],[2,1.8,82.99]],"ltp":2.16,"tv":296.18,"id":25173012}]}]}
{"op":"mcm","clk":"11764375761","pt":1722688044461,"mc":[{"id":"1.231282333","rc":[{"batb":[[0,2.14,10],[1,2.12,13.36],[2,2.1,40.44]],"ltp":2.16,"tv":296.18,"id":25173012}]}]}
{"op":"mcm","clk":"11764376300","pt":1722688047729,"mc":[{"id":"1.231282333","rc":[{"batb":[[0,2.14,2]],"ltp":2.16,"tv":296.18,"id":25173012}]}]}
{"op":"mcm","clk":"11764376682","pt":1722688050128,"mc":[{"id":"1.231282333","rc":[{"batb":[[0,2.14,10]],"ltp":2.16,"tv":296.18,"id":25173012}]}]}
{"op":"mcm","clk":"11764377245","pt":1722688053507,"mc":[{"id":"1.231282333","rc":[{"batb":[[0,2.14,2]],"ltp":2.16,"tv":296.18,"id":25173012}]}]}
{"op":"mcm","clk":"11764377686","pt":1722688056134,"mc":[{"id":"1.231282333","rc":[{"batb":[[0,2.14,10]],"ltp":2.16,"tv":296.18,"id":25173012}]}]}
{"op":"mcm","clk":"11764378243","pt":1722688059313,"mc":[{"id":"1.231282333","rc":[{"batb":[[0,2.12,13.36],[1,2.1,40.44],[2,1.8,82.99]],"ltp":2.16,"tv":296.18,"id":25173012}]}]}
{"op":"mcm","clk":"11764378283","pt":1722688059511,"mc":[{"id":"1.231282333","rc":[{"batb":[[0,2.14,2],[1,2.12,13.36],[2,2.1,40.44]],"ltp":2.16,"tv":296.18,"id":25173012}]}]}
{"op":"mcm","clk":"11764378712","pt":1722688062128,"mc":[{"id":"1.231282333","rc":[{"batb":[[0,2.14,10]],"ltp":2.16,"tv":296.18,"id":25173012}]}]}
{"op":"mcm","clk":"11764379235","pt":1722688065335,"mc":[{"id":"1.231282333","rc":[{"batb":[[0,2.12,13.36],[1,2.1,40.44],[2,1.8,82.99]],"ltp":2.16,"tv":296.18,"id":25173012}]}]}
{"op":"mcm","clk":"11764379251","pt":1722688065436,"mc":[{"id":"1.231282333","rc":[{"batb":[[0,2.14,2],[1,2.12,13.36],[2,2.1,40.44]],"ltp":2.16,"tv":296.18,"id":25173012}]}]}
{"op":"mcm","clk":"11764379643","pt":1722688067834,"mc":[{"id":"1.231282333","rc":[{"batb":[[0,2.14,10]],"ltp":2.16,"tv":296.18,"id":25173012}]}]}
{"op":"mcm","clk":"11764380212","pt":1722688071234,"mc":[{"id":"1.231282333","rc":[{"batb":[[0,2.14,2]],"ltp":2.16,"tv":296.18,"id":25173012}]}]}
{"op":"mcm","clk":"11764380650","pt":1722688073879,"mc":[{"id":"1.231282333","rc":[{"batb":[[0,2.14,10]],"ltp":2.16,"tv":296.18,"id":25173012}]}]}
{"op":"mcm","clk":"11764380878","pt":1722688075237,"mc":[{"id":"1.231282333","rc":[{"batb":[[0,1.86,13.63],[1,1.8,35.36],[2,1.79,56.31]],"ltp":1.8,"tv":464.92,"id":71847983}]}]}
{"op":"mcm","clk":"11764381035","pt":1722688076041,"mc":[{"id":"1.231282333","rc":[{"batb":[[2,1.75,88.52]],"ltp":1.8,"tv":464.92,"id":71847983},{"batb":[[0,2.16,2],[1,2.14,10],[2,2.12,13.36]],"ltp":2.16,"tv":296.18,"id":25173012}]}]}
{"op":"mcm","clk":"11764381228","pt":1722688077136,"mc":[{"id":"1.231282333","rc":[{"batb":[[1,2.12,13.36],[2,1.8,82.99]],"ltp":2.16,"tv":296.18,"id":25173012}]}]}
{"op":"mcm","clk":"11764381445","pt":1722688078350,"mc":[{"id":"1.231282333","rc":[{"batb":[[0,2.12,13.36],[1,1.8,82.99],[2,1.74,17.32]],"ltp":2.16,"tv":296.18,"id":25173012}]}]}
{"op":"mcm","clk":"11764385941","pt":1722688104072,"mc":[{"id":"1.231282333","rc":[{"batb":[[0,1.8,35.36],[1,1.75,88.52],[2,1.74,17.32]],"ltp":1.8,"tv":464.92,"id":71847983},{"batb":[[0,2.14,12],[1,2.12,13.36],[2,1.8,82.99]],"ltp":2.16,"tv":296.18,"id":25173012}]}]}
{"op":"mcm","clk":"11764386323","pt":1722688106384,"mc":[{"id":"1.231282333","rc":[{"batb":[[1,1.79,56.31],[2,1.75,88.52]],"ltp":1.8,"tv":464.92,"id":71847983},{"batb":[[0,2.14,10],[2,2.1,40.44]],"ltp":2.16,"tv":296.18,"id":25173012}]}]}
{"op":"mcm","clk":"11764386471","pt":1722688107381,"mc":[{"id":"1.231282333","rc":[{"batb":[[0,2.12,13.36],[1,2.1,40.44],[2,1.8,82.99]],"ltp":2.16,"tv":296.18,"id":25173012}]}]}
{"op":"mcm","clk":"11764389480","pt":1722688126314,"mc":[{"id":"1.231282333","rc":[{"batl":[[0,1.81,13.63],[1,1.88,1.8],[2,1.89,36.84]],"ltp":1.8,"tv":464.92,"id":71847983},{"batb":[[0,2.14,12],[1,2.12,13.36],[2,2.1,40.44]],"ltp":2.16,"tv":296.18,"id":25173012}]}]}
{"op":"mcm","clk":"11764389865","pt":1722688128511,"mc":[{"id":"1.231282333","rc":[{"batl":[[2,1.89,25.42]],"ltp":1.8,"tv":464.92,"id":71847983},{"batb":[[0,2.14,10],[1,2.1,40.44],[2,1.8,82.99]],"ltp":2.16,"tv":296.18,"id":25173012}]}]}
{"op":"mcm","clk":"11764390079","pt":1722688129720,"mc":[{"id":"1.231282333","rc":[{"batb":[[0,2.1,40.44],[1,1.8,82.99],[2,1.74,17.32]],"ltp":2.16,"tv":296.18,"id":25173012}]}]}
{"op":"mcm","clk":"11764393107","pt":1722688146813,"mc":[{"id":"1.231282333","rc":[{"batl":[[0,1.88,1.8],[1,1.89,25.42],[2,1.9,151.92]],"ltp":1.8,"tv":464.92,"id":71847983},{"batb":[[0,2.12,12],[1,2.1,40.44],[2,1.8,82.99]],"ltp":2.16,"tv":296.18,"id":25173012}]}]}
{"op":"mcm","clk":"11764393504","pt":1722688149035,"mc":[{"id":"1.231282333","rc":[{"batb":[[0,2.12,10]],"ltp":2.16,"tv":296.18,"id":25173012}]}]}
{"op":"mcm","clk":"11764393724","pt":1722688150240,"mc":[{"id":"1.231282333","rc":[{"batb":[[0,2.1,40.44],[1,1.8,82.99],[2,1.74,17.32]],"ltp":2.16,"tv":296.18,"id":25173012}]}]}
{"op":"mcm","clk":"11764401082","pt":1722688195167,"mc":[{"id":"1.231282333","rc":[{"batl":[[2,1.96,20.68]],"ltp":1.8,"tv":464.92,"id":71847983},{"batb":[[0,2.12,12],[1,2.1,40.44],[2,1.8,82.99]],"ltp":2.16,"tv":296.18,"id":25173012}]}]}
{"op":"mcm","clk":"11764401496","pt":1722688197457,"mc":[{"id":"1.231282333","rc":[{"batb":[[0,2.12,10]],"ltp":2.16,"tv":296.18,"id":25173012}]}]}
{"op":"mcm","clk":"11764401689","pt":1722688198570,"mc":[{"id":"1.231282333","rc":[{"batb":[[0,2.1,40.44],[1,1.8,82.99],[2,1.74,17.32]],"ltp":2.16,"tv":296.18,"id":25173012}]}]}
{"op":"mcm","clk":"11764498183","pt":1722688698810,"mc":[{"id":"1.231282333","rc":[{"batb":[[0,1.86,5],[1,1.8,35.36]],"ltp":1.8,"tv":464.92,"id":71847983},{"batb":[[0,2.12,12]],"ltp":2.16,"tv":296.18,"id":25173012}]}]}
{"op":"mcm","clk":"11764498609","pt":1722688700935,"mc":[{"id":"1.231282333","rc":[{"batb":[[0,2.12,10]],"ltp":2.16,"tv":296.18,"id":25173012}]}]}
{"op":"mcm","clk":"11764498816","pt":1722688701847,"mc":[{"id":"1.231282333","rc":[{"batb":[[0,1.8,82.99],[1,1.74,17.32],[2,1.5,232]],"ltp":2.16,"tv":296.18,"id":25173012}]}]}
{"op":"mcm","clk":"11764499232","pt":1722688703960,"mc":[{"id":"1.231282333","rc":[{"batb":[[2,1.79,56.31]],"ltp":1.8,"tv":464.92,"id":71847983},{"batb":[[0,2.12,2],[1,2.1,40.44],[2,1.8,82.99]],"ltp":2.16,"tv":296.18,"id":25173012}]}]}
{"op":"mcm","clk":"11764499681","pt":1722688706252,"mc":[{"id":"1.231282333","rc":[{"batb":[[0,2.1,40.44],[1,1.8,82.99],[2,1.74,17.32]],"ltp":2.16,"tv":296.18,"id":25173012}]}]}
{"op":"mcm","clk":"11764499712","pt":1722688706458,"mc":[{"id":"1.231282333","rc":[{"batb":[[0,2.12,10],[1,2.1,40.44],[2,1.8,82.99]],"ltp":2.16,"tv":296.18,"id":25173012}]}]}
{"op":"mcm","clk":"11764500187","pt":1722688709003,"mc":[{"id":"1.231282333","rc":[{"batb":[[2,1.75,88.52]],"ltp":1.8,"tv":464.92,"id":71847983},{"batb":[[0,2.14,2],[1,2.12,10]],"ltp":2.16,"tv":296.18,"id":25173012}]}]}
{"op":"mcm","clk":"11764500369","pt":1722688709742,"mc":[{"id":"1.231282333","rc":[{"batb":[[1,1.8,82.99],[2,1.74,17.32]],"ltp":2.16,"tv":296.18,"id":25173012}]}]}
{"op":"mcm","clk":"11764500666","pt":1722688711387,"mc":[{"id":"1.231282333","rc":[{"batb":[[0,1.8,82.99],[1,1.74,17.32],[2,1.5,232]],"ltp":2.16,"tv":296.18,"id":25173012}]}]}
{"op":"mcm","clk":"11764501123","pt":1722688713996,"mc":[{"id":"1.231282333","rc":[{"batb":[[2,1.79,56.31]],"ltp":1.8,"tv":464.92,"id":71847983},{"batb":[[0,2.12,12],[1,2.1,40.44],[2,1.8,82.99]],"ltp":2.16,"tv":296.18,"id":25173012}]}]}
{"op":"mcm","clk":"11764501529","pt":1722688716162,"mc":[{"id":"1.231282333","rc":[{"batb":[[0,2.12,10]],"ltp":2.16,"tv":296.18,"id":25173012}]}]}
{"op":"mcm","clk":"11764501741","pt":1722688717371,"mc":[{"id":"1.231282333","rc":[{"batb":[[0,2.1,40.44],[1,1.8,82.99],[2,1.74,17.32]],"ltp":2.16,"tv":296.18,"id":25173012}]}]}
{"op":"mcm","clk":"11764504913","pt":1722688734409,"mc":[{"id":"1.231282333","rc":[{"batb":[[0,2.12,12],[1,2.1,40.44],[2,1.8,82.99]],"ltp":2.16,"tv":296.18,"id":25173012}]}]}
{"op":"mcm","clk":"11764505373","pt":1722688736875,"mc":[{"id":"1.231282333","rc":[{"batb":[[0,2.12,10]],"ltp":2.16,"tv":296.18,"id":25173012}]}]}
{"op":"mcm","clk":"11764505534","pt":1722688737717,"mc":[{"id":"1.231282333","rc":[{"batb":[[0,2.1,40.44],[1,1.8,82.99],[2,1.74,17.32]],"ltp":2.16,"tv":296.18,"id":25173012}]}]}
{"op":"mcm","clk":"11764513567","pt":1722688777952,"mc":[{"id":"1.231282333","rc":[{"batb":[[0,2.12,12],[1,2.1,40.44],[2,1.8,82.99]],"ltp":2.16,"tv":296.18,"id":25173012}]}]}
{"op":"mcm","clk":"11764513822","pt":1722688779066,"mc":[{"id":"1.231282333","rc":[{"batb":[[2,1.75,88.52]],"ltp":1.8,"tv":464.92,"id":71847983},{"batb":[[1,1.8,82.99],[2,1.74,17.32]],"ltp":2.16,"tv":296.18,"id":25173012}]}]}
{"op":"mcm","clk":"11764514103","pt":1722688780352,"mc":[{"id":"1.231282333","rc":[{"batb":[[0,2.12,10]],"ltp":2.16,"tv":296.18,"id":25173012}]}]}
{"op":"mcm","clk":"11764514304","pt":1722688781348,"mc":[{"id":"1.231282333","rc":[{"batb":[[0,1.8,82.99],[1,1.74,17.32],[2,1.5,232]],"ltp":2.16,"tv":296.18,"id":25173012}]}]}
{"op":"mcm","clk":"11764514868","pt":1722688784268,"mc":[{"id":"1.231282333","rc":[{"batb":[[2,1.79,56.31]],"ltp":1.8,"tv":464.92,"id":71847983},{"batb":[[0,2.12,12],[1,2.1,40.44],[2,1.8,82.99]],"ltp":2.16,"tv":296.18,"id":25173012}]}]}
{"op":"mcm","clk":"11764515283","pt":1722688786436,"mc":[{"id":"1.231282333","rc":[{"batb":[[0,2.12,10]],"ltp":2.16,"tv":296.18,"id":25173012}]}]}
{"op":"mcm","clk":"11764515503","pt":1722688787436,"mc":[{"id":"1.231282333","rc":[{"batb":[[0,2.1,40.44],[1,1.8,82.99],[2,1.74,17.32]],"ltp":2.16,"tv":296.18,"id":25173012}]}]}
{"op":"mcm","clk":"11764532662","pt":1722688874327,"mc":[{"id":"1.231282333","rc":[{"batb":[[2,1.75,88.52]],"ltp":1.8,"tv":464.92,"id":71847983},{"batb":[[0,2.12,12]],"ltp":2.16,"tv":296.18,"id":25173012}]}]}
{"op":"mcm","clk":"11764533127","pt":1722688876643,"mc":[{"id":"1.231282333","rc":[{"batb":[[0,2.12,10]],"ltp":2.16,"tv":296.18,"id":25173012}]}]}
{"op":"mcm","clk":"11764533345","pt":1722688877656,"mc":[{"id":"1.231282333","rc":[{"batb":[[0,1.8,82.99],[1,1.74,17.32],[2,1.5,232]],"ltp":2.16,"tv":296.18,"id":25173012}]}]}
{"op":"mcm","clk":"11764533729","pt":1722688879532,"mc":[{"id":"1.231282333","rc":[{"batb":[[2,1.79,56.31]],"ltp":1.8,"tv":464.92,"id":71847983},{"batb":[[0,2.12,2],[1,2.1,40.44],[2,1.8,82.99]],"ltp":2.16,"tv":296.18,"id":25173012}]}]}
{"op":"mcm","clk":"11764534153","pt":1722688881858,"mc":[{"id":"1.231282333","rc":[{"batb":[[0,2.12,10]],"ltp":2.16,"tv":296.18,"id":25173012}]}]}
{"op":"mcm","clk":"11764534846","pt":1722688885243,"mc":[{"id":"1.231282333","rc":[{"batb":[[2,1.75,88.52]],"ltp":1.8,"tv":464.92,"id":71847983},{"batb":[[0,2.14,2],[1,1.8,82.99],[2,1.74,17.32]],"ltp":2.16,"tv":296.18,"id":25173012}]}]}
{"op":"mcm","clk":"11764535173","pt":1722688886733,"mc":[{"id":"1.231282333","rc":[{"batb":[[0,1.8,82.99],[1,1.74,17.32],[2,1.5,232]],"ltp":2.16,"tv":296.18,"id":25173012}]}]}
{"op":"mcm","clk":"11764535740","pt":1722688889650,"mc":[{"id":"1.231282333","rc":[{"batb":[[2,1.79,56.31]],"ltp":1.8,"tv":464.92,"id":71847983},{"batb":[[0,2.12,12],[1,2.1,40.44],[2,1.8,82.99]],"ltp":2.16,"tv":296.18,"id":25173012}]}]}
{"op":"mcm","clk":"11764536210","pt":1722688892092,"mc":[{"id":"1.231282333","rc":[{"batb":[[0,2.12,10]],"ltp":2.16,"tv":296.18,"id":25173012}]}]}
{"op":"mcm","clk":"11764536402","pt":1722688893024,"mc":[{"id":"1.231282333","rc":[{"batb":[[0,2.1,40.44],[1,1.8,82.99],[2,1.74,17.32]],"ltp":2.16,"tv":296.18,"id":25173012}]}]}
{"op":"mcm","clk":"11764540418","pt":1722688914222,"mc":[{"id":"1.231282333","rc":[{"batl":[[2,1.9,20.68]],"ltp":1.8,"tv":464.92,"id":71847983},{"batb":[[0,2.12,12],[1,2.1,40.44],[2,1.8,82.99]],"ltp":2.16,"tv":296.18,"id":25173012}]}]}
{"op":"mcm","clk":"11764540463","pt":1722688914532,"mc":[{"id":"1.231282333","rc":[{"batb":[[2,1.75,88.52]],"ltp":1.8,"tv":464.92,"id":71847983},{"batb":[[1,1.8,82.99],[2,1.74,17.32]],"ltp":2.16,"tv":296.18,"id":25173012}]}]}
{"op":"mcm","clk":"11764540815","pt":1722688916446,"mc":[{"id":"1.231282333","rc":[{"batb":[[0,2.12,10]],"ltp":2.16,"tv":296.18,"id":25173012}]}]}
{"op":"mcm","clk":"11764541033","pt":1722688917656,"mc":[{"id":"1.231282333","rc":[{"batb":[[0,1.8,82.99],[1,1.74,17.32],[2,1.5,232]],"ltp":2.16,"tv":296.18,"id":25173012}]}]}
{"op":"mcm","clk":"11764541445","pt":1722688919730,"mc":[{"id":"1.231282333","rc":[{"batb":[[2,1.79,56.31]],"ltp":1.8,"tv":464.92,"id":71847983},{"batb":[[0,2.12,2],[1,2.1,40.44],[2,1.8,82.99]],"ltp":2.16,"tv":296.18,"id":25173012}]}]}
{"op":"mcm","clk":"11764541981","pt":1722688922354,"mc":[{"id":"1.231282333","rc":[{"batb":[[0,2.12,10]],"ltp":2.16,"tv":296.18,"id":25173012}]}]}
{"op":"mcm","clk":"11764542484","pt":1722688924756,"mc":[{"id":"1.231282333","rc":[{"batb":[[2,1.75,88.52]],"ltp":1.8,"tv":464.92,"id":71847983},{"batb":[[0,2.14,2],[1,2.12,10]],"ltp":2.16,"tv":296.18,"id":25173012}]}]}
{"op":"mcm","clk":"11764542686","pt":1722688925659,"mc":[{"id":"1.231282333","rc":[{"batb":[[1,1.8,82.99],[2,1.74,17.32]],"ltp":2.16,"tv":296.18,"id":25173012}]}]}
{"op":"mcm","clk":"11764542992","pt":1722688927060,"mc":[{"id":"1.231282333","rc":[{"batb":[[0,1.8,82.99],[1,1.74,17.32],[2,1.5,232]],"ltp":2.16,"tv":296.18,"id":25173012}]}]}
{"op":"mcm","clk":"11764543596","pt":1722688929761,"mc":[{"id":"1.231282333","rc":[{"batb":[[2,1.79,56.31]],"ltp":1.8,"tv":464.92,"id":71847983},{"batb":[[0,2.12,12],[1,2.1,40.44],[2,1.8,82.99]],"ltp":2.16,"tv":296.18,"id":25173012}]}]}
{"op":"mcm","clk":"11764544010","pt":1722688932060,"mc":[{"id":"1.231282333","rc":[{"batb":[[0,2.12,10]],"ltp":2.16,"tv":296.18,"id":25173012}]}]}
{"op":"mcm","clk":"11764544187","pt":1722688932962,"mc":[{"id":"1.231282333","rc":[{"batb":[[0,2.1,40.44],[1,1.8,82.99],[2,1.74,17.32]],"ltp":2.16,"tv":296.18,"id":25173012}]}]}
{"op":"mcm","clk":"11764558273","pt":1722689002536,"mc":[{"id":"1.231282333","rc":[{"batb":[[0,2.12,12],[1,2.1,40.44],[2,1.8,82.99]],"ltp":2.16,"tv":296.18,"id":25173012}]}]}
{"op":"mcm","clk":"11764558725","pt":1722689004863,"mc":[{"id":"1.231282333","rc":[{"batb":[[2,1.75,88.52]],"ltp":1.8,"tv":464.92,"id":71847983},{"batb":[[0,2.12,10],[1,1.8,82.99],[2,1.74,17.32]],"ltp":2.16,"tv":296.18,"id":25173012}]}]}
{"op":"mcm","clk":"11764558954","pt":1722689006056,"mc":[{"id":"1.231282333","rc":[{"batb":[[0,1.8,82.99],[1,1.74,17.32],[2,1.5,232]],"ltp":2.16,"tv":296.18,"id":25173012}]}]}
{"op":"mcm","clk":"11764559780","pt":1722689009960,"mc":[{"id":"1.231282333","rc":[{"batb":[[2,1.79,56.31]],"ltp":1.8,"tv":464.92,"id":71847983},{"batb":[[0,2.12,12],[1,2.1,40.44],[2,1.8,82.99]],"ltp":2.16,"tv":296.18,"id":25173012}]}]}
{"op":"mcm","clk":"11764560225","pt":1722689012154,"mc":[{"id":"1.231282333","rc":[{"batb":[[0,2.12,10]],"ltp":2.16,"tv":296.18,"id":25173012}]}]}
{"op":"mcm","clk":"11764560443","pt":1722689013268,"mc":[{"id":"1.231282333","rc":[{"batb":[[0,2.1,40.44],[1,1.8,82.99],[2,1.74,17.32]],"ltp":2.16,"tv":296.18,"id":25173012}]}]}
{"op":"mcm","clk":"11764562786","pt":1722689025063,"mc":[{"id":"1.231282333","rc":[{"batb":[[0,2.12,12],[1,2.1,40.44],[2,1.8,82.99]],"ltp":2.16,"tv":296.18,"id":25173012}]}]}
{"op":"mcm","clk":"11764563242","pt":1722689027279,"mc":[{"id":"1.231282333","rc":[{"batb":[[0,2.12,10]],"ltp":2.16,"tv":296.18,"id":25173012}]}]}
{"op":"mcm","clk":"11764563482","pt":1722689028496,"mc":[{"id":"1.231282333","rc":[{"batb":[[0,2.1,40.44],[1,1.8,82.99],[2,1.74,17.32]],"ltp":2.16,"tv":296.18,"id":25173012}]}]}
{"op":"mcm","clk":"11764569066","pt":1722689056714,"mc":[{"id":"1.231282333","rc":[{"batb":[[0,2.12,12],[1,2.1,40.44],[2,1.8,82.99]],"ltp":2.16,"tv":296.18,"id":25173012}]}]}
{"op":"mcm","clk":"11764569515","pt":1722689059119,"mc":[{"id":"1.231282333","rc":[{"batb":[[0,2.12,10]],"ltp":2.16,"tv":296.18,"id":25173012}]}]}
{"op":"mcm","clk":"11764569713","pt":1722689060125,"mc":[{"id":"1.231282333","rc":[{"batb":[[2,1.75,88.52]],"ltp":1.8,"tv":464.92,"id":71847983},{"batb":[[0,1.8,82.99],[1,1.74,17.32],[2,1.5,232]],"ltp":2.16,"tv":296.18,"id":25173012}]}]}
{"op":"mcm","clk":"11764570750","pt":1722689065257,"mc":[{"id":"1.231282333","rc":[{"batb":[[2,1.79,56.31]],"ltp":1.8,"tv":464.92,"id":71847983},{"batb":[[0,2.12,12],[1,2.1,40.44],[2,1.8,82.99]],"ltp":2.16,"tv":296.18,"id":25173012}]}]}
{"op":"mcm","clk":"11764571349","pt":1722689068339,"mc":[{"id":"1.231282333","rc":[{"batb":[[0,2.1,40.44],[1,1.8,82.99],[2,1.74,17.32]],"ltp":2.16,"tv":296.18,"id":25173012}]}]}
{"op":"mcm","clk":"11764593722","pt":1722689179266,"mc":[{"id":"1.231282333","rc":[{"batb":[[0,2.12,12],[1,2.1,40.44],[2,1.8,82.99]],"ltp":2.16,"tv":296.18,"id":25173012}]}]}
{"op":"mcm","clk":"11764593956","pt":1722689180484,"mc":[{"id":"1.231282333","rc":[{"batb":[[2,1.75,88.52]],"ltp":1.8,"tv":464.92,"id":71847983},{"batb":[[1,1.8,82.99],[2,1.74,17.32]],"ltp":2.16,"tv":296.18,"id":25173012}]}]}
{"op":"mcm","clk":"11764594195","pt":1722689181681,"mc":[{"id":"1.231282333","rc":[{"batb":[[0,2.12,10]],"ltp":2.16,"tv":296.18,"id":25173012}]}]}
{"op":"mcm","clk":"11764594358","pt":1722689182671,"mc":[{"id":"1.231282333","rc":[{"batb":[[0,1.8,82.99],[1,1.74,17.32],[2,1.5,232]],"ltp":2.16,"tv":296.18,"id":25173012}]}]}
{"op":"mcm","clk":"11764594592","pt":1722689183985,"mc":[{"id":"1.231282333","rc":[{"batb":[[0,1.81,2],[1,1.8,82.99],[2,1.74,17.32]],"ltp":2.16,"tv":296.18,"id":25173012}]}]}
{"op":"mcm","clk":"11764595035","pt":1722689186294,"mc":[{"id":"1.231282333","rc":[{"batb":[[2,1.79,56.31]],"ltp":1.8,"tv":464.92,"id":71847983},{"batb":[[0,2.12,10],[1,2.1,40.44],[2,1.8,82.99]],"ltp":2.16,"tv":296.18,"id":25173012}]}]}
{"op":"mcm","clk":"11764595497","pt":1722689188859,"mc":[{"id":"1.231282333","rc":[{"batb":[[0,2.14,2]],"ltp":2.16,"tv":296.18,"id":25173012}]}]}
{"op":"mcm","clk":"11764595924","pt":1722689191276,"mc":[{"id":"1.231282333","rc":[{"batb":[[0,2.12,10]],"ltp":2.16,"tv":296.18,"id":25173012}]}]}
{"op":"mcm","clk":"11764596631","pt":1722689194758,"mc":[{"id":"1.231282333","rc":[{"batb":[[0,2.12,2]],"ltp":2.16,"tv":296.18,"id":25173012}]}]}
{"op":"mcm","clk":"11764597133","pt":1722689197390,"mc":[{"id":"1.231282333","rc":[{"batb":[[0,2.12,10]],"ltp":2.16,"tv":296.18,"id":25173012}]}]}
{"op":"mcm","clk":"11764597768","pt":1722689200792,"mc":[{"id":"1.231282333","rc":[{"batb":[[2,1.75,88.52]],"ltp":1.8,"tv":464.92,"id":71847983},{"batb":[[0,2.14,2],[1,1.8,82.99],[2,1.74,17.32]],"ltp":2.16,"tv":296.18,"id":25173012}]}]}
{"op":"mcm","clk":"11764598237","pt":1722689203157,"mc":[{"id":"1.231282333","rc":[{"batb":[[0,1.81,10]],"ltp":2.16,"tv":296.18,"id":25173012}]}]}
{"op":"mcm","clk":"11764598749","pt":1722689205812,"mc":[{"id":"1.231282333","rc":[{"batb":[[2,1.79,56.31]],"ltp":1.8,"tv":464.92,"id":71847983},{"batb":[[0,2.12,2],[1,2.1,40.44],[2,1.81,10]],"ltp":2.16,"tv":296.18,"id":25173012}]}]}
{"op":"mcm","clk":"11764598898","pt":1722689206605,"mc":[{"id":"1.231282333","rc":[{"batb":[[2,1.8,82.99]],"ltp":2.16,"tv":296.18,"id":25173012}]}]}
{"op":"mcm","clk":"11764599218","pt":1722689208295,"mc":[{"id":"1.231282333","rc":[{"batb":[[0,2.1,40.44],[1,1.8,82.99],[2,1.74,17.32]],"ltp":2.16,"tv":296.18,"id":25173012}]}]}
{"op":"mcm","clk":"11764602268","pt":1722689225022,"mc":[{"id":"1.231282333","rc":[{"batb":[[0,2.12,12],[1,2.1,40.44],[2,1.8,82.99]],"ltp":2.16,"tv":296.18,"id":25173012}]}]}
{"op":"mcm","clk":"11764602425","pt":1722689225908,"mc":[{"id":"1.231282333","rc":[{"batb":[[2,1.75,88.52]],"ltp":1.8,"tv":464.92,"id":71847983},{"batb":[[1,1.8,82.99],[2,1.74,17.32]],"ltp":2.16,"tv":296.18,"id":25173012}]}]}
{"op":"mcm","clk":"11764602645","pt":1722689227194,"mc":[{"id":"1.231282333","rc":[{"batb":[[0,2.12,10]],"ltp":2.16,"tv":296.18,"id":25173012}]}]}
{"op":"mcm","clk":"11764602848","pt":1722689228207,"mc":[{"id":"1.231282333","rc":[{"batb":[[0,1.8,82.99],[1,1.74,17.32],[2,1.5,232]],"ltp":2.16,"tv":296.18,"id":25173012}]}]}
{"op":"mcm","clk":"11764603404","pt":1722689231111,"mc":[{"id":"1.231282333","rc":[{"batb":[[2,1.79,56.31]],"ltp":1.8,"tv":464.92,"id":71847983},{"batb":[[0,2.12,12],[1,2.1,40.44],[2,1.8,82.99]],"ltp":2.16,"tv":296.18,"id":25173012}]}]}
{"op":"mcm","clk":"11764603850","pt":1722689233484,"mc":[{"id":"1.231282333","rc":[{"batb":[[0,2.12,10]],"ltp":2.16,"tv":296.18,"id":25173012}]}]}
{"op":"mcm","clk":"11764604043","pt":1722689234526,"mc":[{"id":"1.231282333","rc":[{"batb":[[0,2.1,40.44],[1,1.8,82.99],[2,1.74,17.32]],"ltp":2.16,"tv":296.18,"id":25173012}]}]}
{"op":"mcm","clk":"11764604885","pt":1722689238405,"mc":[{"id":"1.231282333","rc":[{"batb":[[0,2.12,12],[1,2.1,40.44],[2,1.8,82.99]],"ltp":2.16,"tv":296.18,"id":25173012}]}]}
{"op":"mcm","clk":"11764605408","pt":1722689240896,"mc":[{"id":"1.231282333","rc":[{"batb":[[2,1.75,88.52]],"ltp":1.8,"tv":464.92,"id":71847983},{"batb":[[0,2.12,10],[1,1.8,82.99],[2,1.74,17.32]],"ltp":2.16,"tv":296.18,"id":25173012}]}]}
{"op":"mcm","clk":"11764605558","pt":1722689241637,"mc":[{"id":"1.231282333","rc":[{"batb":[[0,1.8,82.99],[1,1.74,17.32],[2,1.5,232]],"ltp":2.16,"tv":296.18,"id":25173012}]}]}
{"op":"mcm","clk":"11764606359","pt":1722689245923,"mc":[{"id":"1.231282333","rc":[{"batb":[[2,1.79,56.31]],"ltp":1.8,"tv":464.92,"id":71847983},{"batb":[[0,2.1,40.44],[1,1.81,12],[2,1.8,82.99]],"ltp":2.16,"tv":296.18,"id":25173012}]}]}
{"op":"mcm","clk":"11764606755","pt":1722689248304,"mc":[{"id":"1.231282333","rc":[{"batb":[[1,1.81,10]],"ltp":2.16,"tv":296.18,"id":25173012}]}]}
{"op":"mcm","clk":"11764606929","pt":1722689249203,"mc":[{"id":"1.231282333","rc":[{"batb":[[1,1.8,82.99],[2,1.74,17.32]],"ltp":2.16,"tv":296.18,"id":25173012}]}]}
{"op":"mcm","clk":"11764607887","pt":1722689254424,"mc":[{"id":"1.231282333","rc":[{"batb":[[0,2.12,12],[1,2.1,40.44],[2,1.8,82.99]],"ltp":2.16,"tv":296.18,"id":25173012}]}]}
{"op":"mcm","clk":"11764608159","pt":1722689256060,"mc":[{"id":"1.231282333","rc":[{"batb":[[2,1.75,88.52]],"ltp":1.8,"tv":464.92,"id":71847983},{"batb":[[1,1.8,82.99],[2,1.74,17.32]],"ltp":2.16,"tv":296.18,"id":25173012}]}]}
{"op":"mcm","clk":"11764608277","pt":1722689256643,"mc":[{"id":"1.231282333","rc":[{"batb":[[0,2.12,10]],"ltp":2.16,"tv":296.18,"id":25173012}]}]}
{"op":"mcm","clk":"11764608501","pt":1722689257845,"mc":[{"id":"1.231282333","rc":[{"batb":[[0,1.8,82.99],[1,1.74,17.32],[2,1.5,232]],"ltp":2.16,"tv":296.18,"id":25173012}]}]}
{"op":"mcm","clk":"11764609105","pt":1722689261230,"mc":[{"id":"1.231282333","rc":[{"batb":[[2,1.79,56.31]],"ltp":1.8,"tv":464.92,"id":71847983},{"batb":[[0,2.12,12],[1,2.1,40.44],[2,1.8,82.99]],"ltp":2.16,"tv":296.18,"id":25173012}]}]}
{"op":"mcm","clk":"11764609506","pt":1722689263535,"mc":[{"id":"1.231282333","rc":[{"batb":[[0,2.12,10]],"ltp":2.16,"tv":296.18,"id":25173012}]}]}
{"op":"mcm","clk":"11764609682","pt":1722689264548,"mc":[{"id":"1.231282333","rc":[{"batb":[[0,2.1,40.44],[1,1.8,82.99],[2,1.74,17.32]],"ltp":2.16,"tv":296.18,"id":25173012}]}]}
{"op":"mcm","clk":"11764610747","pt":1722689270364,"mc":[{"id":"1.231282333","rc":[{"batb":[[0,2.12,12],[1,2.1,40.44],[2,1.8,82.99]],"ltp":2.16,"tv":296.18,"id":25173012}]}]}
{"op":"mcm","clk":"11764610895","pt":1722689271155,"mc":[{"id":"1.231282333","rc":[{"batb":[[2,1.75,88.52]],"ltp":1.8,"tv":464.92,"id":71847983},{"batb":[[1,1.8,82.99],[2,1.74,17.32]],"ltp":2.16,"tv":296.18,"id":25173012}]}]}
{"op":"mcm","clk":"11764611147","pt":1722689272635,"mc":[{"id":"1.231282333","rc":[{"batb":[[0,2.12,10]],"ltp":2.16,"tv":296.18,"id":25173012}]}]}
{"op":"mcm","clk":"11764611312","pt":1722689273639,"mc":[{"id":"1.231282333","rc":[{"batb":[[0,1.8,82.99],[1,1.74,17.32],[2,1.5,232]],"ltp":2.16,"tv":296.18,"id":25173012}]}]}
{"op":"mcm","clk":"11764611567","pt":1722689275158,"mc":[{"id":"1.231282333","rc":[{"batb":[[0,1.81,2],[1,1.8,82.99],[2,1.74,17.32]],"ltp":2.16,"tv":296.18,"id":25173012}]}]}
{"op":"mcm","clk":"11764611743","pt":1722689276277,"mc":[{"id":"1.231282333","rc":[{"batb":[[2,1.79,56.31]],"ltp":1.8,"tv":464.92,"id":71847983},{"batb":[[0,2.12,10],[1,2.1,40.44],[2,1.81,2]],"ltp":2.16,"tv":296.18,"id":25173012}]}]}
{"op":"mcm","clk":"11764611934","pt":1722689277451,"mc":[{"id":"1.231282333","rc":[{"batb":[[2,1.8,82.99]],"ltp":2.16,"tv":296.18,"id":25173012}]}]}
{"op":"mcm","clk":"11764612340","pt":1722689279975,"mc":[{"id":"1.231282333","rc":[{"batb":[[0,2.14,2]],"ltp":2.16,"tv":296.18,"id":25173012}]}]}
{"op":"mcm","clk":"11764612852","pt":1722689282675,"mc":[{"id":"1.231282333","rc":[{"batb":[[0,2.12,10]],"ltp":2.16,"tv":296.18,"id":25173012}]}]}
{"op":"mcm","clk":"11764613315","pt":1722689285068,"mc":[{"id":"1.231282333","rc":[{"batb":[[0,2.14,2],[1,2.12,10],[2,2.1,40.44]],"ltp":2.16,"tv":296.18,"id":25173012}]}]}
{"op":"mcm","clk":"11764613516","pt":1722689286194,"mc":[{"id":"1.231282333","rc":[{"batb":[[2,1.75,88.52]],"ltp":1.8,"tv":464.92,"id":71847983},{"batb":[[1,1.8,82.99],[2,1.74,17.32]],"ltp":2.16,"tv":296.18,"id":25173012}]}]}
{"op":"mcm","clk":"11764613708","pt":1722689287271,"mc":[{"id":"1.231282333","rc":[{"batb":[[0,1.8,82.99],[1,1.74,17.32],[2,1.5,232]],"ltp":2.16,"tv":296.18,"id":25173012}]}]}
{"op":"mcm","clk":"11764614312","pt":1722689290371,"mc":[{"id":"1.231282333","rc":[{"batb":[[0,1.81,12],[1,1.8,82.99],[2,1.74,17.32]],"ltp":2.16,"tv":296.18,"id":25173012}]}]}
{"op":"mcm","clk":"11764614451","pt":1722689291192,"mc":[{"id":"1.231282333","rc":[{"batb":[[2,1.79,56.31]],"ltp":1.8,"tv":464.92,"id":71847983},{"batb":[[0,2.1,40.44],[1,1.81,12],[2,1.8,82.99]],"ltp":2.16,"tv":296.18,"id":25173012}]}]}
{"op":"mcm","clk":"11764614744","pt":1722689292790,"mc":[{"id":"1.231282333","rc":[{"batb":[[1,1.81,10]],"ltp":2.16,"tv":296.18,"id":25173012}]}]}
{"op":"mcm","clk":"11764614920","pt":1722689293792,"mc":[{"id":"1.231282333","rc":[{"batb":[[1,1.8,82.99],[2,1.74,17.32]],"ltp":2.16,"tv":296.18,"id":25173012}]}]}
{"op":"mcm","clk":"11764615433","pt":1722689296724,"mc":[{"id":"1.231282333","rc":[{"batb":[[0,2.12,12],[1,2.1,40.44],[2,1.8,82.99]],"ltp":2.16,"tv":296.18,"id":25173012}]}]}
{"op":"mcm","clk":"11764615852","pt":1722689299116,"mc":[{"id":"1.231282333","rc":[{"batb":[[0,2.12,10]],"ltp":2.16,"tv":296.18,"id":25173012}]}]}
{"op":"mcm","clk":"11764615997","pt":1722689299968,"mc":[{"id":"1.231282333","rc":[{"batb":[[0,2.1,40.44],[1,1.8,82.99],[2,1.74,17.32]],"ltp":2.16,"tv":296.18,"id":25173012}]}]}
{"op":"mcm","clk":"11764616459","pt":1722689302706,"mc":[{"id":"1.231282333","rc":[{"batb":[[0,2.12,12],[1,2.1,40.44],[2,1.8,82.99]],"ltp":2.16,"tv":296.18,"id":25173012}]}]}
{"op":"mcm","clk":"11764616830","pt":1722689304801,"mc":[{"id":"1.231282333","rc":[{"batb":[[0,2.12,10]],"ltp":2.16,"tv":296.18,"id":25173012}]}]}
{"op":"mcm","clk":"11764617012","pt":1722689305990,"mc":[{"id":"1.231282333","rc":[{"batb":[[0,2.1,40.44],[1,1.8,82.99],[2,1.74,17.32]],"ltp":2.16,"tv":296.18,"id":25173012}]}]}
{"op":"mcm","clk":"11764617337","pt":1722689307908,"mc":[{"id":"1.231282333","rc":[{"batb":[[0,2.12,2],[1,2.1,40.44],[2,1.8,82.99]],"ltp":2.16,"tv":296.18,"id":25173012}]}]}
{"op":"mcm","clk":"11764617931","pt":1722689311339,"mc":[{"id":"1.231282333","rc":[{"batb":[[2,1.75,88.52]],"ltp":1.8,"tv":464.92,"id":71847983},{"batb":[[0,2.12,10],[1,1.8,82.99],[2,1.74,17.32]],"ltp":2.16,"tv":296.18,"id":25173012}]}]}
{"op":"mcm","clk":"11764618149","pt":1722689312610,"mc":[{"id":"1.231282333","rc":[{"batb":[[0,2.14,2],[1,2.12,10],[2,1.8,82.99]],"ltp":2.16,"tv":296.18,"id":25173012}]}]}
{"op":"mcm","clk":"11764618366","pt":1722689313889,"mc":[{"id":"1.231282333","rc":[{"batb":[[1,1.8,82.99],[2,1.74,17.32]],"ltp":2.16,"tv":296.18,"id":25173012}]}]}
{"op":"mcm","clk":"11764618544","pt":1722689314783,"mc":[{"id":"1.231282333","rc":[{"batb":[[0,1.8,82.99],[1,1.74,17.32],[2,1.5,232]],"ltp":2.16,"tv":296.18,"id":25173012}]}]}
{"op":"mcm","clk":"11764618808","pt":1722689316330,"mc":[{"id":"1.231282333","rc":[{"batb":[[2,1.79,56.31]],"ltp":1.8,"tv":464.92,"id":71847983},{"batb":[[0,2.1,40.44],[1,1.81,10],[2,1.8,82.99]],"ltp":2.16,"tv":296.18,"id":25173012}]}]}
{"op":"mcm","clk":"11764618989","pt":1722689317511,"mc":[{"id":"1.231282333","rc":[{"batb":[[0,2.12,2],[1,2.1,40.44],[2,1.81,10]],"ltp":2.16,"tv":296.18,"id":25173012}]}]}
{"op":"mcm","clk":"11764619382","pt":1722689319951,"mc":[{"id":"1.231282333","rc":[{"batb":[[0,2.1,40.44],[1,1.8,82.99],[2,1.74,17.32]],"ltp":2.16,"tv":296.18,"id":25173012}]}]}
{"op":"mcm","clk":"11764619841","pt":1722689322606,"mc":[{"id":"1.231282333","rc":[{"batb":[[0,2.12,12],[1,2.1,40.44],[2,1.8,82.99]],"ltp":2.16,"tv":296.18,"id":25173012}]}]}
{"op":"mcm","clk":"11764620176","pt":1722689324945,"mc":[{"id":"1.231282333","rc":[{"batb":[[0,2.12,10]],"ltp":2.16,"tv":296.18,"id":25173012}]}]}
{"op":"mcm","clk":"11764620360","pt":1722689325899,"mc":[{"id":"1.231282333","rc":[{"batb":[[0,2.1,40.44],[1,1.8,82.99],[2,1.74,17.32]],"ltp":2.16,"tv":296.18,"id":25173012}]}]}
{"op":"mcm","clk":"11764620919","pt":1722689329134,"mc":[{"id":"1.231282333","rc":[{"batb":[[0,2.12,12],[1,2.1,40.44],[2,1.8,82.99]],"ltp":2.16,"tv":296.18,"id":25173012}]}]}
{"op":"mcm","clk":"11764621286","pt":1722689331356,"mc":[{"id":"1.231282333","rc":[{"batb":[[0,2.12,10]],"ltp":2.16,"tv":296.18,"id":25173012}]}]}
{"op":"mcm","clk":"11764621307","pt":1722689331419,"mc":[{"id":"1.231282333","rc":[{"batb":[[2,1.75,88.52]],"ltp":1.8,"tv":464.92,"id":71847983},{"batb":[[1,1.8,82.99],[2,1.74,17.32]],"ltp":2.16,"tv":296.18,"id":25173012}]}]}
{"op":"mcm","clk":"11764621459","pt":1722689332436,"mc":[{"id":"1.231282333","rc":[{"batb":[[0,1.8,82.99],[1,1.74,17.32],[2,1.5,232]],"ltp":2.16,"tv":296.18,"id":25173012}]}]}
{"op":"mcm","clk":"11764621693","pt":1722689333743,"mc":[{"id":"1.231282333","rc":[{"batb":[[0,1.81,2],[1,1.8,82.99],[2,1.74,17.32]],"ltp":2.16,"tv":296.18,"id":25173012}]}]}
{"op":"mcm","clk":"11764622124","pt":1722689336258,"mc":[{"id":"1.231282333","rc":[{"batb":[[0,1.81,10]],"ltp":2.16,"tv":296.18,"id":25173012}]}]}
{"op":"mcm","clk":"11764622159","pt":1722689336433,"mc":[{"id":"1.231282333","rc":[{"batb":[[2,1.79,56.31]],"ltp":1.8,"tv":464.92,"id":71847983},{"batb":[[0,2.1,40.44],[1,1.81,10],[2,1.8,82.99]],"ltp":2.16,"tv":296.18,"id":25173012}]}]}
{"op":"mcm","clk":"11764622729","pt":1722689339785,"mc":[{"id":"1.231282333","rc":[{"batb":[[0,2.12,2],[1,2.1,40.44]],"ltp":2.16,"tv":296.18,"id":25173012}]}]}
{"op":"mcm","clk":"11764623145","pt":1722689342278,"mc":[{"id":"1.231282333","rc":[{"batb":[[0,2.12,10]],"ltp":2.16,"tv":296.18,"id":25173012}]}]}
{"op":"mcm","clk":"11764623785","pt":1722689345692,"mc":[{"id":"1.231282333","rc":[{"batb":[[0,2.12,2]],"ltp":2.16,"tv":296.18,"id":25173012}]}]}
{"op":"mcm","clk":"11764624242","pt":1722689348171,"mc":[{"id":"1.231282333","rc":[{"batb":[[0,2.12,10]],"ltp":2.16,"tv":296.18,"id":25173012}]}]}
{"op":"mcm","clk":"11764624833","pt":1722689351390,"mc":[{"id":"1.231282333","rc":[{"batb":[[0,2.1,40.44],[1,1.8,82.99],[2,1.74,17.32]],"ltp":2.16,"tv":296.18,"id":25173012}]}]}
{"op":"mcm","clk":"11764624872","pt":1722689351599,"mc":[{"id":"1.231282333","rc":[{"batb":[[2,1.75,88.52]],"ltp":1.8,"tv":464.92,"id":71847983},{"batb":[[0,2.12,2]],"ltp":2.16,"tv":296.18,"id":25173012}]}]}
{"op":"mcm","clk":"11764625344","pt":1722689354102,"mc":[{"id":"1.231282333","rc":[{"batb":[[0,1.81,10]],"ltp":2.16,"tv":296.18,"id":25173012}]}]}
{"op":"mcm","clk":"11764625708","pt":1722689356103,"mc":[{"id":"1.231282333","rc":[{"batb":[[0,1.82,2],[1,1.81,10],[2,1.8,82.99]],"ltp":2.16,"tv":296.18,"id":25173012}]}]}
{"op":"mcm","clk":"11764625787","pt":1722689356499,"mc":[{"id":"1.231282333","rc":[{"batb":[[2,1.79,56.31]],"ltp":1.8,"tv":464.92,"id":71847983},{"batb":[[0,2.1,40.44],[1,1.82,2],[2,1.81,10]],"ltp":2.16,"tv":296.18,"id":25173012}]}]}
{"op":"mcm","clk":"11764626125","pt":1722689358305,"mc":[{"id":"1.231282333","rc":[{"batb":[[1,1.8,82.99],[2,1.74,17.32]],"ltp":2.16,"tv":296.18,"id":25173012}]}]}
{"op":"mcm","clk":"11764626576","pt":1722689360806,"mc":[{"id":"1.231282333","rc":[{"batb":[[0,2.12,12],[1,2.1,40.44],[2,1.8,82.99]],"ltp":2.16,"tv":296.18,"id":25173012}]}]}
{"op":"mcm","clk":"11764626741","pt":1722689361716,"mc":[{"id":"1.231282333","rc":[{"batb":[[2,1.75,88.52]],"ltp":1.8,"tv":464.92,"id":71847983},{"batb":[[1,1.8,82.99],[2,1.74,17.32]],"ltp":2.16,"tv":296.18,"id":25173012}]}]}
{"op":"mcm","clk":"11764626984","pt":1722689363085,"mc":[{"id":"1.231282333","rc":[{"batb":[[0,2.12,10]],"ltp":2.16,"tv":296.18,"id":25173012}]}]}
{"op":"mcm","clk":"11764627179","pt":1722689364104,"mc":[{"id":"1.231282333","rc":[{"batb":[[0,1.8,82.99],[1,1.74,17.32],[2,1.5,232]],"ltp":2.16,"tv":296.18,"id":25173012}]}]}
{"op":"mcm","clk":"11764627381","pt":1722689365405,"mc":[{"id":"1.231282333","rc":[{"batb":[[0,1.81,2],[1,1.8,82.99],[2,1.74,17.32]],"ltp":2.16,"tv":296.18,"id":25173012}]}]}
{"op":"mcm","clk":"11764627601","pt":1722689366809,"mc":[{"id":"1.231282333","rc":[{"batb":[[2,1.79,56.31]],"ltp":1.8,"tv":464.92,"id":71847983},{"batb":[[0,2.12,10],[1,2.1,40.44],[2,1.81,2]],"ltp":2.16,"tv":296.18,"id":25173012}]}]}
{"op":"mcm","clk":"11764627750","pt":1722689367815,"mc":[{"id":"1.231282333","rc":[{"batb":[[2,1.8,82.99]],"ltp":2.16,"tv":296.18,"id":25173012}]}]}
{"op":"mcm","clk":"11764628190","pt":1722689370317,"mc":[{"id":"1.231282333","rc":[{"batb":[[0,2.12,2]],"ltp":2.16,"tv":296.18,"id":25173012}]}]}
{"op":"mcm","clk":"11764628619","pt":1722689372704,"mc":[{"id":"1.231282333","rc":[{"batb":[[0,2.12,10]],"ltp":2.16,"tv":296.18,"id":25173012}]}]}
{"op":"mcm","clk":"11764629190","pt":1722689376133,"mc":[{"id":"1.231282333","rc":[{"batb":[[0,2.12,2]],"ltp":2.16,"tv":296.18,"id":25173012}]}]}
{"op":"mcm","clk":"11764629595","pt":1722689378309,"mc":[{"id":"1.231282333","rc":[{"batb":[[0,2.1,40.44],[1,1.8,82.99],[2,1.74,17.32]],"ltp":2.16,"tv":296.18,"id":25173012}]}]}
{"op":"mcm","clk":"11764629637","pt":1722689378545,"mc":[{"id":"1.231282333","rc":[{"batb":[[0,2.12,10],[1,2.1,40.44],[2,1.8,82.99]],"ltp":2.16,"tv":296.18,"id":25173012}]}]}
{"op":"mcm","clk":"11764630218","pt":1722689382692,"mc":[{"id":"1.231282333","rc":[{"batb":[[2,1.75,88.52]],"ltp":1.8,"tv":464.92,"id":71847983},{"batb":[[0,2.14,2],[1,1.8,82.99],[2,1.74,17.32]],"ltp":2.16,"tv":296.18,"id":25173012}]}]}
{"op":"mcm","clk":"11764630618","pt":1722689384128,"mc":[{"id":"1.231282333","rc":[{"batb":[[0,1.81,10]],"ltp":2.16,"tv":296.18,"id":25173012}]}]}
{"op":"mcm","clk":"11764631067","pt":1722689386720,"mc":[{"id":"1.231282333","rc":[{"batb":[[2,1.79,56.31]],"ltp":1.8,"tv":464.92,"id":71847983},{"batb":[[0,2.12,2],[1,2.1,40.44],[2,1.81,10]],"ltp":2.16,"tv":296.18,"id":25173012}]}]}
{"op":"mcm","clk":"11764631203","pt":1722689387444,"mc":[{"id":"1.231282333","rc":[{"batb":[[2,1.8,82.99]],"ltp":2.16,"tv":296.18,"id":25173012}]}]}
{"op":"mcm","clk":"11764631525","pt":1722689389035,"mc":[{"id":"1.231282333","rc":[{"batb":[[0,2.1,40.44],[1,1.8,82.99],[2,1.74,17.32]],"ltp":2.16,"tv":296.18,"id":25173012}]}]}
{"op":"mcm","clk":"11764631712","pt":1722689390238,"mc":[{"id":"1.231282333","rc":[{"batb":[[0,2.12,10],[1,2.1,40.44],[2,1.8,82.99]],"ltp":2.16,"tv":296.18,"id":25173012}]}]}
{"op":"mcm","clk":"11764631924","pt":1722689391742,"mc":[{"id":"1.231282333","rc":[{"batb":[[2,1.75,88.52]],"ltp":1.8,"tv":464.92,"id":71847983},{"batb":[[0,2.14,2],[1,2.12,10]],"ltp":2.16,"tv":296.18,"id":25173012}]}]}
{"op":"mcm","clk":"11764632304","pt":1722689394049,"mc":[{"id":"1.231282333","rc":[{"batb":[[0,1.8,82.99],[1,1.74,17.32],[2,1.5,232]],"ltp":2.16,"tv":296.18,"id":25173012}]}]}
{"op":"mcm","clk":"11764632760","pt":1722689396753,"mc":[{"id":"1.231282333","rc":[{"batb":[[2,1.79,56.31]],"ltp":1.8,"tv":464.92,"id":71847983},{"batb":[[0,2.1,40.44],[1,1.81,12],[2,1.8,82.99]],"ltp":2.16,"tv":296.18,"id":25173012}]}]}
{"op":"mcm","clk":"11764633118","pt":1722689398929,"mc":[{"id":"1.231282333","rc":[{"batb":[[1,1.81,10]],"ltp":2.16,"tv":296.18,"id":25173012}]}]}
{"op":"mcm","clk":"11764633268","pt":1722689399870,"mc":[{"id":"1.231282333","rc":[{"batb":[[1,1.8,82.99],[2,1.74,17.32]],"ltp":2.16,"tv":296.18,"id":25173012}]}]}
{"op":"mcm","clk":"11764633807","pt":1722689402856,"mc":[{"id":"1.231282333","rc":[{"batb":[[0,2.12,12],[1,2.1,40.44],[2,1.8,82.99]],"ltp":2.16,"tv":296.18,"id":25173012}]}]}
{"op":"mcm","clk":"11764634268","pt":1722689405149,"mc":[{"id":"1.231282333","rc":[{"batb":[[0,2.12,10]],"ltp":2.16,"tv":296.18,"id":25173012}]}]}
{"op":"mcm","clk":"11764634439","pt":1722689406062,"mc":[{"id":"1.231282333","rc":[{"batb":[[0,2.1,40.44],[1,1.8,82.99],[2,1.74,17.32]],"ltp":2.16,"tv":296.18,"id":25173012}]}]}
{"op":"mcm","clk":"11764634652","pt":1722689407262,"mc":[{"id":"1.231282333","rc":[{"batb":[[0,2.12,2],[1,2.1,40.44],[2,1.8,82.99]],"ltp":2.16,"tv":296.18,"id":25173012}]}]}
{"op":"mcm","clk":"11764635139","pt":1722689409770,"mc":[{"id":"1.231282333","rc":[{"batb":[[0,2.12,10]],"ltp":2.16,"tv":296.18,"id":25173012}]}]}
{"op":"mcm","clk":"11764635547","pt":1722689412053,"mc":[{"id":"1.231282333","rc":[{"batb":[[2,1.75,88.52]],"ltp":1.8,"tv":464.92,"id":71847983},{"batb":[[0,2.14,2],[1,2.12,10]],"ltp":2.16,"tv":296.18,"id":25173012}]}]}
{"op":"mcm","clk":"11764635727","pt":1722689413062,"mc":[{"id":"1.231282333","rc":[{"batb":[[1,1.8,82.99],[2,1.74,17.32]],"ltp":2.16,"tv":296.18,"id":25173012}]}]}
{"op":"mcm","clk":"11764635965","pt":1722689414468,"mc":[{"id":"1.231282333","rc":[{"batb":[[0,1.8,82.99],[1,1.74,17.32],[2,1.5,232]],"ltp":2.16,"tv":296.18,"id":25173012}]}]}
{"op":"mcm","clk":"11764636204","pt":1722689415691,"mc":[{"id":"1.231282333","rc":[{"batb":[[0,1.81,10],[1,1.8,82.99],[2,1.74,17.32]],"ltp":2.16,"tv":296.18,"id":25173012}]}]}
{"op":"mcm","clk":"11764636435","pt":1722689416871,"mc":[{"id":"1.231282333","rc":[{"batb":[[2,1.79,56.31]],"ltp":1.8,"tv":464.92,"id":71847983},{"batb":[[0,2.1,40.44],[1,1.82,2],[2,1.81,10]],"ltp":2.16,"tv":296.18,"id":25173012}]}]}
{"op":"mcm","clk":"11764636860","pt":1722689419069,"mc":[{"id":"1.231282333","rc":[{"batb":[[1,1.8,82.99],[2,1.74,17.32]],"ltp":2.16,"tv":296.18,"id":25173012}]}]}
{"op":"mcm","clk":"11764637336","pt":1722689421966,"mc":[{"id":"1.231282333","rc":[{"batb":[[2,1.75,88.52]],"ltp":1.8,"tv":464.92,"id":71847983},{"batb":[[0,2.12,12]],"ltp":2.16,"tv":296.18,"id":25173012}]}]}
{"op":"mcm","clk":"11764637676","pt":1722689423971,"mc":[{"id":"1.231282333","rc":[{"batb":[[0,2.12,10]],"ltp":2.16,"tv":296.18,"id":25173012}]}]}
{"op":"mcm","clk":"11764637840","pt":1722689424977,"mc":[{"id":"1.231282333","rc":[{"batb":[[0,1.8,82.99],[1,1.74,17.32],[2,1.5,232]],"ltp":2.16,"tv":296.18,"id":25173012}]}]}
{"op":"mcm","clk":"11764638065","pt":1722689426302,"mc":[{"id":"1.231282333","rc":[{"batb":[[0,1.81,2],[1,1.8,82.99],[2,1.74,17.32]],"ltp":2.16,"tv":296.18,"id":25173012}]}]}
{"op":"mcm","clk":"11764638214","pt":1722689427192,"mc":[{"id":"1.231282333","rc":[{"batb":[[2,1.79,56.31]],"ltp":1.8,"tv":464.92,"id":71847983},{"batb":[[0,2.12,10],[1,2.1,40.44],[2,1.81,2]],"ltp":2.16,"tv":296.18,"id":25173012}]}]}
{"op":"mcm","clk":"11764638458","pt":1722689429227,"mc":[{"id":"1.231282333","rc":[{"batb":[[2,1.8,82.99]],"ltp":2.16,"tv":296.18,"id":25173012}]}]}
{"op":"mcm","clk":"11764638752","pt":1722689430378,"mc":[{"id":"1.231282333","rc":[{"batb":[[0,2.1,40.44],[1,1.8,82.99],[2,1.74,17.32]],"ltp":2.16,"tv":296.18,"id":25173012}]}]}
{"op":"mcm","clk":"11764639294","pt":1722689433715,"mc":[{"id":"1.231282333","rc":[{"batb":[[0,2.12,12],[1,2.1,40.44],[2,1.8,82.99]],"ltp":2.16,"tv":296.18,"id":25173012}]}]}
{"op":"mcm","clk":"11764639698","pt":1722689436093,"mc":[{"id":"1.231282333","rc":[{"batb":[[0,2.12,10]],"ltp":2.16,"tv":296.18,"id":25173012}]}]}
{"op":"mcm","clk":"11764639850","pt":1722689437088,"mc":[{"id":"1.231282333","rc":[{"batb":[[2,1.75,88.52]],"ltp":1.8,"tv":464.92,"id":71847983},{"batb":[[0,1.8,82.99],[1,1.74,17.32],[2,1.5,232]],"ltp":2.16,"tv":296.18,"id":25173012}]}]}
{"op":"mcm","clk":"11764640473","pt":1722689440918,"mc":[{"id":"1.231282333","rc":[{"batb":[[0,1.81,12],[1,1.8,82.99],[2,1.74,17.32]],"ltp":2.16,"tv":296.18,"id":25173012}]}]}
{"op":"mcm","clk":"11764640661","pt":1722689442115,"mc":[{"id":"1.231282333","rc":[{"batb":[[2,1.79,56.31]],"ltp":1.8,"tv":464.92,"id":71847983},{"batb":[[0,2.1,40.44],[1,1.81,12],[2,1.8,82.99]],"ltp":2.16,"tv":296.18,"id":25173012}]}]}
{"op":"mcm","clk":"11764640846","pt":1722689443283,"mc":[{"id":"1.231282333","rc":[{"batb":[[1,1.81,10]],"ltp":2.16,"tv":296.18,"id":25173012}]}]}
{"op":"mcm","clk":"11764640974","pt":1722689444131,"mc":[{"id":"1.231282333","rc":[{"batb":[[1,1.8,82.99],[2,1.74,17.32]],"ltp":2.16,"tv":296.18,"id":25173012}]}]}
{"op":"mcm","clk":"11764641167","pt":1722689445407,"mc":[{"id":"1.231282333","rc":[{"batb":[[0,2.12,2],[1,2.1,40.44],[2,1.8,82.99]],"ltp":2.16,"tv":296.18,"id":25173012}]}]}
{"op":"mcm","clk":"11764641554","pt":1722689447814,"mc":[{"id":"1.231282333","rc":[{"batb":[[0,2.12,10]],"ltp":2.16,"tv":296.18,"id":25173012}]}]}
{"op":"mcm","clk":"11764642102","pt":1722689451203,"mc":[{"id":"1.231282333","rc":[{"batb":[[0,2.14,2]],"ltp":2.16,"tv":296.18,"id":25173012}]}]}
{"op":"mcm","clk":"11764642528","pt":1722689453905,"mc":[{"id":"1.231282333","rc":[{"batb":[[0,2.12,10]],"ltp":2.16,"tv":296.18,"id":25173012}]}]}
{"op":"mcm","clk":"11764642992","pt":1722689457257,"mc":[{"id":"1.231282333","rc":[{"batb":[[2,1.75,88.52]],"ltp":1.8,"tv":464.92,"id":71847983},{"batb":[[0,1.81,2],[1,1.8,82.99],[2,1.74,17.32]],"ltp":2.16,"tv":296.18,"id":25173012}]}]}
{"op":"mcm","clk":"11764643355","pt":1722689459651,"mc":[{"id":"1.231282333","rc":[{"batb":[[0,1.81,10]],"ltp":2.16,"tv":296.18,"id":25173012}]}]}
{"op":"mcm","clk":"11764643723","pt":1722689462354,"mc":[{"id":"1.231282333","rc":[{"batb":[[2,1.79,56.31]],"ltp":1.8,"tv":464.92,"id":71847983},{"batb":[[0,2.12,2],[1,2.1,40.44],[2,1.81,10]],"ltp":2.16,"tv":296.18,"id":25173012}]}]}
{"op":"mcm","clk":"11764643837","pt":1722689463037,"mc":[{"id":"1.231282333","rc":[{"batb":[[2,1.8,82.99]],"ltp":2.16,"tv":296.18,"id":25173012}]}]}
{"op":"mcm","clk":"11764644089","pt":1722689464638,"mc":[{"id":"1.231282333","rc":[{"batb":[[0,2.1,40.44],[1,1.8,82.99],[2,1.74,17.32]],"ltp":2.16,"tv":296.18,"id":25173012}]}]}
{"op":"mcm","clk":"11764644537","pt":1722689467649,"mc":[{"id":"1.231282333","rc":[{"batb":[[0,2.12,12],[1,2.1,40.44],[2,1.8,82.99]],"ltp":2.16,"tv":296.18,"id":25173012}]}]}
{"op":"mcm","clk":"11764644904","pt":1722689469979,"mc":[{"id":"1.231282333","rc":[{"batb":[[0,2.12,10]],"ltp":2.16,"tv":296.18,"id":25173012}]}]}
{"op":"mcm","clk":"11764645046","pt":1722689470827,"mc":[{"id":"1.231282333","rc":[{"batb":[[0,2.1,40.44],[1,1.8,82.99],[2,1.74,17.32]],"ltp":2.16,"tv":296.18,"id":25173012}]}]}
{"op":"mcm","clk":"11764645360","pt":1722689472973,"mc":[{"id":"1.231282333","rc":[{"batb":[[0,2.12,12],[1,2.1,40.44],[2,1.8,82.99]],"ltp":2.16,"tv":296.18,"id":25173012}]}]}
{"op":"mcm","clk":"11764645787","pt":1722689475343,"mc":[{"id":"1.231282333","rc":[{"batb":[[0,2.12,10]],"ltp":2.16,"tv":296.18,"id":25173012}]}]}
{"op":"mcm","clk":"11764645953","pt":1722689476353,"mc":[{"id":"1.231282333","rc":[{"batb":[[0,2.1,40.44],[1,1.8,82.99],[2,1.74,17.32]],"ltp":2.16,"tv":296.18,"id":25173012}]}]}
{"op":"mcm","clk":"11764646352","pt":1722689479008,"mc":[{"id":"1.231282333","rc":[{"batb":[[0,2.12,12],[1,2.1,40.44],[2,1.8,82.99]],"ltp":2.16,"tv":296.18,"id":25173012}]}]}
{"op":"mcm","clk":"11764646652","pt":1722689481174,"mc":[{"id":"1.231282333","rc":[{"batb":[[0,2.12,10]],"ltp":2.16,"tv":296.18,"id":25173012}]}]}
{"op":"mcm","clk":"11764646824","pt":1722689482341,"mc":[{"id":"1.231282333","rc":[{"batb":[[2,1.75,88.52]],"ltp":1.8,"tv":464.92,"id":71847983},{"batb":[[0,1.8,82.99],[1,1.74,17.32],[2,1.5,232]],"ltp":2.16,"tv":296.18,"id":25173012}]}]}
{"op":"mcm","clk":"11764646973","pt":1722689483449,"mc":[{"id":"1.231282333","rc":[{"batb":[[0,1.81,2],[1,1.8,82.99],[2,1.74,17.32]],"ltp":2.16,"tv":296.18,"id":25173012}]}]}
{"op":"mcm","clk":"11764647330","pt":1722689485876,"mc":[{"id":"1.231282333","rc":[{"batb":[[0,1.81,10]],"ltp":2.16,"tv":296.18,"id":25173012}]}]}
{"op":"mcm","clk":"11764647530","pt":1722689487268,"mc":[{"id":"1.231282333","rc":[{"batb":[[2,1.79,56.31]],"ltp":1.8,"tv":464.92,"id":71847983},{"batb":[[0,2.1,40.44],[1,1.81,10],[2,1.8,82.99]],"ltp":2.16,"tv":296.18,"id":25173012}]}]}
{"op":"mcm","clk":"11764647827","pt":1722689489381,"mc":[{"id":"1.231282333","rc":[{"batb":[[0,2.12,2],[1,2.1,40.44]],"ltp":2.16,"tv":296.18,"id":25173012}]}]}
{"op":"mcm","clk":"11764648254","pt":1722689492391,"mc":[{"id":"1.231282333","rc":[{"batb":[[2,1.75,88.52]],"ltp":1.8,"tv":464.92,"id":71847983},{"batb":[[0,2.12,10],[1,1.8,82.99],[2,1.74,17.32]],"ltp":2.16,"tv":296.18,"id":25173012}]}]}
{"op":"mcm","clk":"11764648639","pt":1722689495058,"mc":[{"id":"1.231282333","rc":[{"batb":[[0,2.14,2]],"ltp":2.16,"tv":296.18,"id":25173012}]}]}
{"op":"mcm","clk":"11764648976","pt":1722689497390,"mc":[{"id":"1.231282333","rc":[{"batb":[[2,1.79,56.31]],"ltp":1.8,"tv":464.92,"id":71847983},{"batb":[[0,2.1,40.44]],"ltp":2.16,"tv":296.18,"id":25173012}]}]}
{"op":"mcm","clk":"11764648994","pt":1722689497489,"mc":[{"id":"1.231282333","rc":[{"batb":[[1,1.81,10],[2,1.8,82.99]],"ltp":2.16,"tv":296.18,"id":25173012}]}]}
{"op":"mcm","clk":"11764649604","pt":1722689500994,"mc":[{"id":"1.231282333","rc":[{"batb":[[0,2.12,2],[1,2.1,40.44]],"ltp":2.16,"tv":296.18,"id":25173012}]}]}
{"op":"mcm","clk":"11764650176","pt":1722689504595,"mc":[{"id":"1.231282333","rc":[{"batb":[[0,2.12,10]],"ltp":2.16,"tv":296.18,"id":25173012}]}]}
{"op":"mcm","clk":"11764650518","pt":1722689507106,"mc":[{"id":"1.231282333","rc":[{"batb":[[0,2.14,2],[1,2.12,10],[2,2.1,40.44]],"ltp":2.16,"tv":296.18,"id":25173012}]}]}
{"op":"mcm","clk":"11764650661","pt":1722689508099,"mc":[{"id":"1.231282333","rc":[{"batb":[[2,1.75,88.52]],"ltp":1.8,"tv":464.92,"id":71847983},{"batb":[[1,1.8,82.99],[2,1.74,17.32]],"ltp":2.16,"tv":296.18,"id":25173012}]}]}
{"op":"mcm","clk":"11764650836","pt":1722689509305,"mc":[{"id":"1.231282333","rc":[{"batb":[[0,1.8,82.99],[1,1.74,17.32],[2,1.5,232]],"ltp":2.16,"tv":296.18,"id":25173012}]}]}
{"op":"mcm","clk":"11764651226","pt":1722689512404,"mc":[{"id":"1.231282333","rc":[{"batb":[[2,1.79,56.31]],"ltp":1.8,"tv":464.92,"id":71847983},{"batb":[[0,2.1,40.44],[1,1.81,12],[2,1.8,82.99]],"ltp":2.16,"tv":296.18,"id":25173012}]}]}
{"op":"mcm","clk":"11764651396","pt":1722689513666,"mc":[{"id":"1.231282333","rc":[{"batb":[[1,1.81,10]],"ltp":2.16,"tv":296.18,"id":25173012}]}]}
{"op":"mcm","clk":"11764651507","pt":1722689514610,"mc":[{"id":"1.231282333","rc":[{"batb":[[1,1.8,82.99],[2,1.74,17.32]],"ltp":2.16,"tv":296.18,"id":25173012}]}]}
{"op":"mcm","clk":"11764651847","pt":1722689516991,"mc":[{"id":"1.231282333","rc":[{"batb":[[0,2.12,12],[1,2.1,40.44],[2,1.8,82.99]],"ltp":2.16,"tv":296.18,"id":25173012}]}]}
{"op":"mcm","clk":"11764651930","pt":1722689517479,"mc":[{"id":"1.231282333","rc":[{"batb":[[2,1.75,88.52]],"ltp":1.8,"tv":464.92,"id":71847983},{"batb":[[1,1.8,82.99],[2,1.74,17.32]],"ltp":2.16,"tv":296.18,"id":25173012}]}]}
{"op":"mcm","clk":"11764652189","pt":1722689519385,"mc":[{"id":"1.231282333","rc":[{"batb":[[0,2.12,10]],"ltp":2.16,"tv":296.18,"id":25173012}]}]}
{"op":"mcm","clk":"11764652325","pt":1722689520381,"mc":[{"id":"1.231282333","rc":[{"batb":[[0,1.8,82.99],[1,1.74,17.32],[2,1.5,232]],"ltp":2.16,"tv":296.18,"id":25173012}]}]}
{"op":"mcm","clk":"11764652608","pt":1722689522601,"mc":[{"id":"1.231282333","rc":[{"batb":[[2,1.79,56.31]],"ltp":1.8,"tv":464.92,"id":71847983},{"batb":[[0,2.12,12],[1,2.1,40.44],[2,1.8,82.99]],"ltp":2.16,"tv":296.18,"id":25173012}]}]}
{"op":"mcm","clk":"11764652925","pt":1722689524824,"mc":[{"id":"1.231282333","rc":[{"batb":[[0,2.12,10]],"ltp":2.16,"tv":296.18,"id":25173012}]}]}
{"op":"mcm","clk":"11764653093","pt":1722689526021,"mc":[{"id":"1.231282333","rc":[{"batb":[[0,2.1,40.44],[1,1.8,82.99],[2,1.74,17.32]],"ltp":2.16,"tv":296.18,"id":25173012}]}]}
{"op":"mcm","clk":"11764653431","pt":1722689528739,"mc":[{"id":"1.231282333","rc":[{"batb":[[0,2.12,12],[1,2.1,40.44],[2,1.8,82.99]],"ltp":2.16,"tv":296.18,"id":25173012}]}]}
{"op":"mcm","clk":"11764653751","pt":1722689531030,"mc":[{"id":"1.231282333","rc":[{"batb":[[0,2.12,10]],"ltp":2.16,"tv":296.18,"id":25173012}]}]}
{"op":"mcm","clk":"11764653905","pt":1722689532247,"mc":[{"id":"1.231282333","rc":[{"batb":[[0,2.1,40.44],[1,1.8,82.99],[2,1.74,17.32]],"ltp":2.16,"tv":296.18,"id":25173012}]}]}
{"op":"mcm","clk":"11764654115","pt":1722689533717,"mc":[{"id":"1.231282333","rc":[{"batb":[[0,2.12,2],[1,2.1,40.44],[2,1.8,82.99]],"ltp":2.16,"tv":296.18,"id":25173012}]}]}
{"op":"mcm","clk":"11764654474","pt":1722689536139,"mc":[{"id":"1.231282333","rc":[{"batb":[[0,2.12,10]],"ltp":2.16,"tv":296.18,"id":25173012}]}]}
{"op":"mcm","clk":"11764654681","pt":1722689537599,"mc":[{"id":"1.231282333","rc":[{"batb":[[2,1.75,88.52]],"ltp":1.8,"tv":464.92,"id":71847983},{"batb":[[1,1.8,82.99],[2,1.74,17.32]],"ltp":2.16,"tv":296.18,"id":25173012}]}]}
{"op":"mcm","clk":"11764654863","pt":1722689538744,"mc":[{"id":"1.231282333","rc":[{"batb":[[0,2.14,2],[1,2.12,10],[2,1.8,82.99]],"ltp":2.16,"tv":296.18,"id":25173012}]}]}
{"op":"mcm","clk":"11764654980","pt":1722689539517,"mc":[{"id":"1.231282333","rc":[{"batb":[[1,1.8,82.99],[2,1.74,17.32]],"ltp":2.16,"tv":296.18,"id":25173012}]}]}
{"op":"mcm","clk":"11764655190","pt":1722689540962,"mc":[{"id":"1.231282333","rc":[{"batb":[[0,1.8,82.99],[1,1.74,17.32],[2,1.5,232]],"ltp":2.16,"tv":296.18,"id":25173012}]}]}
{"op":"mcm","clk":"11764655380","pt":1722689542384,"mc":[{"id":"1.231282333","rc":[{"batb":[[0,1.81,10],[1,1.8,82.99],[2,1.74,17.32]],"ltp":2.16,"tv":296.18,"id":25173012}]}]}
{"op":"mcm","clk":"11764655403","pt":1722689542478,"mc":[{"id":"1.231282333","rc":[{"batb":[[2,1.79,56.31]],"ltp":1.8,"tv":464.92,"id":71847983},{"batb":[[0,2.1,40.44],[1,1.81,10],[2,1.8,82.99]],"ltp":2.16,"tv":296.18,"id":25173012}]}]}
{"op":"mcm","clk":"11764655571","pt":1722689543690,"mc":[{"id":"1.231282333","rc":[{"batb":[[0,2.12,2],[1,2.1,40.44],[2,1.81,10]],"ltp":2.16,"tv":296.18,"id":25173012}]}]}
{"op":"mcm","clk":"11764655901","pt":1722689546099,"mc":[{"id":"1.231282333","rc":[{"batb":[[0,2.1,40.44],[1,1.8,82.99],[2,1.74,17.32]],"ltp":2.16,"tv":296.18,"id":25173012}]}]}
{"op":"mcm","clk":"11764656230","pt":1722689548474,"mc":[{"id":"1.231282333","rc":[{"batb":[[0,2.12,12],[1,2.1,40.44],[2,1.8,82.99]],"ltp":2.16,"tv":296.18,"id":25173012}]}]}
{"op":"mcm","clk":"11764656597","pt":1722689550908,"mc":[{"id":"1.231282333","rc":[{"batb":[[0,2.12,10]],"ltp":2.16,"tv":296.18,"id":25173012}]}]}
{"op":"mcm","clk":"11764656736","pt":1722689551805,"mc":[{"id":"1.231282333","rc":[{"batb":[[0,2.1,40.44],[1,1.8,82.99],[2,1.74,17.32]],"ltp":2.16,"tv":296.18,"id":25173012}]}]}
{"op":"mcm","clk":"11764657024","pt":1722689554174,"mc":[{"id":"1.231282333","rc":[{"batb":[[0,2.12,12],[1,2.1,40.44],[2,1.8,82.99]],"ltp":2.16,"tv":296.18,"id":25173012}]}]}
{"op":"mcm","clk":"11764657319","pt":1722689556505,"mc":[{"id":"1.231282333","rc":[{"batb":[[0,2.12,10]],"ltp":2.16,"tv":296.18,"id":25173012}]}]}
{"op":"mcm","clk":"11764657446","pt":1722689557518,"mc":[{"id":"1.231282333","rc":[{"batb":[[2,1.75,88.52]],"ltp":1.8,"tv":464.92,"id":71847983},{"batb":[[0,1.8,82.99],[1,1.74,17.32],[2,1.5,232]],"ltp":2.16,"tv":296.18,"id":25173012}]}]}
{"op":"mcm","clk":"11764657726","pt":1722689559606,"mc":[{"id":"1.231282333","rc":[{"batb":[[0,1.81,12],[1,1.8,82.99],[2,1.74,17.32]],"ltp":2.16,"tv":296.18,"id":25173012}]}]}
{"op":"mcm","clk":"11764658035","pt":1722689561826,"mc":[{"id":"1.231282333","rc":[{"batb":[[0,1.81,10]],"ltp":2.16,"tv":296.18,"id":25173012}]}]}
{"op":"mcm","clk":"11764658190","pt":1722689562938,"mc":[{"id":"1.231282333","rc":[{"batb":[[2,1.79,56.31]],"ltp":1.8,"tv":464.92,"id":71847983},{"batb":[[0,2.1,40.44]],"ltp":2.16,"tv":296.18,"id":25173012}]}]}
{"op":"mcm","clk":"11764658366","pt":1722689564409,"mc":[{"id":"1.231282333","rc":[{"batb":[[0,2.12,2],[1,2.1,40.44],[2,1.8,82.99]],"ltp":2.16,"tv":296.18,"id":25173012}]}]}
{"op":"mcm","clk":"11764658776","pt":1722689567041,"mc":[{"id":"1.231282333","rc":[{"batb":[[0,2.12,10]],"ltp":2.16,"tv":296.18,"id":25173012}]}]}
{"op":"mcm","clk":"11764658855","pt":1722689567626,"mc":[{"id":"1.231282333","rc":[{"batb":[[2,1.75,88.52]],"ltp":1.8,"tv":464.92,"id":71847983},{"batb":[[1,1.8,82.99],[2,1.74,17.32]],"ltp":2.16,"tv":296.18,"id":25173012}]}]}
{"op":"mcm","clk":"11764659212","pt":1722689570251,"mc":[{"id":"1.231282333","rc":[{"batb":[[0,2.14,2]],"ltp":2.16,"tv":296.18,"id":25173012}]}]}
{"op":"mcm","clk":"11764659469","pt":1722689572047,"mc":[{"id":"1.231282333","rc":[{"batb":[[0,1.8,82.99],[1,1.74,17.32],[2,1.5,232]],"ltp":2.16,"tv":296.18,"id":25173012}]}]}
{"op":"mcm","clk":"11764659582","pt":1722689572841,"mc":[{"id":"1.231282333","rc":[{"batb":[[2,1.79,56.31]],"ltp":1.8,"tv":464.92,"id":71847983},{"batb":[[0,2.12,10],[1,2.1,40.44],[2,1.8,82.99]],"ltp":2.16,"tv":296.18,"id":25173012}]}]}
{"op":"mcm","clk":"11764660049","pt":1722689576361,"mc":[{"id":"1.231282333","rc":[{"batb":[[0,2.12,2]],"ltp":2.16,"tv":296.18,"id":25173012}]}]}
{"op":"mcm","clk":"11764660448","pt":1722689578857,"mc":[{"id":"1.231282333","rc":[{"batb":[[0,2.12,10]],"ltp":2.16,"tv":296.18,"id":25173012}]}]}
{"op":"mcm","clk":"11764660919","pt":1722689582364,"mc":[{"id":"1.231282333","rc":[{"batb":[[0,2.12,2]],"ltp":2.16,"tv":296.18,"id":25173012}]}]}
{"op":"mcm","clk":"11764661214","pt":1722689584664,"mc":[{"id":"1.231282333","rc":[{"batb":[[0,2.12,10]],"ltp":2.16,"tv":296.18,"id":25173012}]}]}
{"op":"mcm","clk":"11764661519","pt":1722689587042,"mc":[{"id":"1.231282333","rc":[{"batb":[[0,2.14,2],[1,2.12,10],[2,2.1,40.44]],"ltp":2.16,"tv":296.18,"id":25173012}]}]}
{"op":"mcm","clk":"11764661624","pt":1722689587933,"mc":[{"id":"1.231282333","rc":[{"batb":[[2,1.75,88.52]],"ltp":1.8,"tv":464.92,"id":71847983},{"batb":[[1,1.8,82.99],[2,1.74,17.32]],"ltp":2.16,"tv":296.18,"id":25173012}]}]}
{"op":"mcm","clk":"11764661816","pt":1722689589472,"mc":[{"id":"1.231282333","rc":[{"batb":[[0,1.8,82.99],[1,1.74,17.32],[2,1.5,232]],"ltp":2.16,"tv":296.18,"id":25173012}]}]}
{"op":"mcm","clk":"11764661969","pt":1722689590790,"mc":[{"id":"1.231282333","rc":[{"batb":[[0,1.81,10],[1,1.8,82.99],[2,1.74,17.32]],"ltp":2.16,"tv":296.18,"id":25173012}]}]}
{"op":"mcm","clk":"11764662274","pt":1722689592886,"mc":[{"id":"1.231282333","rc":[{"batb":[[2,1.79,56.31]],"ltp":1.8,"tv":464.92,"id":71847983},{"batb":[[0,2.12,2],[1,2.1,40.44],[2,1.81,10]],"ltp":2.16,"tv":296.18,"id":25173012}]}]}
{"op":"mcm","clk":"11764662432","pt":1722689594095,"mc":[{"id":"1.231282333","rc":[{"batb":[[2,1.8,82.99]],"ltp":2.16,"tv":296.18,"id":25173012}]}]}
{"op":"mcm","clk":"11764662570","pt":1722689595039,"mc":[{"id":"1.231282333","rc":[{"batb":[[0,2.1,40.44],[1,1.8,82.99],[2,1.74,17.32]],"ltp":2.16,"tv":296.18,"id":25173012}]}]}
{"op":"mcm","clk":"11764662721","pt":1722689596204,"mc":[{"id":"1.231282333","rc":[{"batb":[[0,2.12,10],[1,2.1,40.44],[2,1.8,82.99]],"ltp":2.16,"tv":296.18,"id":25173012}]}]}
{"op":"mcm","clk":"11764662905","pt":1722689597370,"mc":[{"id":"1.231282333","rc":[{"batb":[[0,2.14,2],[1,2.12,10],[2,2.1,40.44]],"ltp":2.16,"tv":296.18,"id":25173012}]}]}
{"op":"mcm","clk":"11764662945","pt":1722689597676,"mc":[{"id":"1.231282333","rc":[{"batb":[[2,1.75,88.52]],"ltp":1.8,"tv":464.92,"id":71847983},{"batb":[[2,1.8,82.99]],"ltp":2.16,"tv":296.18,"id":25173012}]}]}
{"op":"mcm","clk":"11764663227","pt":1722689599684,"mc":[{"id":"1.231282333","rc":[{"batb":[[0,1.8,82.99],[1,1.74,17.32],[2,1.5,232]],"ltp":2.16,"tv":296.18,"id":25173012}]}]}
{"op":"mcm","clk":"11764663532","pt":1722689602294,"mc":[{"id":"1.231282333","rc":[{"batb":[[0,1.82,2],[1,1.81,10],[2,1.8,82.99]],"ltp":2.16,"tv":296.18,"id":25173012}]}]}
{"op":"mcm","clk":"11764663573","pt":1722689602669,"mc":[{"id":"1.231282333","rc":[{"batb":[[2,1.79,56.31]],"ltp":1.8,"tv":464.92,"id":71847983},{"batb":[[0,2.1,40.44],[1,1.82,2],[2,1.81,10]],"ltp":2.16,"tv":296.18,"id":25173012}]}]}
{"op":"mcm","clk":"11764663894","pt":1722689605185,"mc":[{"id":"1.231282333","rc":[{"batb":[[1,1.8,82.99],[2,1.74,17.32]],"ltp":2.16,"tv":296.18,"id":25173012}]}]}
{"op":"mcm","clk":"11764664317","pt":1722689608387,"mc":[{"id":"1.231282333","rc":[{"batb":[[0,2.12,12],[1,2.1,40.44],[2,1.8,82.99]],"ltp":2.16,"tv":296.18,"id":25173012}]}]}
{"op":"mcm","clk":"11764664620","pt":1722689610814,"mc":[{"id":"1.231282333","rc":[{"batb":[[0,2.12,10]],"ltp":2.16,"tv":296.18,"id":25173012}]}]}
{"op":"mcm","clk":"11764664733","pt":1722689611798,"mc":[{"id":"1.231282333","rc":[{"batb":[[0,2.1,40.44],[1,1.8,82.99],[2,1.74,17.32]],"ltp":2.16,"tv":296.18,"id":25173012}]}]}
{"op":"mcm","clk":"11764664888","pt":1722689613167,"mc":[{"id":"1.231282333","rc":[{"batb":[[0,2.12,2],[1,2.1,40.44],[2,1.8,82.99]],"ltp":2.16,"tv":296.18,"id":25173012}]}]}
{"op":"mcm","clk":"11764665246","pt":1722689615786,"mc":[{"id":"1.231282333","rc":[{"batb":[[0,2.12,10]],"ltp":2.16,"tv":296.18,"id":25173012}]}]}
{"op":"mcm","clk":"11764665524","pt":1722689618000,"mc":[{"id":"1.231282333","rc":[{"batb":[[2,1.75,88.52]],"ltp":1.8,"tv":464.92,"id":71847983},{"batb":[[0,2.14,2],[1,2.12,10]],"ltp":2.16,"tv":296.18,"id":25173012}]}]}
{"op":"mcm","clk":"11764665672","pt":1722689619207,"mc":[{"id":"1.231282333","rc":[{"batb":[[1,1.8,82.99],[2,1.74,17.32]],"ltp":2.16,"tv":296.18,"id":25173012}]}]}
{"op":"mcm","clk":"11764665812","pt":1722689620306,"mc":[{"id":"1.231282333","rc":[{"batb":[[0,1.8,82.99],[1,1.74,17.32],[2,1.5,232]],"ltp":2.16,"tv":296.18,"id":25173012}]}]}
{"op":"mcm","clk":"11764665997","pt":1722689621580,"mc":[{"id":"1.231282333","rc":[{"batb":[[0,1.81,10],[1,1.8,82.99],[2,1.74,17.32]],"ltp":2.16,"tv":296.18,"id":25173012}]}]}
{"op":"mcm","clk":"11764666166","pt":1722689622782,"mc":[{"id":"1.231282333","rc":[{"batb":[[2,1.79,56.31]],"ltp":1.8,"tv":464.92,"id":71847983},{"batb":[[0,2.1,40.44],[1,1.82,2],[2,1.81,10]],"ltp":2.16,"tv":296.18,"id":25173012}]}]}
{"op":"mcm","clk":"11764666504","pt":1722689625090,"mc":[{"id":"1.231282333","rc":[{"batb":[[1,1.8,82.99],[2,1.74,17.32]],"ltp":2.16,"tv":296.18,"id":25173012}]}]}
{"op":"mcm","clk":"11764666846","pt":1722689627778,"mc":[{"id":"1.231282333","rc":[{"batb":[[2,1.75,88.52]],"ltp":1.8,"tv":464.92,"id":71847983},{"batb":[[0,2.12,12]],"ltp":2.16,"tv":296.18,"id":25173012}]}]}
{"op":"mcm","clk":"11764667170","pt":1722689629883,"mc":[{"id":"1.231282333","rc":[{"batb":[[0,2.12,10]],"ltp":2.16,"tv":296.18,"id":25173012}]}]}
{"op":"mcm","clk":"11764667308","pt":1722689630894,"mc":[{"id":"1.231282333","rc":[{"batb":[[0,1.8,82.99],[1,1.74,17.32],[2,1.5,232]],"ltp":2.16,"tv":296.18,"id":25173012}]}]}
{"op":"mcm","clk":"11764667604","pt":1722689632987,"mc":[{"id":"1.231282333","rc":[{"batb":[[2,1.79,56.31]],"ltp":1.8,"tv":464.92,"id":71847983},{"batb":[[0,2.12,2],[1,2.1,40.44],[2,1.8,82.99]],"ltp":2.16,"tv":296.18,"id":25173012}]}]}
{"op":"mcm","clk":"11764667973","pt":1722689635618,"mc":[{"id":"1.231282333","rc":[{"batb":[[0,2.12,10]],"ltp":2.16,"tv":296.18,"id":25173012}]}]}
{"op":"mcm","clk":"11764668297","pt":1722689637992,"mc":[{"id":"1.231282333","rc":[{"batb":[[2,1.75,88.52]],"ltp":1.8,"tv":464.92,"id":71847983},{"batb":[[0,2.14,2],[1,2.12,10]],"ltp":2.16,"tv":296.18,"id":25173012}]}]}
{"op":"mcm","clk":"11764668400","pt":1722689638785,"mc":[{"id":"1.231282333","rc":[{"batb":[[1,1.8,82.99],[2,1.74,17.32]],"ltp":2.16,"tv":296.18,"id":25173012}]}]}
{"op":"mcm","clk":"11764668603","pt":1722689640418,"mc":[{"id":"1.231282333","rc":[{"batb":[[0,1.8,82.99],[1,1.74,17.32],[2,1.5,232]],"ltp":2.16,"tv":296.18,"id":25173012}]}]}
{"op":"mcm","clk":"11764668781","pt":1722689641561,"mc":[{"id":"1.231282333","rc":[{"batb":[[0,1.81,10],[1,1.8,82.99],[2,1.74,17.32]],"ltp":2.16,"tv":296.18,"id":25173012}]}]}
{"op":"mcm","clk":"11764668990","pt":1722689643034,"mc":[{"id":"1.231282333","rc":[{"batb":[[2,1.79,56.31]],"ltp":1.8,"tv":464.92,"id":71847983},{"batb":[[0,2.12,2],[1,2.1,40.44],[2,1.81,10]],"ltp":2.16,"tv":296.18,"id":25173012}]}]}
{"op":"mcm","clk":"11764669313","pt":1722689645320,"mc":[{"id":"1.231282333","rc":[{"batb":[[0,2.1,40.44],[1,1.8,82.99],[2,1.74,17.32]],"ltp":2.16,"tv":296.18,"id":25173012}]}]}
{"op":"mcm","clk":"11764669551","pt":1722689647221,"mc":[{"id":"1.231282333","rc":[{"batb":[[0,2.12,10],[1,2.1,40.44],[2,1.8,82.99]],"ltp":2.16,"tv":296.18,"id":25173012}]}]}
{"op":"mcm","clk":"11764669676","pt":1722689648130,"mc":[{"id":"1.231282333","rc":[{"batb":[[2,1.75,88.52]],"ltp":1.8,"tv":464.92,"id":71847983},{"batb":[[0,2.14,2],[1,2.12,10]],"ltp":2.16,"tv":296.18,"id":25173012}]}]}
{"op":"mcm","clk":"11764670020","pt":1722689650305,"mc":[{"id":"1.231282333","rc":[{"batb":[[0,2.12,10],[1,1.8,82.99],[2,1.74,17.32]],"ltp":2.16,"tv":296.18,"id":25173012}]}]}
{"op":"mcm","clk":"11764670071","pt":1722689650614,"mc":[{"id":"1.231282333","rc":[{"batb":[[0,1.8,82.99],[1,1.74,17.32],[2,1.5,232]],"ltp":2.16,"tv":296.18,"id":25173012}]}]}
{"op":"mcm","clk":"11764670451","pt":1722689653163,"mc":[{"id":"1.231282333","rc":[{"batb":[[2,1.79,56.31]],"ltp":1.8,"tv":464.92,"id":71847983},{"batb":[[0,2.12,12],[1,2.1,40.44],[2,1.8,82.99]],"ltp":2.16,"tv":296.18,"id":25173012}]}]}
{"op":"mcm","clk":"11764670818","pt":1722689655586,"mc":[{"id":"1.231282333","rc":[{"batb":[[0,2.12,10]],"ltp":2.16,"tv":296.18,"id":25173012}]}]}
{"op":"mcm","clk":"11764670977","pt":1722689656677,"mc":[{"id":"1.231282333","rc":[{"batb":[[0,2.1,40.44],[1,1.8,82.99],[2,1.74,17.32]],"ltp":2.16,"tv":296.18,"id":25173012}]}]}
{"op":"mcm","clk":"11764671535","pt":1722689660287,"mc":[{"id":"1.231282333","rc":[{"batb":[[0,2.12,12],[1,2.1,40.44],[2,1.8,82.99]],"ltp":2.16,"tv":296.18,"id":25173012}]}]}
{"op":"mcm","clk":"11764671951","pt":1722689662974,"mc":[{"id":"1.231282333","rc":[{"batb":[[2,1.75,88.52]],"ltp":1.8,"tv":464.92,"id":71847983},{"batb":[[0,2.12,10],[1,1.8,82.99],[2,1.74,17.32]],"ltp":2.16,"tv":296.18,"id":25173012}]}]}
{"op":"mcm","clk":"11764672051","pt":1722689663615,"mc":[{"id":"1.231282333","rc":[{"batb":[[0,1.8,82.99],[1,1.74,17.32],[2,1.5,232]],"ltp":2.16,"tv":296.18,"id":25173012}]}]}
{"op":"mcm","clk":"11764672485","pt":1722689666787,"mc":[{"id":"1.231282333","rc":[{"batb":[[0,1.81,12],[1,1.8,82.99],[2,1.74,17.32]],"ltp":2.16,"tv":296.18,"id":25173012}]}]}
{"op":"mcm","clk":"11764672658","pt":1722689667985,"mc":[{"id":"1.231282333","rc":[{"batb":[[2,1.79,56.31]],"ltp":1.8,"tv":464.92,"id":71847983},{"batb":[[0,2.1,40.44],[1,1.81,12],[2,1.8,82.99]],"ltp":2.16,"tv":296.18,"id":25173012}]}]}
{"op":"mcm","clk":"11764672798","pt":1722689669093,"mc":[{"id":"1.231282333","rc":[{"batb":[[1,1.81,10]],"ltp":2.16,"tv":296.18,"id":25173012}]}]}
{"op":"mcm","clk":"11764672941","pt":1722689670107,"mc":[{"id":"1.231282333","rc":[{"batb":[[1,1.8,82.99],[2,1.74,17.32]],"ltp":2.16,"tv":296.18,"id":25173012}]}]}
{"op":"mcm","clk":"11764673449","pt":1722689673606,"mc":[{"id":"1.231282333","rc":[{"batb":[[0,2.12,12],[1,2.1,40.44],[2,1.8,82.99]],"ltp":2.16,"tv":296.18,"id":25173012}]}]}
{"op":"mcm","clk":"11764673764","pt":1722689675795,"mc":[{"id":"1.231282333","rc":[{"batb":[[0,2.12,10]],"ltp":2.16,"tv":296.18,"id":25173012}]}]}
{"op":"mcm","clk":"11764673941","pt":1722689677001,"mc":[{"id":"1.231282333","rc":[{"batb":[[0,2.1,40.44],[1,1.8,82.99],[2,1.74,17.32]],"ltp":2.16,"tv":296.18,"id":25173012}]}]}
{"op":"mcm","clk":"11764674285","pt":1722689679426,"mc":[{"id":"1.231282333","rc":[{"batb":[[0,2.12,12],[1,2.1,40.44],[2,1.8,82.99]],"ltp":2.16,"tv":296.18,"id":25173012}]}]}
{"op":"mcm","clk":"11764674628","pt":1722689681825,"mc":[{"id":"1.231282333","rc":[{"batb":[[0,2.12,10]],"ltp":2.16,"tv":296.18,"id":25173012}]}]}
{"op":"mcm","clk":"11764674752","pt":1722689682727,"mc":[{"id":"1.231282333","rc":[{"batb":[[0,2.1,40.44],[1,1.8,82.99],[2,1.74,17.32]],"ltp":2.16,"tv":296.18,"id":25173012}]}]}
{"op":"mcm","clk":"11764675203","pt":1722689686220,"mc":[{"id":"1.231282333","rc":[{"batb":[[0,2.12,12],[1,2.1,40.44],[2,1.8,82.99]],"ltp":2.16,"tv":296.18,"id":25173012}]}]}
{"op":"mcm","clk":"11764675459","pt":1722689688014,"mc":[{"id":"1.231282333","rc":[{"batb":[[2,1.75,88.52]],"ltp":1.8,"tv":464.92,"id":71847983},{"batb":[[1,1.8,82.99],[2,1.74,17.32]],"ltp":2.16,"tv":296.18,"id":25173012}]}]}
{"op":"mcm","clk":"11764675526","pt":1722689688542,"mc":[{"id":"1.231282333","rc":[{"batb":[[0,2.12,10]],"ltp":2.16,"tv":296.18,"id":25173012}]}]}
{"op":"mcm","clk":"11764675689","pt":1722689689558,"mc":[{"id":"1.231282333","rc":[{"batb":[[0,1.8,82.99],[1,1.74,17.32],[2,1.5,232]],"ltp":2.16,"tv":296.18,"id":25173012}]}]}
{"op":"mcm","clk":"11764675907","pt":1722689690825,"mc":[{"id":"1.231282333","rc":[{"batb":[[0,1.81,2],[1,1.8,82.99],[2,1.74,17.32]],"ltp":2.16,"tv":296.18,"id":25173012}]}]}
{"op":"mcm","clk":"11764676244","pt":1722689693258,"mc":[{"id":"1.231282333","rc":[{"batb":[[2,1.79,56.31]],"ltp":1.8,"tv":464.92,"id":71847983},{"batb":[[0,2.12,10],[1,2.1,40.44],[2,1.8,82.99]],"ltp":2.16,"tv":296.18,"id":25173012}]}]}
{"op":"mcm","clk":"11764676739","pt":1722689696640,"mc":[{"id":"1.231282333","rc":[{"batb":[[0,2.12,2]],"ltp":2.16,"tv":296.18,"id":25173012}]}]}
{"op":"mcm","clk":"11764677107","pt":1722689699227,"mc":[{"id":"1.231282333","rc":[{"batb":[[0,2.1,40.44],[1,1.8,82.99],[2,1.74,17.32]],"ltp":2.16,"tv":296.18,"id":25173012}]}]}
{"op":"mcm","clk":"11764677133","pt":1722689699426,"mc":[{"id":"1.231282333","rc":[{"batb":[[0,2.12,10],[1,2.1,40.44],[2,1.8,82.99]],"ltp":2.16,"tv":296.18,"id":25173012}]}]}
{"op":"mcm","clk":"11764677483","pt":1722689701546,"mc":[{"id":"1.231282333","rc":[{"batb":[[0,2.14,2],[1,2.12,10],[2,2.1,40.44]],"ltp":2.16,"tv":296.18,"id":25173012}]}]}
{"op":"mcm","clk":"11764677662","pt":1722689702720,"mc":[{"id":"1.231282333","rc":[{"batb":[[1,2.1,40.44],[2,1.8,82.99]],"batl":[[0,2.86,4.34],[1,4,1.18],[2,5,1.05]],"ltp":2.16,"tv":296.18,"id":25173012}]}]}
{"op":"mcm","clk":"11764677854","pt":1722689703948,"mc":[{"id":"1.231282333","rc":[{"batb":[[0,2.1,40.44],[1,1.8,82.99],[2,1.74,17.32]],"ltp":2.16,"tv":296.18,"id":25173012}]}]}
{"op":"mcm","clk":"11764678055","pt":1722689705158,"mc":[{"id":"1.231282333","rc":[{"batb":[[0,2.12,10],[1,2.1,40.44],[2,1.8,82.99]],"ltp":2.16,"tv":296.18,"id":25173012}]}]}
{"op":"mcm","clk":"11764678579","pt":1722689708260,"mc":[{"id":"1.231282333","rc":[{"batb":[[2,1.75,88.52]],"ltp":1.8,"tv":464.92,"id":71847983},{"batb":[[0,2.14,2],[1,2.12,10]],"ltp":2.16,"tv":296.18,"id":25173012}]}]}
{"op":"mcm","clk":"11764678611","pt":1722689708443,"mc":[{"id":"1.231282333","rc":[{"batb":[[1,1.8,82.99],[2,1.74,17.32]],"ltp":2.16,"tv":296.18,"id":25173012}]}]}
{"op":"mcm","clk":"11764678855","pt":1722689710069,"mc":[{"id":"1.231282333","rc":[{"batb":[[1,1.8,89.6]],"ltp":2.16,"tv":296.18,"id":25173012}]}]}
{"op":"mcm","clk":"11764678931","pt":1722689710759,"mc":[{"id":"1.231282333","rc":[{"batb":[[0,1.81,10]],"ltp":2.16,"tv":296.18,"id":25173012}]}]}
{"op":"mcm","clk":"11764679285","pt":1722689713269,"mc":[{"id":"1.231282333","rc":[{"batb":[[2,1.79,56.31]],"ltp":1.8,"tv":464.92,"id":71847983},{"batb":[[0,2.12,2],[1,2.1,40.44],[2,1.81,10]],"ltp":2.16,"tv":296.18,"id":25173012}]}]}
{"op":"mcm","clk":"11764679438","pt":1722689714166,"mc":[{"id":"1.231282333","rc":[{"batb":[[2,1.8,89.6]],"ltp":2.16,"tv":296.18,"id":25173012}]}]}
{"op":"mcm","clk":"11764679647","pt":1722689715491,"mc":[{"id":"1.231282333","rc":[{"batb":[[0,2.1,40.44],[1,1.8,89.6],[2,1.74,17.32]],"ltp":2.16,"tv":296.18,"id":25173012}]}]}
{"op":"mcm","clk":"11764679822","pt":1722689716660,"mc":[{"id":"1.231282333","rc":[{"batb":[[0,2.12,10],[1,2.1,40.44],[2,1.8,89.6]],"ltp":2.16,"tv":296.18,"id":25173012}]}]}
{"op":"mcm","clk":"11764680053","pt":1722689718163,"mc":[{"id":"1.231282333","rc":[{"batb":[[2,1.75,88.52]],"ltp":1.8,"tv":464.92,"id":71847983},{"batb":[[0,2.14,2],[1,2.12,10]],"ltp":2.16,"tv":296.18,"id":25173012}]}]}
{"op":"mcm","clk":"11764680338","pt":1722689719955,"mc":[{"id":"1.231282333","rc":[{"batb":[[1,1.8,89.6],[2,1.74,17.32]],"ltp":2.16,"tv":296.18,"id":25173012}]}]}
{"op":"mcm","clk":"11764680465","pt":1722689720656,"mc":[{"id":"1.231282333","rc":[{"batb":[[0,1.8,89.6],[1,1.74,17.32],[2,1.5,232]],"ltp":2.16,"tv":296.18,"id":25173012}]}]}
{"op":"mcm","clk":"11764680888","pt":1722689723163,"mc":[{"id":"1.231282333","rc":[{"batb":[[2,1.79,56.31]],"ltp":1.8,"tv":464.92,"id":71847983},{"batb":[[0,2.1,40.44],[1,1.81,12],[2,1.8,89.6]],"ltp":2.16,"tv":296.18,"id":25173012}]}]}
{"op":"mcm","clk":"11764681220","pt":1722689725171,"mc":[{"id":"1.231282333","rc":[{"batb":[[1,1.81,10]],"ltp":2.16,"tv":296.18,"id":25173012}]}]}
{"op":"mcm","clk":"11764681409","pt":1722689726388,"mc":[{"id":"1.231282333","rc":[{"batb":[[1,1.8,89.6],[2,1.74,17.32]],"ltp":2.16,"tv":296.18,"id":25173012}]}]}
{"op":"mcm","clk":"11764682027","pt":1722689730490,"mc":[{"id":"1.231282333","rc":[{"batb":[[0,2.12,12],[1,2.1,40.44],[2,1.8,89.6]],"ltp":2.16,"tv":296.18,"id":25173012}]}]}
{"op":"mcm","clk":"11764682438","pt":1722689733291,"mc":[{"id":"1.231282333","rc":[{"batb":[[2,1.75,88.52]],"ltp":1.8,"tv":464.92,"id":71847983},{"batb":[[0,2.12,10],[1,1.8,89.6],[2,1.74,17.32]],"ltp":2.16,"tv":296.18,"id":25173012}]}]}
{"op":"mcm","clk":"11764682511","pt":1722689733875,"mc":[{"id":"1.231282333","rc":[{"batb":[[0,1.8,89.6],[1,1.74,17.32],[2,1.5,232]],"ltp":2.16,"tv":296.18,"id":25173012}]}]}
{"op":"mcm","clk":"11764682760","pt":1722689735587,"mc":[{"id":"1.231282333","rc":[{"batb":[[0,1.81,2],[1,1.8,89.6],[2,1.74,17.32]],"ltp":2.16,"tv":296.18,"id":25173012}]}]}
{"op":"mcm","clk":"11764683105","pt":1722689738203,"mc":[{"id":"1.231282333","rc":[{"batb":[[2,1.79,56.31]],"ltp":1.8,"tv":464.92,"id":71847983},{"batb":[[0,2.1,40.44],[1,1.81,10],[2,1.8,89.6]],"ltp":2.16,"tv":296.18,"id":25173012}]}]}
{"op":"mcm","clk":"11764683552","pt":1722689741284,"mc":[{"id":"1.231282333","rc":[{"batb":[[0,2.12,2],[1,2.1,40.44]],"ltp":2.16,"tv":296.18,"id":25173012}]}]}
{"op":"mcm","clk":"11764683932","pt":1722689743704,"mc":[{"id":"1.231282333","rc":[{"batb":[[0,2.12,10]],"ltp":2.16,"tv":296.18,"id":25173012}]}]}
{"op":"mcm","clk":"11764684485","pt":1722689747293,"mc":[{"id":"1.231282333","rc":[{"batb":[[0,2.12,2]],"ltp":2.16,"tv":296.18,"id":25173012}]}]}
{"op":"mcm","clk":"11764684814","pt":1722689749702,"mc":[{"id":"1.231282333","rc":[{"batb":[[0,2.12,10]],"ltp":2.16,"tv":296.18,"id":25173012}]}]}
{"op":"mcm","clk":"11764685128","pt":1722689752003,"mc":[{"id":"1.231282333","rc":[{"batb":[[0,2.14,2],[1,2.12,10],[2,2.1,40.44]],"ltp":2.16,"tv":296.18,"id":25173012}]}]}
{"op":"mcm","clk":"11764685245","pt":1722689752894,"mc":[{"id":"1.231282333","rc":[{"batb":[[1,2.1,40.44],[2,1.8,89.6]],"ltp":2.16,"tv":296.18,"id":25173012}]}]}
{"op":"mcm","clk":"11764685430","pt":1722689754320,"mc":[{"id":"1.231282333","rc":[{"batb":[[0,2.1,40.44],[1,1.8,89.6],[2,1.74,17.32]],"ltp":2.16,"tv":296.18,"id":25173012}]}]}
{"op":"mcm","clk":"11764685594","pt":1722689755479,"mc":[{"id":"1.231282333","rc":[{"batb":[[0,2.12,10],[1,2.1,40.44],[2,1.8,89.6]],"ltp":2.16,"tv":296.18,"id":25173012}]}]}
{"op":"mcm","clk":"11764685752","pt":1722689756690,"mc":[{"id":"1.231282333","rc":[{"batb":[[0,2.14,2],[1,2.12,10],[2,2.1,40.44]],"ltp":2.16,"tv":296.18,"id":25173012}]}]}
{"op":"mcm","clk":"11764686083","pt":1722689759004,"mc":[{"id":"1.231282333","rc":[{"batb":[[2,1.75,88.52]],"ltp":1.8,"tv":464.92,"id":71847983},{"batb":[[0,1.8,89.6],[1,1.74,17.32],[2,1.5,232]],"ltp":2.16,"tv":296.18,"id":25173012}]}]}
{"op":"mcm","clk":"11764686446","pt":1722689761298,"mc":[{"id":"1.231282333","rc":[{"batb":[[0,1.82,2],[1,1.81,10],[2,1.8,89.6]],"ltp":2.16,"tv":296.18,"id":25173012}]}]}
{"op":"mcm","clk":"11764686751","pt":1722689763339,"mc":[{"id":"1.231282333","rc":[{"batb":[[2,1.79,56.31]],"ltp":1.8,"tv":464.92,"id":71847983},{"batb":[[0,2.1,40.44],[1,1.82,2],[2,1.81,10]],"ltp":2.16,"tv":296.18,"id":25173012}]}]}
{"op":"mcm","clk":"11764686909","pt":1722689764399,"mc":[{"id":"1.231282333","rc":[{"batb":[[1,1.8,89.6],[2,1.74,17.32]],"ltp":2.16,"tv":296.18,"id":25173012}]}]}
{"op":"mcm","clk":"11764687268","pt":1722689766991,"mc":[{"id":"1.231282333","rc":[{"batb":[[0,2.12,12],[1,2.1,40.44],[2,1.8,89.6]],"ltp":2.16,"tv":296.18,"id":25173012}]}]}
{"op":"mcm","clk":"11764687585","pt":1722689768809,"mc":[{"id":"1.231282333","rc":[{"batb":[[2,1.75,88.52]],"ltp":1.8,"tv":464.92,"id":71847983},{"batb":[[0,2.12,10],[1,1.8,89.6],[2,1.74,17.32]],"ltp":2.16,"tv":296.18,"id":25173012}]}]}
{"op":"mcm","clk":"11764687769","pt":1722689770047,"mc":[{"id":"1.231282333","rc":[{"batb":[[0,1.8,89.6],[1,1.74,17.32],[2,1.5,232]],"ltp":2.16,"tv":296.18,"id":25173012}]}]}
{"op":"mcm","clk":"11764687956","pt":1722689771327,"mc":[{"id":"1.231282333","rc":[{"batb":[[0,1.81,2],[1,1.8,89.6],[2,1.74,17.32]],"ltp":2.16,"tv":296.18,"id":25173012}]}]}
{"op":"mcm","clk":"11764688337","pt":1722689773715,"mc":[{"id":"1.231282333","rc":[{"batb":[[2,1.79,56.31]],"ltp":1.8,"tv":464.92,"id":71847983},{"batb":[[0,2.12,10],[1,2.1,40.44],[2,1.8,89.6]],"ltp":2.16,"tv":296.18,"id":25173012}]}]}
{"op":"mcm","clk":"11764688788","pt":1722689777024,"mc":[{"id":"1.231282333","rc":[{"batb":[[0,2.12,2]],"ltp":2.16,"tv":296.18,"id":25173012}]}]}
{"op":"mcm","clk":"11764689144","pt":1722689779332,"mc":[{"id":"1.231282333","rc":[{"batb":[[0,2.1,40.44],[1,1.8,89.6],[2,1.74,17.32]],"ltp":2.16,"tv":296.18,"id":25173012}]}]}
{"op":"mcm","clk":"11764689260","pt":1722689780130,"mc":[{"id":"1.231282333","rc":[{"batl":[[2,1.9,22.68]],"ltp":1.8,"tv":464.92,"id":71847983},{"batb":[[0,2.12,10],[1,2.1,40.44],[2,1.8,89.6]],"ltp":2.16,"tv":296.18,"id":25173012}]}]}
{"op":"mcm","clk":"11764689636","pt":1722689783013,"mc":[{"id":"1.231282333","rc":[{"batb":[[0,2.12,2]],"ltp":2.16,"tv":296.18,"id":25173012}]}]}
{"op":"mcm","clk":"11764690041","pt":1722689785646,"mc":[{"id":"1.231282333","rc":[{"batb":[[0,2.12,10]],"ltp":2.16,"tv":296.18,"id":25173012}]}]}
{"op":"mcm","clk":"11764690509","pt":1722689788950,"mc":[{"id":"1.231282333","rc":[{"batb":[[2,1.75,88.52]],"ltp":1.8,"tv":464.92,"id":71847983},{"batb":[[0,2.14,2],[1,1.8,89.6],[2,1.74,17.32]],"ltp":2.16,"tv":296.18,"id":25173012}]}]}
{"op":"mcm","clk":"11764690826","pt":1722689791131,"mc":[{"id":"1.231282333","rc":[{"batb":[[0,1.81,10]],"ltp":2.16,"tv":296.18,"id":25173012}]}]}
{"op":"mcm","clk":"11764691177","pt":1722689793641,"mc":[{"id":"1.231282333","rc":[{"batb":[[2,1.79,56.31]],"ltp":1.8,"tv":464.92,"id":71847983},{"batb":[[0,2.1,40.44],[1,1.82,2],[2,1.81,10]],"ltp":2.16,"tv":296.18,"id":25173012}]}]}
{"op":"mcm","clk":"11764691294","pt":1722689794538,"mc":[{"id":"1.231282333","rc":[{"batb":[[2,1.8,89.6]],"ltp":2.16,"tv":296.18,"id":25173012}]}]}
{"op":"mcm","clk":"11764691472","pt":1722689795851,"mc":[{"id":"1.231282333","rc":[{"batb":[[1,1.8,89.6],[2,1.74,17.32]],"ltp":2.16,"tv":296.18,"id":25173012}]}]}
{"op":"mcm","clk":"11764691641","pt":1722689797233,"mc":[{"id":"1.231282333","rc":[{"batb":[[0,2.12,10],[1,2.1,40.44],[2,1.8,89.6]],"ltp":2.16,"tv":296.18,"id":25173012}]}]}
{"op":"mcm","clk":"11764691847","pt":1722689798636,"mc":[{"id":"1.231282333","rc":[{"batb":[[2,1.75,88.52]],"ltp":1.8,"tv":464.92,"id":71847983},{"batb":[[0,2.14,2],[1,2.12,10]],"ltp":2.16,"tv":296.18,"id":25173012}]}]}
{"op":"mcm","clk":"11764692110","pt":1722689800664,"mc":[{"id":"1.231282333","rc":[{"batb":[[0,1.8,89.6],[1,1.74,17.32],[2,1.5,232]],"ltp":2.16,"tv":296.18,"id":25173012}]}]}
{"op":"mcm","clk":"11764692579","pt":1722689803841,"mc":[{"id":"1.231282333","rc":[{"batb":[[2,1.79,56.31]],"ltp":1.8,"tv":464.92,"id":71847983},{"batb":[[0,2.12,12],[1,2.1,40.44],[2,1.8,89.6]],"ltp":2.16,"tv":296.18,"id":25173012}]}]}
{"op":"mcm","clk":"11764692864","pt":1722689806168,"mc":[{"id":"1.231282333","rc":[{"batb":[[0,2.12,10]],"ltp":2.16,"tv":296.18,"id":25173012}]}]}
{"op":"mcm","clk":"11764692993","pt":1722689807066,"mc":[{"id":"1.231282333","rc":[{"batb":[[0,2.1,40.44],[1,1.8,89.6],[2,1.74,17.32]],"ltp":2.16,"tv":296.18,"id":25173012}]}]}
{"op":"mcm","clk":"11764693333","pt":1722689809455,"mc":[{"id":"1.231282333","rc":[{"batb":[[0,2.12,12],[1,2.1,40.44],[2,1.8,89.6]],"ltp":2.16,"tv":296.18,"id":25173012}]}]}
{"op":"mcm","clk":"11764693672","pt":1722689811749,"mc":[{"id":"1.231282333","rc":[{"batb":[[0,2.12,10]],"ltp":2.16,"tv":296.18,"id":25173012}]}]}
{"op":"mcm","clk":"11764693804","pt":1722689812801,"mc":[{"id":"1.231282333","rc":[{"batb":[[0,2.1,40.44],[1,1.8,89.6],[2,1.74,17.32]],"ltp":2.16,"tv":296.18,"id":25173012}]}]}
{"op":"mcm","clk":"11764694308","pt":1722689816682,"mc":[{"id":"1.231282333","rc":[{"batb":[[0,2.12,12],[1,2.1,40.44],[2,1.8,89.6]],"ltp":2.16,"tv":296.18,"id":25173012}]}]}
{"op":"mcm","clk":"11764694605","pt":1722689819116,"mc":[{"id":"1.231282333","rc":[{"batb":[[2,1.75,88.52]],"ltp":1.8,"tv":464.92,"id":71847983},{"batb":[[0,2.12,10],[1,1.8,89.6],[2,1.74,17.32]],"ltp":2.16,"tv":296.18,"id":25173012}]}]}
{"op":"mcm","clk":"11764694762","pt":1722689819988,"mc":[{"id":"1.231282333","rc":[{"batb":[[0,1.8,89.6],[1,1.74,17.32],[2,1.5,232]],"ltp":2.16,"tv":296.18,"id":25173012}]}]}
{"op":"mcm","clk":"11764695288","pt":1722689823763,"mc":[{"id":"1.231282333","rc":[{"batb":[[2,1.79,56.31]],"ltp":1.8,"tv":464.92,"id":71847983},{"batb":[[0,2.12,12],[1,2.1,40.44],[2,1.8,89.6]],"ltp":2.16,"tv":296.18,"id":25173012}]}]}
{"op":"mcm","clk":"11764695636","pt":1722689826087,"mc":[{"id":"1.231282333","rc":[{"batb":[[0,2.12,10]],"ltp":2.16,"tv":296.18,"id":25173012}]}]}
{"op":"mcm","clk":"11764695778","pt":1722689827090,"mc":[{"id":"1.231282333","rc":[{"batb":[[0,2.1,40.44],[1,1.8,89.6],[2,1.74,17.32]],"ltp":2.16,"tv":296.18,"id":25173012}]}]}
{"op":"mcm","clk":"11764696205","pt":1722689829987,"mc":[{"id":"1.231282333","rc":[{"batb":[[0,2.12,12],[1,2.1,40.44],[2,1.8,89.6]],"ltp":2.16,"tv":296.18,"id":25173012}]}]}
{"op":"mcm","clk":"11764696514","pt":1722689832204,"mc":[{"id":"1.231282333","rc":[{"batb":[[0,2.12,10]],"ltp":2.16,"tv":296.18,"id":25173012}]}]}
{"op":"mcm","clk":"11764696647","pt":1722689833201,"mc":[{"id":"1.231282333","rc":[{"batb":[[0,2.1,40.44],[1,1.8,89.6],[2,1.74,17.32]],"ltp":2.16,"tv":296.18,"id":25173012}]}]}
{"op":"mcm","clk":"11764696844","pt":1722689834621,"mc":[{"id":"1.231282333","rc":[{"batb":[[0,2.12,2],[1,2.1,40.44],[2,1.8,89.6]],"ltp":2.16,"tv":296.18,"id":25173012}]}]}
{"op":"mcm","clk":"11764697215","pt":1722689837099,"mc":[{"id":"1.231282333","rc":[{"batb":[[0,2.12,10]],"ltp":2.16,"tv":296.18,"id":25173012}]}]}
{"op":"mcm","clk":"11764697464","pt":1722689838791,"mc":[{"id":"1.231282333","rc":[{"batb":[[2,1.75,88.52]],"ltp":1.8,"tv":464.92,"id":71847983},{"batb":[[1,1.8,89.6],[2,1.74,17.32]],"ltp":2.16,"tv":296.18,"id":25173012}]}]}
{"op":"mcm","clk":"11764697713","pt":1722689840388,"mc":[{"id":"1.231282333","rc":[{"batb":[[0,1.8,89.6],[1,1.74,17.32],[2,1.5,232]],"ltp":2.16,"tv":296.18,"id":25173012}]}]}
{"op":"mcm","clk":"11764697733","pt":1722689840501,"mc":[{"id":"1.231282333","rc":[{"batb":[[0,1.81,2],[1,1.8,89.6],[2,1.74,17.32]],"ltp":2.16,"tv":296.18,"id":25173012}]}]}
{"op":"mcm","clk":"11764698024","pt":1722689842838,"mc":[{"id":"1.231282333","rc":[{"batb":[[0,1.81,10]],"ltp":2.16,"tv":296.18,"id":25173012}]}]}
{"op":"mcm","clk":"11764698194","pt":1722689843799,"mc":[{"id":"1.231282333","rc":[{"batb":[[2,1.79,56.31]],"ltp":1.8,"tv":464.92,"id":71847983},{"batb":[[0,2.1,40.44],[1,1.81,10],[2,1.8,89.6]],"ltp":2.16,"tv":296.18,"id":25173012}]}]}
{"op":"mcm","clk":"11764698498","pt":1722689845995,"mc":[{"id":"1.231282333","rc":[{"batb":[[0,2.12,2],[1,2.1,40.44]],"ltp":2.16,"tv":296.18,"id":25173012}]}]}
{"op":"mcm","clk":"11764698920","pt":1722689848948,"mc":[{"id":"1.231282333","rc":[{"batb":[[2,1.75,88.52]],"ltp":1.8,"tv":464.92,"id":71847983},{"batb":[[0,2.12,10],[1,1.8,89.6],[2,1.74,17.32]],"ltp":2.16,"tv":296.18,"id":25173012}]}]}
{"op":"mcm","clk":"11764699416","pt":1722689852002,"mc":[{"id":"1.231282333","rc":[{"batb":[[0,1.81,2]],"ltp":2.16,"tv":296.18,"id":25173012}]}]}
{"op":"mcm","clk":"11764699795","pt":1722689854324,"mc":[{"id":"1.231282333","rc":[{"batb":[[2,1.79,56.31]],"ltp":1.8,"tv":464.92,"id":71847983},{"batb":[[0,2.12,10],[1,2.1,40.44],[2,1.8,89.6]],"ltp":2.16,"tv":296.18,"id":25173012}]}]}
{"op":"mcm","clk":"11764700328","pt":1722689857698,"mc":[{"id":"1.231282333","rc":[{"batb":[[0,2.12,2]],"ltp":2.16,"tv":296.18,"id":25173012}]}]}
{"op":"mcm","clk":"11764700623","pt":1722689860259,"mc":[{"id":"1.231282333","rc":[{"batb":[[0,2.12,10]],"ltp":2.16,"tv":296.18,"id":25173012}]}]}
{"op":"mcm","clk":"11764701041","pt":1722689863446,"mc":[{"id":"1.231282333","rc":[{"batb":[[0,2.14,2]],"ltp":2.16,"tv":296.18,"id":25173012}]}]}
{"op":"mcm","clk":"11764701376","pt":1722689865928,"mc":[{"id":"1.231282333","rc":[{"batb":[[0,2.12,10]],"ltp":2.16,"tv":296.18,"id":25173012}]}]}
{"op":"mcm","clk":"11764701874","pt":1722689869343,"mc":[{"id":"1.231282333","rc":[{"batb":[[2,1.75,88.52]],"ltp":1.8,"tv":464.92,"id":71847983},{"trd":[[2.14,4]],"batb":[[0,1.8,89.6],[1,1.74,17.32],[2,1.5,232]],"ltp":2.14,"tv":300.18,"id":25173012}],"tv":765.1}]}
{"op":"mcm","clk":"11764702544","pt":1722689874234,"mc":[{"id":"1.231282333","rc":[{"batb":[[2,1.79,56.31]],"ltp":1.8,"tv":464.92,"id":71847983},{"batb":[[0,2.12,12],[1,2.1,40.44],[2,1.8,89.6]],"ltp":2.14,"tv":300.18,"id":25173012}]}]}
{"op":"mcm","clk":"11764702792","pt":1722689876447,"mc":[{"id":"1.231282333","rc":[{"batb":[[0,2.12,10]],"ltp":2.14,"tv":300.18,"id":25173012}]}]}
{"op":"mcm","clk":"11764702965","pt":1722689877659,"mc":[{"id":"1.231282333","rc":[{"batb":[[0,2.1,40.44],[1,1.8,89.6],[2,1.74,17.32]],"ltp":2.14,"tv":300.18,"id":25173012}]}]}
{"op":"mcm","clk":"11764703218","pt":1722689879561,"mc":[{"id":"1.231282333","rc":[{"batb":[[0,2.12,2],[1,2.1,40.44],[2,1.8,89.6]],"ltp":2.14,"tv":300.18,"id":25173012}]}]}
{"op":"mcm","clk":"11764703603","pt":1722689882036,"mc":[{"id":"1.231282333","rc":[{"batb":[[0,2.12,10]],"ltp":2.14,"tv":300.18,"id":25173012}]}]}
{"op":"mcm","clk":"11764703972","pt":1722689884146,"mc":[{"id":"1.231282333","rc":[{"batb":[[2,1.75,88.52]],"ltp":1.8,"tv":464.92,"id":71847983},{"batb":[[0,2.14,2],[1,2.12,10]],"ltp":2.14,"tv":300.18,"id":25173012}]}]}
{"op":"mcm","clk":"11764704165","pt":1722689885365,"mc":[{"id":"1.231282333","rc":[{"batb":[[1,1.8,89.6],[2,1.74,17.32]],"ltp":2.14,"tv":300.18,"id":25173012}]}]}
{"op":"mcm","clk":"11764704339","pt":1722689886578,"mc":[{"id":"1.231282333","rc":[{"batb":[[0,1.8,89.6],[1,1.74,17.32],[2,1.5,232]],"ltp":2.14,"tv":300.18,"id":25173012}]}]}
{"op":"mcm","clk":"11764704770","pt":1722689889277,"mc":[{"id":"1.231282333","rc":[{"batb":[[2,1.79,56.31]],"ltp":1.8,"tv":464.92,"id":71847983},{"batb":[[0,2.12,12],[1,2.1,40.44],[2,1.8,89.6]],"ltp":2.14,"tv":300.18,"id":25173012}]}]}
{"op":"mcm","clk":"11764705105","pt":1722689891544,"mc":[{"id":"1.231282333","rc":[{"batb":[[0,2.12,10]],"ltp":2.14,"tv":300.18,"id":25173012}]}]}
{"op":"mcm","clk":"11764705283","pt":1722689892760,"mc":[{"id":"1.231282333","rc":[{"batb":[[0,2.1,40.44],[1,1.8,89.6],[2,1.74,17.32]],"ltp":2.14,"tv":300.18,"id":25173012}]}]}
{"op":"mcm","clk":"11764705654","pt":1722689895160,"mc":[{"id":"1.231282333","rc":[{"batb":[[0,2.12,12],[1,2.1,40.44],[2,1.8,89.6]],"ltp":2.14,"tv":300.18,"id":25173012}]}]}
{"op":"mcm","clk":"11764705977","pt":1722689897367,"mc":[{"id":"1.231282333","rc":[{"batb":[[0,2.12,10]],"ltp":2.14,"tv":300.18,"id":25173012}]}]}
{"op":"mcm","clk":"11764706149","pt":1722689898468,"mc":[{"id":"1.231282333","rc":[{"batb":[[0,2.1,40.44],[1,1.8,89.6],[2,1.74,17.32]],"ltp":2.14,"tv":300.18,"id":25173012}]}]}
{"op":"mcm","clk":"11764706773","pt":1722689902562,"mc":[{"id":"1.231282333","rc":[{"batb":[[0,2.12,12],[1,2.1,40.44],[2,1.8,89.6]],"ltp":2.14,"tv":300.18,"id":25173012}]}]}
{"op":"mcm","clk":"11764707010","pt":1722689904197,"mc":[{"id":"1.231282333","rc":[{"batb":[[2,1.75,88.52]],"ltp":1.8,"tv":464.92,"id":71847983},{"batb":[[1,1.8,89.6],[2,1.74,17.32]],"ltp":2.14,"tv":300.18,"id":25173012}]}]}
{"op":"mcm","clk":"11764707112","pt":1722689904887,"mc":[{"id":"1.231282333","rc":[{"batb":[[0,2.12,10]],"ltp":2.14,"tv":300.18,"id":25173012}]}]}
{"op":"mcm","clk":"11764707232","pt":1722689905900,"mc":[{"id":"1.231282333","rc":[{"batb":[[0,1.8,89.6],[1,1.74,17.32],[2,1.5,232]],"ltp":2.14,"tv":300.18,"id":25173012}]}]}
{"op":"mcm","clk":"11764707700","pt":1722689909161,"mc":[{"id":"1.231282333","rc":[{"batb":[[2,1.79,56.31]],"ltp":1.8,"tv":464.92,"id":71847983},{"batb":[[0,2.1,40.44],[1,1.81,12],[2,1.8,89.6]],"ltp":2.14,"tv":300.18,"id":25173012}]}]}
{"op":"mcm","clk":"11764707979","pt":1722689911091,"mc":[{"id":"1.231282333","rc":[{"batb":[[1,1.81,10]],"ltp":2.14,"tv":300.18,"id":25173012}]}]}
{"op":"mcm","clk":"11764708112","pt":1722689911974,"mc":[{"id":"1.231282333","rc":[{"batb":[[1,1.8,89.6],[2,1.74,17.32]],"ltp":2.14,"tv":300.18,"id":25173012}]}]}
{"op":"mcm","clk":"11764708382","pt":1722689913865,"mc":[{"id":"1.231282333","rc":[{"batb":[[0,2.12,2],[1,2.1,40.44],[2,1.8,89.6]],"ltp":2.14,"tv":300.18,"id":25173012}]}]}
{"op":"mcm","clk":"11764708770","pt":1722689916295,"mc":[{"id":"1.231282333","rc":[{"batb":[[0,2.12,10]],"ltp":2.14,"tv":300.18,"id":25173012}]}]}
{"op":"mcm","clk":"11764709174","pt":1722689919194,"mc":[{"id":"1.231282333","rc":[{"batb":[[2,1.75,88.52]],"ltp":1.8,"tv":464.92,"id":71847983},{"batb":[[0,2.14,2],[1,2.12,10]],"ltp":2.14,"tv":300.18,"id":25173012}]}]}
{"op":"mcm","clk":"11764709282","pt":1722689919913,"mc":[{"id":"1.231282333","rc":[{"batb":[[1,1.8,89.6],[2,1.74,17.32]],"ltp":2.14,"tv":300.18,"id":25173012}]}]}
{"op":"mcm","clk":"11764709463","pt":1722689921303,"mc":[{"id":"1.231282333","rc":[{"batb":[[0,1.8,89.6],[1,1.74,17.32],[2,1.5,232]],"ltp":2.14,"tv":300.18,"id":25173012}]}]}
{"op":"mcm","clk":"11764709946","pt":1722689924632,"mc":[{"id":"1.231282333","rc":[{"batb":[[2,1.79,56.31]],"ltp":1.8,"tv":464.92,"id":71847983},{"batb":[[0,2.12,12],[1,2.1,40.44],[2,1.8,89.6]],"ltp":2.14,"tv":300.18,"id":25173012}]}]}
{"op":"mcm","clk":"11764710276","pt":1722689926799,"mc":[{"id":"1.231282333","rc":[{"batb":[[0,2.12,10]],"ltp":2.14,"tv":300.18,"id":25173012}]}]}
{"op":"mcm","clk":"11764710405","pt":1722689927801,"mc":[{"id":"1.231282333","rc":[{"batb":[[0,2.1,40.44],[1,1.8,89.6],[2,1.74,17.32]],"ltp":2.14,"tv":300.18,"id":25173012}]}]}
{"op":"mcm","clk":"11764710859","pt":1722689930891,"mc":[{"id":"1.231282333","rc":[{"batb":[[0,2.12,12],[1,2.1,40.44],[2,1.8,89.6]],"ltp":2.14,"tv":300.18,"id":25173012}]}]}
{"op":"mcm","clk":"11764711140","pt":1722689933086,"mc":[{"id":"1.231282333","rc":[{"batb":[[0,2.12,10]],"ltp":2.14,"tv":300.18,"id":25173012}]}]}
{"op":"mcm","clk":"11764711300","pt":1722689934294,"mc":[{"id":"1.231282333","rc":[{"batb":[[2,1.75,88.52]],"ltp":1.8,"tv":464.92,"id":71847983},{"batb":[[0,1.8,89.6],[1,1.74,17.32],[2,1.5,232]],"ltp":2.14,"tv":300.18,"id":25173012}]}]}
{"op":"mcm","clk":"11764711954","pt":1722689939321,"mc":[{"id":"1.231282333","rc":[{"batb":[[2,1.79,56.31]],"ltp":1.8,"tv":464.92,"id":71847983},{"batb":[[0,2.1,40.44],[1,1.8,89.6],[2,1.74,17.32]],"ltp":2.14,"tv":300.18,"id":25173012}]}]}
{"op":"mcm","clk":"11764711970","pt":1722689939426,"mc":[{"id":"1.231282333","rc":[{"batb":[[0,2.12,12],[1,2.1,40.44],[2,1.8,89.6]],"ltp":2.14,"tv":300.18,"id":25173012}]}]}
{"op":"mcm","clk":"11764712309","pt":1722689941802,"mc":[{"id":"1.231282333","rc":[{"batb":[[0,2.12,10]],"ltp":2.14,"tv":300.18,"id":25173012}]}]}
{"op":"mcm","clk":"11764712451","pt":1722689942704,"mc":[{"id":"1.231282333","rc":[{"batb":[[0,2.1,40.44],[1,1.8,89.6],[2,1.74,17.32]],"ltp":2.14,"tv":300.18,"id":25173012}]}]}
{"op":"mcm","clk":"11764712830","pt":1722689945622,"mc":[{"id":"1.231282333","rc":[{"batb":[[0,2.12,12],[1,2.1,40.44],[2,1.8,89.6]],"ltp":2.14,"tv":300.18,"id":25173012}]}]}
{"op":"mcm","clk":"11764713136","pt":1722689948012,"mc":[{"id":"1.231282333","rc":[{"batb":[[0,2.12,10]],"ltp":2.14,"tv":300.18,"id":25173012}]}]}
{"op":"mcm","clk":"11764713285","pt":1722689949115,"mc":[{"id":"1.231282333","rc":[{"batb":[[0,2.1,40.44],[1,1.8,89.6],[2,1.74,17.32]],"ltp":2.14,"tv":300.18,"id":25173012}]}]}
{"op":"mcm","clk":"11764713523","pt":1722689950913,"mc":[{"id":"1.231282333","rc":[{"batb":[[0,2.12,2],[1,2.1,40.44],[2,1.8,89.6]],"ltp":2.14,"tv":300.18,"id":25173012}]}]}
{"op":"mcm","clk":"11764713887","pt":1722689953508,"mc":[{"id":"1.231282333","rc":[{"batb":[[0,2.12,10]],"ltp":2.14,"tv":300.18,"id":25173012}]}]}
{"op":"mcm","clk":"11764713997","pt":1722689954440,"mc":[{"id":"1.231282333","rc":[{"batb":[[2,1.75,88.52]],"ltp":1.8,"tv":464.92,"id":71847983},{"batb":[[1,1.8,89.6],[2,1.74,17.32]],"ltp":2.14,"tv":300.18,"id":25173012}]}]}
{"op":"mcm","clk":"11764714159","pt":1722689955619,"mc":[{"id":"1.231282333","rc":[{"batb":[[0,2.14,2],[1,2.12,10],[2,1.8,89.6]],"ltp":2.14,"tv":300.18,"id":25173012}]}]}
{"op":"mcm","clk":"11764714335","pt":1722689956921,"mc":[{"id":"1.231282333","rc":[{"batb":[[1,1.8,89.6],[2,1.74,17.32]],"ltp":2.14,"tv":300.18,"id":25173012}]}]}
{"op":"mcm","clk":"11764714458","pt":1722689958016,"mc":[{"id":"1.231282333","rc":[{"batb":[[0,1.8,89.6],[1,1.74,17.32],[2,1.5,232]],"ltp":2.14,"tv":300.18,"id":25173012}]}]}
{"op":"mcm","clk":"11764714650","pt":1722689959545,"mc":[{"id":"1.231282333","rc":[{"batb":[[2,1.79,56.31]],"ltp":1.8,"tv":464.92,"id":71847983},{"batb":[[0,2.12,10],[1,2.1,40.44],[2,1.8,89.6]],"ltp":2.14,"tv":300.18,"id":25173012}]}]}
{"op":"mcm","clk":"11764714823","pt":1722689960747,"mc":[{"id":"1.231282333","rc":[{"batb":[[0,2.14,2],[1,2.12,10],[2,2.1,40.44]],"ltp":2.14,"tv":300.18,"id":25173012}]}]}
{"op":"mcm","clk":"11764715103","pt":1722689962946,"mc":[{"id":"1.231282333","rc":[{"batb":[[0,2.1,40.44],[1,1.8,89.6],[2,1.74,17.32]],"ltp":2.14,"tv":300.18,"id":25173012}]}]}
{"op":"mcm","clk":"11764715564","pt":1722689966065,"mc":[{"id":"1.231282333","rc":[{"batb":[[0,2.12,12],[1,2.1,40.44],[2,1.8,89.6]],"ltp":2.14,"tv":300.18,"id":25173012}]}]}
{"op":"mcm","clk":"11764716042","pt":1722689969244,"mc":[{"id":"1.231282333","rc":[{"batb":[[0,2.1,40.44],[1,1.8,89.6],[2,1.74,17.32]],"ltp":2.14,"tv":300.18,"id":25173012}]}]}
{"op":"mcm","clk":"11764716402","pt":1722689971723,"mc":[{"id":"1.231282333","rc":[{"batb":[[0,2.12,12],[1,2.1,40.44],[2,1.8,89.6]],"ltp":2.14,"tv":300.18,"id":25173012}]}]}
{"op":"mcm","clk":"11764716704","pt":1722689974064,"mc":[{"id":"1.231282333","rc":[{"batb":[[0,2.12,10]],"ltp":2.14,"tv":300.18,"id":25173012}]}]}
{"op":"mcm","clk":"11764716837","pt":1722689975059,"mc":[{"id":"1.231282333","rc":[{"batb":[[2,1.75,88.52]],"ltp":1.8,"tv":464.92,"id":71847983},{"batb":[[0,1.8,89.6],[1,1.74,17.32],[2,1.5,232]],"ltp":2.14,"tv":300.18,"id":25173012}]}]}
{"op":"mcm","clk":"11764717090","pt":1722689977046,"mc":[{"id":"1.231282333","rc":[{"batb":[[0,1.81,2],[1,1.8,89.6],[2,1.74,17.32]],"ltp":2.14,"tv":300.18,"id":25173012}]}]}
{"op":"mcm","clk":"11764717415","pt":1722689979667,"mc":[{"id":"1.231282333","rc":[{"batb":[[2,1.79,56.31]],"ltp":1.8,"tv":464.92,"id":71847983},{"batb":[[0,2.1,40.44],[1,1.81,10],[2,1.8,89.6]],"ltp":2.14,"tv":300.18,"id":25173012}]}]}
{"op":"mcm","clk":"11764717750","pt":1722689982235,"mc":[{"id":"1.231282333","rc":[{"batb":[[0,2.12,2],[1,2.1,40.44],[2,1.81,10]],"ltp":2.14,"tv":300.18,"id":25173012}]}]}
{"op":"mcm","clk":"11764717863","pt":1722689983171,"mc":[{"id":"1.231282333","rc":[{"batb":[[2,1.8,89.6]],"ltp":2.14,"tv":300.18,"id":25173012}]}]}
{"op":"mcm","clk":"11764718062","pt":1722689984658,"mc":[{"id":"1.231282333","rc":[{"batb":[[0,2.1,40.44],[1,1.8,89.6],[2,1.74,17.32]],"ltp":2.14,"tv":300.18,"id":25173012}]}]}
{"op":"mcm","clk":"11764718465","pt":1722689987497,"mc":[{"id":"1.231282333","rc":[{"batb":[[0,2.12,12],[1,2.1,40.44],[2,1.8,89.6]],"ltp":2.14,"tv":300.18,"id":25173012}]}]}
{"op":"mcm","clk":"11764718794","pt":1722689989853,"mc":[{"id":"1.231282333","rc":[{"batb":[[2,1.75,88.52]],"ltp":1.8,"tv":464.92,"id":71847983},{"batb":[[0,2.12,10],[1,1.8,89.6],[2,1.74,17.32]],"ltp":2.14,"tv":300.18,"id":25173012}]}]}
{"op":"mcm","clk":"11764718904","pt":1722689990670,"mc":[{"id":"1.231282333","rc":[{"batb":[[0,1.8,89.6],[1,1.74,17.32],[2,1.5,232]],"ltp":2.14,"tv":300.18,"id":25173012}]}]}
{"op":"mcm","clk":"11764719273","pt":1722689993302,"mc":[{"id":"1.231282333","rc":[{"batb":[[0,1.81,12],[1,1.8,89.6],[2,1.74,17.32]],"ltp":2.14,"tv":300.18,"id":25173012}]}]}
{"op":"mcm","clk":"11764719446","pt":1722689994605,"mc":[{"id":"1.231282333","rc":[{"batb":[[2,1.79,56.31]],"ltp":1.8,"tv":464.92,"id":71847983},{"batb":[[0,2.1,40.44],[1,1.81,12],[2,1.8,89.6]],"ltp":2.14,"tv":300.18,"id":25173012}]}]}
{"op":"mcm","clk":"11764719544","pt":1722689995551,"mc":[{"id":"1.231282333","rc":[{"batb":[[1,1.81,10]],"ltp":2.14,"tv":300.18,"id":25173012}]}]}
{"op":"mcm","clk":"11764719678","pt":1722689996511,"mc":[{"id":"1.231282333","rc":[{"batb":[[1,1.8,89.6],[2,1.74,17.32]],"ltp":2.14,"tv":300.18,"id":25173012}]}]}
{"op":"mcm","clk":"11764719845","pt":1722689997733,"mc":[{"id":"1.231282333","rc":[{"batb":[[0,2.12,2],[1,2.1,40.44],[2,1.8,89.6]],"ltp":2.14,"tv":300.18,"id":25173012}]}]}
{"op":"mcm","clk":"11764720174","pt":1722690000265,"mc":[{"id":"1.231282333","rc":[{"batb":[[0,2.1,40.44],[1,1.8,89.6],[2,1.74,17.32]],"ltp":2.14,"tv":300.18,"id":25173012}]}]}
{"op":"mcm","clk":"11764720230","pt":1722690000479,"mc":[{"id":"1.231282333","rc":[{"batb":[[0,2.12,10],[1,2.1,40.44],[2,1.8,89.6]],"ltp":2.14,"tv":300.18,"id":25173012}]}]}
{"op":"mcm","clk":"11764720707","pt":1722690002539,"mc":[{"id":"1.231282333","rc":[{"batb":[[0,2.14,2],[1,2.12,10],[2,2.1,40.44]],"ltp":2.14,"tv":300.18,"id":25173012}]}]}
{"op":"mcm","clk":"11764720942","pt":1722690003964,"mc":[{"id":"1.231282333","rc":[{"batb":[[1,2.1,40.44],[2,1.8,89.6]],"ltp":2.14,"tv":300.18,"id":25173012}]}]}
{"op":"mcm","clk":"11764721132","pt":1722690004826,"mc":[{"id":"1.231282333","rc":[{"batb":[[0,2.1,40.44],[1,1.8,89.6],[2,1.74,17.32]],"ltp":2.14,"tv":300.18,"id":25173012}]}]}
{"op":"mcm","clk":"11764721278","pt":1722690005543,"mc":[{"id":"1.231282333","rc":[{"batb":[[1,1.8,57.75]],"ltp":1.8,"tv":464.92,"id":71847983},{"batb":[[0,2.1,56.72]],"ltp":2.14,"tv":300.18,"id":25173012}]}]}
{"op":"mcm","clk":"11764721529","pt":1722690007064,"mc":[{"id":"1.231282333","rc":[{"batb":[[0,2.14,2],[1,2.12,10],[2,2.1,56.72]],"ltp":2.14,"tv":300.18,"id":25173012}]}]}
{"op":"mcm","clk":"11764721614","pt":1722690007544,"mc":[{"id":"1.231282333","rc":[{"batb":[[1,2.12,25.99]],"ltp":2.14,"tv":300.18,"id":25173012}]}]}
{"op":"mcm","clk":"11764721900","pt":1722690009366,"mc":[{"id":"1.231282333","rc":[{"batb":[[0,2.12,25.99],[1,2.1,56.72],[2,1.8,89.6]],"ltp":2.14,"tv":300.18,"id":25173012}]}]}
{"op":"mcm","clk":"11764722044","pt":1722690010154,"mc":[{"id":"1.231282333","rc":[{"batb":[[2,1.75,88.52]],"ltp":1.8,"tv":464.92,"id":71847983},{"batb":[[0,2.12,15.99],[1,2.1,16.28]],"ltp":2.14,"tv":300.18,"id":25173012}]}]}
{"op":"mcm","clk":"11764722375","pt":1722690012231,"mc":[{"id":"1.231282333","rc":[{"batb":[[0,2.14,2],[1,2.12,15.99],[2,2.1,16.28]],"ltp":2.14,"tv":300.18,"id":25173012}]}]}
{"op":"mcm","clk":"11764722821","pt":1722690015289,"mc":[{"id":"1.231282333","rc":[{"batb":[[0,2.14,10]],"ltp":2.14,"tv":300.18,"id":25173012}]}]}
{"op":"mcm","clk":"11764723232","pt":1722690018245,"mc":[{"id":"1.231282333","rc":[{"batb":[[0,2.16,2],[1,2.14,10],[2,2.12,15.99]],"ltp":2.14,"tv":300.18,"id":25173012}]}]}
{"op":"mcm","clk":"11764723289","pt":1722690018593,"mc":[{"id":"1.231282333","rc":[{"batb":[[1,2.12,15.99],[2,2.1,16.28]],"ltp":2.14,"tv":300.18,"id":25173012}]}]}
{"op":"mcm","clk":"11764723598","pt":1722690020450,"mc":[{"id":"1.231282333","rc":[{"batb":[[0,2.12,15.99],[1,2.1,16.28],[2,1.8,89.6]],"ltp":2.14,"tv":300.18,"id":25173012}]}]}
{"op":"mcm","clk":"11764724023","pt":1722690023564,"mc":[{"id":"1.231282333","rc":[{"batb":[[0,2.14,12],[1,2.12,15.99],[2,2.1,16.28]],"ltp":2.14,"tv":300.18,"id":25173012}]}]}
{"op":"mcm","clk":"11764724375","pt":1722690026159,"mc":[{"id":"1.231282333","rc":[{"batb":[[0,2.14,10]],"ltp":2.14,"tv":300.18,"id":25173012}]}]}
{"op":"mcm","clk":"11764724503","pt":1722690027065,"mc":[{"id":"1.231282333","rc":[{"batb":[[0,2.12,15.99],[1,2.1,16.28],[2,1.8,89.6]],"ltp":2.14,"tv":300.18,"id":25173012}]}]}
{"op":"mcm","clk":"11764724800","pt":1722690029158,"mc":[{"id":"1.231282333","rc":[{"batb":[[0,2.14,12],[1,2.12,15.99],[2,2.1,16.28]],"ltp":2.14,"tv":300.18,"id":25173012}]}]}
{"op":"mcm","clk":"11764725156","pt":1722690031503,"mc":[{"id":"1.231282333","rc":[{"batb":[[0,2.14,10]],"ltp":2.14,"tv":300.18,"id":25173012}]}]}
{"op":"mcm","clk":"11764725307","pt":1722690032584,"mc":[{"id":"1.231282333","rc":[{"batb":[[0,2.12,15.99],[1,2.1,16.28],[2,1.8,89.6]],"ltp":2.14,"tv":300.18,"id":25173012}]}]}
{"op":"mcm","clk":"11764725479","pt":1722690033772,"mc":[{"id":"1.231282333","rc":[{"batb":[[0,2.14,2],[1,2.12,15.99],[2,2.1,16.28]],"ltp":2.14,"tv":300.18,"id":25173012}]}]}
{"op":"mcm","clk":"11764725832","pt":1722690036267,"mc":[{"id":"1.231282333","rc":[{"batb":[[0,2.12,15.99],[1,2.1,16.28],[2,1.8,89.6]],"ltp":2.14,"tv":300.18,"id":25173012}]}]}
{"op":"mcm","clk":"11764725866","pt":1722690036576,"mc":[{"id":"1.231282333","rc":[{"batb":[[0,2.14,10],[1,2.12,15.99],[2,2.1,16.28]],"ltp":2.14,"tv":300.18,"id":25173012}]}]}
{"op":"mcm","clk":"11764726300","pt":1722690039795,"mc":[{"id":"1.231282333","rc":[{"batb":[[0,2.16,2]],"ltp":2.14,"tv":300.18,"id":25173012}]}]}
{"op":"mcm","clk":"11764726628","pt":1722690042068,"mc":[{"id":"1.231282333","rc":[{"batb":[[0,2.14,10]],"ltp":2.14,"tv":300.18,"id":25173012}]}]}
{"op":"mcm","clk":"11764727114","pt":1722690045402,"mc":[{"id":"1.231282333","rc":[{"batb":[[0,2.16,2]],"ltp":2.14,"tv":300.18,"id":25173012}]}]}
{"op":"mcm","clk":"11764727542","pt":1722690048212,"mc":[{"id":"1.231282333","rc":[{"batb":[[0,2.14,10]],"ltp":2.14,"tv":300.18,"id":25173012}]}]}
{"op":"mcm","clk":"11764727831","pt":1722690050292,"mc":[{"id":"1.231282333","rc":[{"batb":[[0,2.16,2],[1,2.14,10],[2,2.12,15.99]],"ltp":2.14,"tv":300.18,"id":25173012}]}]}
{"op":"mcm","clk":"11764728024","pt":1722690051500,"mc":[{"id":"1.231282333","rc":[{"batb":[[1,2.12,15.99],[2,2.1,16.28]],"ltp":2.14,"tv":300.18,"id":25173012}]}]}
{"op":"mcm","clk":"11764728201","pt":1722690052675,"mc":[{"id":"1.231282333","rc":[{"batb":[[0,2.12,15.99],[1,2.1,16.28],[2,1.8,89.6]],"ltp":2.14,"tv":300.18,"id":25173012}]}]}
{"op":"mcm","clk":"11764728499","pt":1722690054802,"mc":[{"id":"1.231282333","rc":[{"batb":[[0,2.16,2],[1,2.14,10],[2,2.12,15.99]],"ltp":2.14,"tv":300.18,"id":25173012}]}]}
{"op":"mcm","clk":"11764728859","pt":1722690057108,"mc":[{"id":"1.231282333","rc":[{"batb":[[0,2.14,10],[1,2.12,15.99],[2,2.1,16.28]],"ltp":2.14,"tv":300.18,"id":25173012}]}]}
{"op":"mcm","clk":"11764728982","pt":1722690058004,"mc":[{"id":"1.231282333","rc":[{"batb":[[0,2.12,15.99],[1,2.1,16.28],[2,1.8,89.6]],"ltp":2.14,"tv":300.18,"id":25173012}]}]}
{"op":"mcm","clk":"11764729327","pt":1722690060330,"mc":[{"id":"1.231282333","rc":[{"batb":[[0,2.14,12],[1,2.12,15.99],[2,2.1,16.28]],"ltp":2.14,"tv":300.18,"id":25173012}]}]}
{"op":"mcm","clk":"11764729683","pt":1722690062599,"mc":[{"id":"1.231282333","rc":[{"batb":[[0,2.14,10]],"ltp":2.14,"tv":300.18,"id":25173012}]}]}
{"op":"mcm","clk":"11764729841","pt":1722690063613,"mc":[{"id":"1.231282333","rc":[{"batb":[[0,2.12,15.99],[1,2.1,16.28],[2,1.8,89.6]],"ltp":2.14,"tv":300.18,"id":25173012}]}]}
{"op":"mcm","clk":"11764730147","pt":1722690065513,"mc":[{"id":"1.231282333","rc":[{"batb":[[0,2.14,2],[1,2.12,15.99],[2,2.1,16.28]],"ltp":2.14,"tv":300.18,"id":25173012}]}]}
{"op":"mcm","clk":"11764730543","pt":1722690068149,"mc":[{"id":"1.231282333","rc":[{"batb":[[0,2.14,10]],"ltp":2.14,"tv":300.18,"id":25173012}]}]}
{"op":"mcm","clk":"11764731085","pt":1722690071354,"mc":[{"id":"1.231282333","rc":[{"batb":[[0,2.12,15.99],[1,2.1,16.28],[2,1.8,89.6]],"ltp":2.14,"tv":300.18,"id":25173012}]}]}
{"op":"mcm","clk":"11764731102","pt":1722690071424,"mc":[{"id":"1.231282333","rc":[{"batb":[[0,2.16,2],[1,2.12,15.99],[2,2.1,16.28]],"ltp":2.14,"tv":300.18,"id":25173012}]}]}
{"op":"mcm","clk":"11764731562","pt":1722690074118,"mc":[{"id":"1.231282333","rc":[{"batb":[[0,2.14,10]],"ltp":2.14,"tv":300.18,"id":25173012}]}]}
{"op":"mcm","clk":"11764732004","pt":1722690076231,"mc":[{"id":"1.231282333","rc":[{"batb":[[0,2.16,2],[1,2.14,10],[2,2.12,15.99]],"ltp":2.14,"tv":300.18,"id":25173012}]}]}
{"op":"mcm","clk":"11764732204","pt":1722690077553,"mc":[{"id":"1.231282333","rc":[{"batb":[[1,2.12,15.99],[2,2.1,16.28]],"ltp":2.14,"tv":300.18,"id":25173012}]}]}
{"op":"mcm","clk":"11764732355","pt":1722690078519,"mc":[{"id":"1.231282333","rc":[{"batb":[[0,2.12,15.99],[1,2.1,16.28],[2,1.8,89.6]],"ltp":2.14,"tv":300.18,"id":25173012}]}]}
{"op":"mcm","clk":"11764732572","pt":1722690080139,"mc":[{"id":"1.231282333","rc":[{"batb":[[0,2.14,10],[1,2.12,15.99],[2,2.1,16.28]],"ltp":2.14,"tv":300.18,"id":25173012}]}]}
{"op":"mcm","clk":"11764732826","pt":1722690081836,"mc":[{"id":"1.231282333","rc":[{"batb":[[0,2.16,2],[1,2.14,10],[2,2.12,15.99]],"ltp":2.14,"tv":300.18,"id":25173012}]}]}
{"op":"mcm","clk":"11764733192","pt":1722690084233,"mc":[{"id":"1.231282333","rc":[{"batb":[[0,2.12,15.99],[1,2.1,16.28],[2,1.8,89.6]],"ltp":2.14,"tv":300.18,"id":25173012}]}]}
{"op":"mcm","clk":"11764733508","pt":1722690086334,"mc":[{"id":"1.231282333","rc":[{"batb":[[0,2.14,10],[1,2.12,15.99],[2,2.1,16.28]],"ltp":2.14,"tv":300.18,"id":25173012}]}]}
{"op":"mcm","clk":"11764733533","pt":1722690086540,"mc":[{"id":"1.231282333","rc":[{"batb":[[0,2.16,2],[1,2.14,10],[2,2.12,15.99]],"ltp":2.14,"tv":300.18,"id":25173012}]}]}
{"op":"mcm","clk":"11764733857","pt":1722690088726,"mc":[{"id":"1.231282333","rc":[{"batb":[[0,2.14,10],[1,2.12,15.99],[2,2.1,16.28]],"ltp":2.14,"tv":300.18,"id":25173012}]}]}
{"op":"mcm","clk":"11764733997","pt":1722690089666,"mc":[{"id":"1.231282333","rc":[{"batb":[[0,2.12,15.99],[1,2.1,16.28],[2,1.8,89.6]],"ltp":2.14,"tv":300.18,"id":25173012}]}]}
{"op":"mcm","clk":"11764734638","pt":1722690093581,"mc":[{"id":"1.231282333","rc":[{"batb":[[0,2.14,12],[1,2.12,15.99],[2,2.1,16.28]],"ltp":2.14,"tv":300.18,"id":25173012}]}]}
{"op":"mcm","clk":"11764735024","pt":1722690095951,"mc":[{"id":"1.231282333","rc":[{"batb":[[0,2.14,10]],"ltp":2.14,"tv":300.18,"id":25173012}]}]}
{"op":"mcm","clk":"11764735189","pt":1722690096958,"mc":[{"id":"1.231282333","rc":[{"batb":[[0,2.12,15.99],[1,2.1,16.28],[2,1.8,89.6]],"ltp":2.14,"tv":300.18,"id":25173012}]}]}
{"op":"mcm","clk":"11764735377","pt":1722690098166,"mc":[{"id":"1.231282333","rc":[{"batb":[[0,2.14,2],[1,2.12,15.99],[2,2.1,16.28]],"ltp":2.14,"tv":300.18,"id":25173012}]}]}
{"op":"mcm","clk":"11764735701","pt":1722690100386,"mc":[{"id":"1.231282333","rc":[{"batb":[[0,2.12,15.99],[1,2.1,16.28],[2,1.8,89.6]],"ltp":2.14,"tv":300.18,"id":25173012}]}]}
{"op":"mcm","clk":"11764735796","pt":1722690100871,"mc":[{"id":"1.231282333","rc":[{"batb":[[0,2.14,10],[1,2.12,15.99],[2,2.1,16.28]],"ltp":2.14,"tv":300.18,"id":25173012}]}]}
{"op":"mcm","clk":"11764736318","pt":1722690104254,"mc":[{"id":"1.231282333","rc":[{"batb":[[0,2.16,2]],"ltp":2.14,"tv":300.18,"id":25173012}]}]}
{"op":"mcm","clk":"11764736706","pt":1722690106580,"mc":[{"id":"1.231282333","rc":[{"batb":[[0,2.14,10]],"ltp":2.14,"tv":300.18,"id":25173012}]}]}
{"op":"mcm","clk":"11764737218","pt":1722690109893,"mc":[{"id":"1.231282333","rc":[{"batb":[[0,2.16,2]],"ltp":2.14,"tv":300.18,"id":25173012}]}]}
{"op":"mcm","clk":"11764737602","pt":1722690112372,"mc":[{"id":"1.231282333","rc":[{"batb":[[0,2.14,10]],"ltp":2.14,"tv":300.18,"id":25173012}]}]}
{"op":"mcm","clk":"11764738128","pt":1722690115792,"mc":[{"id":"1.231282333","rc":[{"batb":[[0,2.16,2]],"ltp":2.14,"tv":300.18,"id":25173012}]}]}
{"op":"mcm","clk":"11764738523","pt":1722690118175,"mc":[{"id":"1.231282333","rc":[{"batb":[[0,2.14,10]],"ltp":2.14,"tv":300.18,"id":25173012}]}]}
{"op":"mcm","clk":"11764738856","pt":1722690120283,"mc":[{"id":"1.231282333","rc":[{"batb":[[0,2.16,2],[1,2.14,10],[2,2.12,15.99]],"ltp":2.14,"tv":300.18,"id":25173012}]}]}
{"op":"mcm","clk":"11764739054","pt":1722690121474,"mc":[{"id":"1.231282333","rc":[{"batb":[[1,2.12,15.99],[2,2.1,16.28]],"ltp":2.14,"tv":300.18,"id":25173012}]}]}
{"op":"mcm","clk":"11764739242","pt":1722690122582,"mc":[{"id":"1.231282333","rc":[{"batb":[[0,2.12,15.99],[1,2.1,16.28],[2,1.8,89.6]],"ltp":2.14,"tv":300.18,"id":25173012}]}]}
{"op":"mcm","clk":"11764739434","pt":1722690123782,"mc":[{"id":"1.231282333","rc":[{"batb":[[0,2.14,10],[1,2.12,15.99],[2,2.1,16.28]],"ltp":2.14,"tv":300.18,"id":25173012}]}]}
{"op":"mcm","clk":"11764739656","pt":1722690125084,"mc":[{"id":"1.231282333","rc":[{"batb":[[0,2.16,2],[1,2.14,10],[2,2.12,15.99]],"ltp":2.14,"tv":300.18,"id":25173012}]}]}
{"op":"mcm","clk":"11764740027","pt":1722690127296,"mc":[{"id":"1.231282333","rc":[{"batb":[[0,2.12,15.99],[1,2.1,16.28],[2,1.8,89.6]],"ltp":2.14,"tv":300.18,"id":25173012}]}]}
{"op":"mcm","clk":"11764740923","pt":1722690133009,"mc":[{"id":"1.231282333","rc":[{"batb":[[0,2.14,12],[1,2.12,15.99],[2,2.1,16.28]],"ltp":2.14,"tv":300.18,"id":25173012}]}]}
{"op":"mcm","clk":"11764741335","pt":1722690135300,"mc":[{"id":"1.231282333","rc":[{"batb":[[0,2.14,10]],"ltp":2.14,"tv":300.18,"id":25173012}]}]}
{"op":"mcm","clk":"11764741521","pt":1722690136308,"mc":[{"id":"1.231282333","rc":[{"batb":[[0,2.12,15.99],[1,2.1,16.28],[2,1.8,89.6]],"ltp":2.14,"tv":300.18,"id":25173012}]}]}
{"op":"mcm","clk":"11764741890","pt":1722690138398,"mc":[{"id":"1.231282333","rc":[{"batb":[[0,2.14,2],[1,2.12,15.99],[2,2.1,16.28]],"ltp":2.14,"tv":300.18,"id":25173012}]}]}
{"op":"mcm","clk":"11764742332","pt":1722690140933,"mc":[{"id":"1.231282333","rc":[{"batb":[[0,2.14,10]],"ltp":2.14,"tv":300.18,"id":25173012}]}]}
{"op":"mcm","clk":"11764742850","pt":1722690144137,"mc":[{"id":"1.231282333","rc":[{"batb":[[0,2.16,2]],"ltp":2.14,"tv":300.18,"id":25173012}]}]}
{"op":"mcm","clk":"11764743240","pt":1722690146620,"mc":[{"id":"1.231282333","rc":[{"batb":[[0,2.14,10]],"ltp":2.14,"tv":300.18,"id":25173012}]}]}
{"op":"mcm","clk":"11764743807","pt":1722690150006,"mc":[{"id":"1.231282333","rc":[{"batb":[[0,2.14,2]],"ltp":2.14,"tv":300.18,"id":25173012}]}]}
{"op":"mcm","clk":"11764744139","pt":1722690152326,"mc":[{"id":"1.231282333","rc":[{"batb":[[0,2.12,15.99],[1,2.1,16.28],[2,1.8,89.6]],"ltp":2.14,"tv":300.18,"id":25173012}]}]}
{"op":"mcm","clk":"11764744154","pt":1722690152417,"mc":[{"id":"1.231282333","rc":[{"batb":[[0,2.14,10],[1,2.12,15.99],[2,2.1,16.28]],"ltp":2.14,"tv":300.18,"id":25173012}]}]}
{"op":"mcm","clk":"11764744551","pt":1722690154921,"mc":[{"id":"1.231282333","rc":[{"batb":[[0,2.16,2],[1,2.14,10],[2,2.12,15.99]],"ltp":2.14,"tv":300.18,"id":25173012}]}]}
{"op":"mcm","clk":"11764744687","pt":1722690155814,"mc":[{"id":"1.231282333","rc":[{"batb":[[1,2.12,15.99],[2,2.1,16.28]],"ltp":2.14,"tv":300.18,"id":25173012}]}]}
{"op":"mcm","clk":"11764744920","pt":1722690157321,"mc":[{"id":"1.231282333","rc":[{"batb":[[0,2.12,15.99],[1,2.1,16.28],[2,1.8,89.6]],"ltp":2.14,"tv":300.18,"id":25173012}]}]}
{"op":"mcm","clk":"11764745251","pt":1722690159526,"mc":[{"id":"1.231282333","rc":[{"batb":[[0,2.14,12],[1,2.12,15.99],[2,2.1,16.28]],"ltp":2.14,"tv":300.18,"id":25173012}]}]}
{"op":"mcm","clk":"11764745700","pt":1722690161924,"mc":[{"id":"1.231282333","rc":[{"batb":[[0,2.14,10]],"ltp":2.14,"tv":300.18,"id":25173012}]}]}
{"op":"mcm","clk":"11764745838","pt":1722690162816,"mc":[{"id":"1.231282333","rc":[{"batb":[[0,2.12,15.99],[1,2.1,16.28],[2,1.8,89.6]],"ltp":2.14,"tv":300.18,"id":25173012}]}]}
{"op":"mcm","clk":"11764746812","pt":1722690169068,"mc":[{"id":"1.231282333","rc":[{"batb":[[0,2.14,12],[1,2.12,15.99],[2,2.1,16.28]],"ltp":2.14,"tv":300.18,"id":25173012}]}]}
{"op":"mcm","clk":"11764747205","pt":1722690171350,"mc":[{"id":"1.231282333","rc":[{"batb":[[0,2.14,10]],"ltp":2.14,"tv":300.18,"id":25173012}]}]}
{"op":"mcm","clk":"11764747362","pt":1722690172462,"mc":[{"id":"1.231282333","rc":[{"batb":[[0,2.12,15.99],[1,2.1,16.28],[2,1.8,89.6]],"ltp":2.14,"tv":300.18,"id":25173012}]}]}
{"op":"mcm","clk":"11764747817","pt":1722690175162,"mc":[{"id":"1.231282333","rc":[{"batb":[[0,2.14,12],[1,2.12,15.99],[2,2.1,16.28]],"ltp":2.14,"tv":300.18,"id":25173012}]}]}
{"op":"mcm","clk":"11764748209","pt":1722690177557,"mc":[{"id":"1.231282333","rc":[{"batb":[[0,2.14,10]],"ltp":2.14,"tv":300.18,"id":25173012}]}]}
{"op":"mcm","clk":"11764748376","pt":1722690178565,"mc":[{"id":"1.231282333","rc":[{"batb":[[0,2.12,15.99],[1,2.1,16.28],[2,1.8,89.6]],"ltp":2.14,"tv":300.18,"id":25173012}]}]}
{"op":"mcm","clk":"11764749348","pt":1722690184349,"mc":[{"id":"1.231282333","rc":[{"batb":[[0,2.14,12],[1,2.12,15.99],[2,2.1,16.28]],"ltp":2.14,"tv":300.18,"id":25173012}]}]}
{"op":"mcm","clk":"11764749751","pt":1722690186772,"mc":[{"id":"1.231282333","rc":[{"batb":[[0,2.14,10]],"ltp":2.14,"tv":300.18,"id":25173012}]}]}
{"op":"mcm","clk":"11764749910","pt":1722690187785,"mc":[{"id":"1.231282333","rc":[{"batb":[[0,2.12,15.99],[1,2.1,16.28],[2,1.8,89.6]],"ltp":2.14,"tv":300.18,"id":25173012}]}]}
{"op":"mcm","clk":"11764750540","pt":1722690191666,"mc":[{"id":"1.231282333","rc":[{"batb":[[0,2.14,12],[1,2.12,15.99],[2,2.1,16.28]],"ltp":2.14,"tv":300.18,"id":25173012}]}]}
{"op":"mcm","clk":"11764750937","pt":1722690193959,"mc":[{"id":"1.231282333","rc":[{"batb":[[0,2.14,10]],"ltp":2.14,"tv":300.18,"id":25173012}]}]}
{"op":"mcm","clk":"11764751098","pt":1722690194969,"mc":[{"id":"1.231282333","rc":[{"batb":[[0,2.12,15.99],[1,2.1,16.28],[2,1.8,89.6]],"ltp":2.14,"tv":300.18,"id":25173012}]}]}
{"op":"mcm","clk":"11764751357","pt":1722690196359,"mc":[{"id":"1.231282333","rc":[{"batb":[[0,2.14,2],[1,2.12,15.99],[2,2.1,16.28]],"ltp":2.14,"tv":300.18,"id":25173012}]}]}
{"op":"mcm","clk":"11764751839","pt":1722690198961,"mc":[{"id":"1.231282333","rc":[{"batb":[[0,2.14,10]],"ltp":2.14,"tv":300.18,"id":25173012}]}]}
{"op":"mcm","clk":"11764752423","pt":1722690202278,"mc":[{"id":"1.231282333","rc":[{"batb":[[0,2.16,2]],"ltp":2.14,"tv":300.18,"id":25173012}]}]}
{"op":"mcm","clk":"11764752785","pt":1722690204349,"mc":[{"id":"1.231282333","rc":[{"batb":[[0,2.12,15.99],[1,2.1,16.28],[2,1.8,89.6]],"ltp":2.14,"tv":300.18,"id":25173012}]}]}
{"op":"mcm","clk":"11764752813","pt":1722690204456,"mc":[{"id":"1.231282333","rc":[{"batb":[[0,2.14,10],[1,2.12,15.99],[2,2.1,16.28]],"ltp":2.14,"tv":300.18,"id":25173012}]}]}
{"op":"mcm","clk":"11764754174","pt":1722690212090,"mc":[{"id":"1.231282333","rc":[{"batb":[[0,2.12,15.99],[1,2.1,16.28],[2,1.8,89.6]],"ltp":2.14,"tv":300.18,"id":25173012}]}]}
{"op":"mcm","clk":"11764754832","pt":1722690216082,"mc":[{"id":"1.231282333","rc":[{"batb":[[0,2.16,12],[1,2.12,15.99],[2,2.1,16.28]],"ltp":2.14,"tv":300.18,"id":25173012}]}]}
{"op":"mcm","clk":"11764755767","pt":1722690221773,"mc":[{"id":"1.231282333","rc":[{"batb":[[0,2.16,10]],"ltp":2.14,"tv":300.18,"id":25173012}]}]}
{"op":"mcm","clk":"11764755931","pt":1722690222728,"mc":[{"id":"1.231282333","rc":[{"batb":[[0,2.12,15.99],[1,2.1,16.28],[2,1.8,89.6]],"ltp":2.14,"tv":300.18,"id":25173012}]}]}
{"op":"mcm","clk":"11764757891","pt":1722690233894,"mc":[{"id":"1.231282333","rc":[{"batb":[[0,2.14,12],[1,2.12,15.99],[2,2.1,16.28]],"ltp":2.14,"tv":300.18,"id":25173012}]}]}
{"op":"mcm","clk":"11764758303","pt":1722690236210,"mc":[{"id":"1.231282333","rc":[{"batb":[[0,2.14,10]],"ltp":2.14,"tv":300.18,"id":25173012}]}]}
{"op":"mcm","clk":"11764758446","pt":1722690237113,"mc":[{"id":"1.231282333","rc":[{"batb":[[0,2.12,15.99],[1,2.1,16.28],[2,1.8,89.6]],"ltp":2.14,"tv":300.18,"id":25173012}]}]}
{"op":"mcm","clk":"11764761574","pt":1722690255028,"mc":[{"id":"1.231282333","rc":[{"batb":[[0,2.14,12],[1,2.12,15.99],[2,2.1,16.28]],"ltp":2.14,"tv":300.18,"id":25173012}]}]}
{"op":"mcm","clk":"11764761999","pt":1722690257419,"mc":[{"id":"1.231282333","rc":[{"batb":[[0,2.14,10]],"ltp":2.14,"tv":300.18,"id":25173012}]}]}
{"op":"mcm","clk":"11764762175","pt":1722690258434,"mc":[{"id":"1.231282333","rc":[{"batb":[[0,2.12,15.99],[1,2.1,16.28],[2,1.8,89.6]],"ltp":2.14,"tv":300.18,"id":25173012}]}]}
{"op":"mcm","clk":"11764762622","pt":1722690260926,"mc":[{"id":"1.231282333","rc":[{"batb":[[0,2.14,12],[1,2.12,15.99],[2,2.1,16.28]],"ltp":2.14,"tv":300.18,"id":25173012}]}]}
{"op":"mcm","clk":"11764763014","pt":1722690263313,"mc":[{"id":"1.231282333","rc":[{"batb":[[0,2.14,10]],"ltp":2.14,"tv":300.18,"id":25173012}]}]}
{"op":"mcm","clk":"11764763207","pt":1722690264366,"mc":[{"id":"1.231282333","rc":[{"batb":[[0,2.12,15.99],[1,2.1,16.28],[2,1.8,89.6]],"ltp":2.14,"tv":300.18,"id":25173012}]}]}
{"op":"mcm","clk":"11764765250","pt":1722690275967,"mc":[{"id":"1.231282333","rc":[{"batb":[[0,2.14,12],[1,2.12,15.99],[2,2.1,16.28]],"ltp":2.14,"tv":300.18,"id":25173012}]}]}
{"op":"mcm","clk":"11764765864","pt":1722690279236,"mc":[{"id":"1.231282333","rc":[{"batb":[[0,2.12,15.99],[1,2.1,16.28],[2,1.8,89.6]],"ltp":2.14,"tv":300.18,"id":25173012}]}]}
{"op":"mcm","clk":"11764766634","pt":1722690283385,"mc":[{"id":"1.231282333","rc":[{"batb":[[0,2.14,10],[1,2.12,15.99],[2,2.1,16.28]],"ltp":2.14,"tv":300.18,"id":25173012}]}]}
{"op":"mcm","clk":"11764766659","pt":1722690283469,"mc":[{"id":"1.231282333","rc":[{"batb":[[0,2.14,12]],"ltp":2.14,"tv":300.18,"id":25173012}]}]}
{"op":"mcm","clk":"11764767076","pt":1722690285764,"mc":[{"id":"1.231282333","rc":[{"batb":[[0,2.14,10]],"ltp":2.14,"tv":300.18,"id":25173012}]}]}
{"op":"mcm","clk":"11764767278","pt":1722690286806,"mc":[{"id":"1.231282333","rc":[{"batb":[[0,2.12,15.99],[1,2.1,16.28],[2,1.8,89.6]],"ltp":2.14,"tv":300.18,"id":25173012}]}]}
{"op":"mcm","clk":"11764767572","pt":1722690287952,"mc":[{"id":"1.231282333","rc":[{"batb":[[0,2.14,2],[1,2.12,15.99],[2,2.1,16.28]],"ltp":2.14,"tv":300.18,"id":25173012}]}]}
{"op":"mcm","clk":"11764767988","pt":1722690290348,"mc":[{"id":"1.231282333","rc":[{"batb":[[0,2.12,15.99],[1,2.1,16.28],[2,1.8,89.6]],"ltp":2.14,"tv":300.18,"id":25173012}]}]}
{"op":"mcm","clk":"11764768025","pt":1722690290574,"mc":[{"id":"1.231282333","rc":[{"batb":[[0,2.14,10],[1,2.12,15.99],[2,2.1,16.28]],"ltp":2.14,"tv":300.18,"id":25173012}]}]}
{"op":"mcm","clk":"11764768622","pt":1722690293955,"mc":[{"id":"1.231282333","rc":[{"batb":[[0,2.14,2]],"ltp":2.14,"tv":300.18,"id":25173012}]}]}
{"op":"mcm","clk":"11764769019","pt":1722690296312,"mc":[{"id":"1.231282333","rc":[{"batb":[[0,2.14,10]],"ltp":2.14,"tv":300.18,"id":25173012}]}]}
{"op":"mcm","clk":"11764769614","pt":1722690299812,"mc":[{"id":"1.231282333","rc":[{"batb":[[0,2.14,2]],"ltp":2.14,"tv":300.18,"id":25173012}]}]}
{"op":"mcm","clk":"11764770053","pt":1722690302279,"mc":[{"id":"1.231282333","rc":[{"batb":[[0,2.14,10]],"ltp":2.14,"tv":300.18,"id":25173012}]}]}
{"op":"mcm","clk":"11764770645","pt":1722690305780,"mc":[{"id":"1.231282333","rc":[{"batb":[[0,2.14,2]],"ltp":2.14,"tv":300.18,"id":25173012}]}]}
{"op":"mcm","clk":"11764771034","pt":1722690308178,"mc":[{"id":"1.231282333","rc":[{"batb":[[0,2.14,10]],"ltp":2.14,"tv":300.18,"id":25173012}]}]}
{"op":"mcm","clk":"11764771606","pt":1722690311558,"mc":[{"id":"1.231282333","rc":[{"batb":[[0,2.14,2]],"ltp":2.14,"tv":300.18,"id":25173012}]}]}
{"op":"mcm","clk":"11764772071","pt":1722690314096,"mc":[{"id":"1.231282333","rc":[{"trd":[[1.86,10]],"batb":[[0,1.8,57.75],[1,1.75,88.52],[2,1.74,17.32]],"batl":[[0,1.86,130],[1,1.88,1.8],[2,1.89,25.42]],"ltp":1.86,"tv":474.92,"id":71847983},{"batb":[[0,2.14,10]],"ltp":2.14,"tv":300.18,"id":25173012}],"tv":775.1}]}
{"op":"mcm","clk":"11764772545","pt":1722690316394,"mc":[{"id":"1.231282333","rc":[{"batb":[[1,1.79,56.31],[2,1.75,88.52]],"ltp":1.86,"tv":474.92,"id":71847983},{"batb":[[0,2.16,2],[1,2.14,25.71],[2,2.12,15.99]],"ltp":2.14,"tv":300.18,"id":25173012}]}]}
{"op":"mcm","clk":"11764772712","pt":1722690317297,"mc":[{"id":"1.231282333","rc":[{"batb":[[1,2.14,15.71]],"ltp":2.14,"tv":300.18,"id":25173012}]}]}
{"op":"mcm","clk":"11764772961","pt":1722690318703,"mc":[{"id":"1.231282333","rc":[{"batb":[[0,2.14,15.71],[1,2.12,15.99],[2,2.1,56.72]],"ltp":2.14,"tv":300.18,"id":25173012}]}]}
{"op":"mcm","clk":"11764776142","pt":1722690335346,"mc":[{"id":"1.231282333","rc":[{"batb":[[0,1.8,35.36],[1,1.79,78.98]],"batl":[[0,1.82,45],[1,1.86,130],[2,1.88,1.8]],"ltp":1.86,"tv":474.92,"id":71847983},{"batb":[[0,2.16,27.44],[1,2.14,15.71],[2,2.12,15.99]],"ltp":2.14,"tv":300.18,"id":25173012}]}]}
{"op":"mcm","clk":"11764776491","pt":1722690337259,"mc":[{"id":"1.231282333","rc":[{"batb":[[0,2.18,15.18],[1,2.16,27.44],[2,2.14,15.71]],"ltp":2.14,"tv":300.18,"id":25173012}]}]}
{"op":"mcm","clk":"11764776513","pt":1722690337469,"mc":[{"id":"1.231282333","rc":[{"batb":[[1,2.16,25.44]],"ltp":2.14,"tv":300.18,"id":25173012}]}]}
{"op":"mcm","clk":"11764776728","pt":1722690338555,"mc":[{"id":"1.231282333","rc":[{"batb":[[1,2.16,15.44]],"ltp":2.14,"tv":300.18,"id":25173012}]}]}
{"op":"mcm","clk":"11764777331","pt":1722690341881,"mc":[{"id":"1.231282333","rc":[{"batb":[[0,2.2,12],[1,2.18,15.18],[2,2.16,15.44]],"ltp":2.14,"tv":300.18,"id":25173012}]}]}
{"op":"mcm","clk":"11764777767","pt":1722690344284,"mc":[{"id":"1.231282333","rc":[{"batb":[[0,2.2,10]],"ltp":2.14,"tv":300.18,"id":25173012}]}]}
{"op":"mcm","clk":"11764777914","pt":1722690345147,"mc":[{"id":"1.231282333","rc":[{"batb":[[0,2.18,15.18],[1,2.16,15.44],[2,2.14,15.71]],"ltp":2.14,"tv":300.18,"id":25173012}]}]}
{"op":"mcm","clk":"11764778317","pt":1722690347381,"mc":[{"id":"1.231282333","rc":[{"batb":[[0,2.2,12],[1,2.18,15.18],[2,2.16,15.44]],"ltp":2.14,"tv":300.18,"id":25173012}]}]}
{"op":"mcm","clk":"11764778712","pt":1722690349676,"mc":[{"id":"1.231282333","rc":[{"batb":[[0,2.2,10]],"ltp":2.14,"tv":300.18,"id":25173012}]}]}
{"op":"mcm","clk":"11764778900","pt":1722690350660,"mc":[{"id":"1.231282333","rc":[{"batb":[[0,2.18,15.18],[1,2.16,15.44],[2,2.14,15.71]],"ltp":2.14,"tv":300.18,"id":25173012}]}]}
{"op":"mcm","clk":"11764780634","pt":1722690359900,"mc":[{"id":"1.231282333","rc":[{"batb":[[0,2.2,12],[1,2.18,15.18],[2,2.16,15.44]],"ltp":2.14,"tv":300.18,"id":25173012}]}]}
{"op":"mcm","clk":"11764781079","pt":1722690362071,"mc":[{"id":"1.231282333","rc":[{"batb":[[0,2.2,10]],"ltp":2.14,"tv":300.18,"id":25173012}]}]}
{"op":"mcm","clk":"11764781289","pt":1722690363176,"mc":[{"id":"1.231282333","rc":[{"batb":[[0,2.18,15.18],[1,2.16,15.44],[2,2.14,15.71]],"ltp":2.14,"tv":300.18,"id":25173012}]}]}
{"op":"mcm","clk":"11764783683","pt":1722690375524,"mc":[{"id":"1.231282333","rc":[{"batb":[[0,2.2,12],[1,2.18,15.18],[2,2.16,15.44]],"ltp":2.14,"tv":300.18,"id":25173012}]}]}
{"op":"mcm","clk":"11764784148","pt":1722690377847,"mc":[{"id":"1.231282333","rc":[{"batb":[[0,2.2,10]],"ltp":2.14,"tv":300.18,"id":25173012}]}]}
{"op":"mcm","clk":"11764784340","pt":1722690378924,"mc":[{"id":"1.231282333","rc":[{"batb":[[0,2.18,15.18],[1,2.16,15.44],[2,2.14,15.71]],"ltp":2.14,"tv":300.18,"id":25173012}]}]}
{"op":"mcm","clk":"11764785036","pt":1722690382721,"mc":[{"id":"1.231282333","rc":[{"batb":[[0,2.2,12],[1,2.18,15.18],[2,2.16,15.44]],"ltp":2.14,"tv":300.18,"id":25173012}]}]}
{"op":"mcm","clk":"11764785439","pt":1722690384961,"mc":[{"id":"1.231282333","rc":[{"batb":[[0,2.2,10]],"ltp":2.14,"tv":300.18,"id":25173012}]}]}
{"op":"mcm","clk":"11764785638","pt":1722690386094,"mc":[{"id":"1.231282333","rc":[{"batb":[[0,2.18,15.18],[1,2.16,15.44],[2,2.14,15.71]],"ltp":2.14,"tv":300.18,"id":25173012}]}]}
{"op":"mcm","clk":"11764786334","pt":1722690389765,"mc":[{"id":"1.231282333","rc":[{"batb":[[0,2.2,12],[1,2.18,15.18],[2,2.16,15.44]],"ltp":2.14,"tv":300.18,"id":25173012}]}]}
{"op":"mcm","clk":"11764786791","pt":1722690392244,"mc":[{"id":"1.231282333","rc":[{"batb":[[0,2.2,10]],"ltp":2.14,"tv":300.18,"id":25173012}]}]}
{"op":"mcm","clk":"11764786944","pt":1722690393873,"mc":[{"id":"1.231282333","rc":[{"batb":[[0,2.18,15.18],[1,2.16,15.44],[2,2.14,15.71]],"ltp":2.14,"tv":300.18,"id":25173012}]}]}
{"op":"mcm","clk":"11764788213","pt":1722690399293,"mc":[{"id":"1.231282333","rc":[{"batb":[[0,2.2,12],[1,2.18,15.18],[2,2.16,15.44]],"ltp":2.14,"tv":300.18,"id":25173012}]}]}
{"op":"mcm","clk":"11764788679","pt":1722690401509,"mc":[{"id":"1.231282333","rc":[{"batb":[[0,2.2,10]],"ltp":2.14,"tv":300.18,"id":25173012}]}]}
{"op":"mcm","clk":"11764788929","pt":1722690402622,"mc":[{"id":"1.231282333","rc":[{"batb":[[0,2.18,15.18],[1,2.16,15.44],[2,2.14,15.71]],"ltp":2.14,"tv":300.18,"id":25173012}]}]}
{"op":"mcm","clk":"11764789588","pt":1722690405824,"mc":[{"id":"1.231282333","rc":[{"batb":[[0,2.2,12],[1,2.18,15.18],[2,2.16,15.44]],"ltp":2.14,"tv":300.18,"id":25173012}]}]}
{"op":"mcm","clk":"11764790113","pt":1722690408074,"mc":[{"id":"1.231282333","rc":[{"batb":[[0,2.2,10]],"ltp":2.14,"tv":300.18,"id":25173012}]}]}
{"op":"mcm","clk":"11764790288","pt":1722690409079,"mc":[{"id":"1.231282333","rc":[{"batb":[[0,2.18,15.18],[1,2.16,15.44],[2,2.14,15.71]],"ltp":2.14,"tv":300.18,"id":25173012}]}]}
{"op":"mcm","clk":"11764791169","pt":1722690413910,"mc":[{"id":"1.231282333","rc":[{"batb":[[0,2.2,12],[1,2.18,15.18],[2,2.16,15.44]],"ltp":2.14,"tv":300.18,"id":25173012}]}]}
{"op":"mcm","clk":"11764791610","pt":1722690416319,"mc":[{"id":"1.231282333","rc":[{"batb":[[0,2.2,10]],"ltp":2.14,"tv":300.18,"id":25173012}]}]}
{"op":"mcm","clk":"11764791769","pt":1722690417208,"mc":[{"id":"1.231282333","rc":[{"batb":[[0,2.18,15.18],[1,2.16,15.44],[2,2.14,15.71]],"ltp":2.14,"tv":300.18,"id":25173012}]}]}
{"op":"mcm","clk":"11764792112","pt":1722690419080,"mc":[{"id":"1.231282333","rc":[{"batb":[[0,2.2,2],[1,2.18,15.18],[2,2.16,15.44]],"ltp":2.14,"tv":300.18,"id":25173012}]}]}
{"op":"mcm","clk":"11764792617","pt":1722690421714,"mc":[{"id":"1.231282333","rc":[{"batb":[[0,2.2,10]],"ltp":2.14,"tv":300.18,"id":25173012}]}]}
{"op":"mcm","clk":"11764793094","pt":1722690424324,"mc":[{"id":"1.231282333","rc":[{"batb":[[0,2.22,2],[1,2.2,10],[2,2.18,15.18]],"ltp":2.14,"tv":300.18,"id":25173012}]}]}
{"op":"mcm","clk":"11764793226","pt":1722690425135,"mc":[{"id":"1.231282333","rc":[{"batb":[[1,2.2,14.92]],"ltp":2.14,"tv":300.18,"id":25173012}]}]}
{"op":"mcm","clk":"11764793479","pt":1722690426415,"mc":[{"id":"1.231282333","rc":[{"batb":[[0,2.2,14.92],[1,2.18,15.18],[2,2.16,15.44]],"ltp":2.14,"tv":300.18,"id":25173012}]}]}
{"op":"mcm","clk":"11764793870","pt":1722690428615,"mc":[{"id":"1.231282333","rc":[{"batb":[[0,2.22,12],[1,2.2,14.92],[2,2.18,15.18]],"ltp":2.14,"tv":300.18,"id":25173012}]}]}
{"op":"mcm","clk":"11764794418","pt":1722690431509,"mc":[{"id":"1.231282333","rc":[{"batb":[[1,1.79,22.67]],"ltp":1.86,"tv":474.92,"id":71847983},{"batb":[[0,2.22,10]],"ltp":2.14,"tv":300.18,"id":25173012}]}]}
{"op":"mcm","clk":"11764794628","pt":1722690432639,"mc":[{"id":"1.231282333","rc":[{"batb":[[0,2.2,14.92],[1,2.18,15.18],[2,2.16,15.44]],"ltp":2.14,"tv":300.18,"id":25173012}]}]}
{"op":"mcm","clk":"11764795444","pt":1722690436714,"mc":[{"id":"1.231282333","rc":[{"batb":[[1,1.79,78.98]],"ltp":1.86,"tv":474.92,"id":71847983},{"batb":[[0,2.22,12],[1,2.2,14.92],[2,2.18,15.18]],"ltp":2.14,"tv":300.18,"id":25173012}]}]}
{"op":"mcm","clk":"11764795880","pt":1722690439038,"mc":[{"id":"1.231282333","rc":[{"batb":[[0,2.22,10]],"ltp":2.14,"tv":300.18,"id":25173012}]}]}
{"op":"mcm","clk":"11764796049","pt":1722690439954,"mc":[{"id":"1.231282333","rc":[{"batb":[[0,2.2,14.92],[1,2.18,15.18],[2,2.16,15.44]],"ltp":2.14,"tv":300.18,"id":25173012}]}]}
{"op":"mcm","clk":"11764799482","pt":1722690459445,"mc":[{"id":"1.231282333","rc":[{"batb":[[0,2.22,12],[1,2.2,14.92],[2,2.18,15.18]],"ltp":2.14,"tv":300.18,"id":25173012}]}]}
{"op":"mcm","clk":"11764799865","pt":1722690461732,"mc":[{"id":"1.231282333","rc":[{"batb":[[1,1.79,22.67]],"ltp":1.86,"tv":474.92,"id":71847983},{"batb":[[0,2.22,10]],"ltp":2.14,"tv":300.18,"id":25173012}]}]}
{"op":"mcm","clk":"11764800055","pt":1722690462851,"mc":[{"id":"1.231282333","rc":[{"batb":[[0,2.2,14.92],[1,2.18,15.18],[2,2.16,15.44]],"ltp":2.14,"tv":300.18,"id":25173012}]}]}
{"op":"mcm","clk":"11764800335","pt":1722690464557,"mc":[{"id":"1.231282333","rc":[{"batb":[[0,2.22,2],[1,2.2,14.92],[2,2.18,15.18]],"ltp":2.14,"tv":300.18,"id":25173012}]}]}
{"op":"mcm","clk":"11764800779","pt":1722690467056,"mc":[{"id":"1.231282333","rc":[{"batb":[[1,1.79,78.98]],"ltp":1.86,"tv":474.92,"id":71847983},{"batb":[[0,2.22,10]],"ltp":2.14,"tv":300.18,"id":25173012}]}]}
{"op":"mcm","clk":"11764801324","pt":1722690470350,"mc":[{"id":"1.231282333","rc":[{"batb":[[0,2.24,2]],"ltp":2.14,"tv":300.18,"id":25173012}]}]}
{"op":"mcm","clk":"11764801721","pt":1722690472578,"mc":[{"id":"1.231282333","rc":[{"batb":[[0,2.22,10]],"ltp":2.14,"tv":300.18,"id":25173012}]}]}
{"op":"mcm","clk":"11764802299","pt":1722690476169,"mc":[{"id":"1.231282333","rc":[{"batb":[[0,2.22,2]],"ltp":2.14,"tv":300.18,"id":25173012}]}]}
{"op":"mcm","clk":"11764802689","pt":1722690478661,"mc":[{"id":"1.231282333","rc":[{"batb":[[0,2.22,10]],"ltp":2.14,"tv":300.18,"id":25173012}]}]}
{"op":"mcm","clk":"11764803243","pt":1722690481981,"mc":[{"id":"1.231282333","rc":[{"batb":[[1,1.79,22.67]],"ltp":1.86,"tv":474.92,"id":71847983},{"batb":[[0,2.24,2]],"ltp":2.14,"tv":300.18,"id":25173012}]}]}
{"op":"mcm","clk":"11764803631","pt":1722690484291,"mc":[{"id":"1.231282333","rc":[{"batb":[[0,2.2,14.92],[1,2.18,15.18],[2,2.16,15.44]],"ltp":2.14,"tv":300.18,"id":25173012}]}]}
{"op":"mcm","clk":"11764803668","pt":1722690484450,"mc":[{"id":"1.231282333","rc":[{"batb":[[0,2.22,10],[1,2.2,14.92],[2,2.18,15.18]],"ltp":2.14,"tv":300.18,"id":25173012}]}]}
{"op":"mcm","clk":"11764804337","pt":1722690487979,"mc":[{"id":"1.231282333","rc":[{"batb":[[0,2.22,2]],"ltp":2.14,"tv":300.18,"id":25173012}]}]}
{"op":"mcm","clk":"11764804744","pt":1722690490391,"mc":[{"id":"1.231282333","rc":[{"batb":[[0,2.22,10]],"ltp":2.14,"tv":300.18,"id":25173012}]}]}
{"op":"mcm","clk":"11764805380","pt":1722690493780,"mc":[{"id":"1.231282333","rc":[{"batb":[[0,2.22,2]],"ltp":2.14,"tv":300.18,"id":25173012}]}]}
{"op":"mcm","clk":"11764805855","pt":1722690496286,"mc":[{"id":"1.231282333","rc":[{"batb":[[0,2.22,10]],"ltp":2.14,"tv":300.18,"id":25173012}]}]}
{"op":"mcm","clk":"11764806352","pt":1722690499080,"mc":[{"id":"1.231282333","rc":[{"batb":[[0,2.24,2],[1,2.22,10],[2,2.2,14.92]],"ltp":2.14,"tv":300.18,"id":25173012}]}]}
{"op":"mcm","clk":"11764806448","pt":1722690499599,"mc":[{"id":"1.231282333","rc":[{"batb":[[1,2.2,14.92],[2,2.18,15.18]],"ltp":2.14,"tv":300.18,"id":25173012}]}]}
{"op":"mcm","clk":"11764806898","pt":1722690502003,"mc":[{"id":"1.231282333","rc":[{"batb":[[1,1.79,78.98]],"ltp":1.86,"tv":474.92,"id":71847983},{"batb":[[0,2.22,10]],"ltp":2.14,"tv":300.18,"id":25173012}]}]}
{"op":"mcm","clk":"11764807517","pt":1722690505621,"mc":[{"id":"1.231282333","rc":[{"batb":[[0,2.22,2]],"ltp":2.14,"tv":300.18,"id":25173012}]}]}
{"op":"mcm","clk":"11764807995","pt":1722690508242,"mc":[{"id":"1.231282333","rc":[{"batb":[[0,2.22,10]],"ltp":2.14,"tv":300.18,"id":25173012}]}]}
{"op":"mcm","clk":"11764808629","pt":1722690511705,"mc":[{"id":"1.231282333","rc":[{"batb":[[0,2.22,2]],"ltp":2.14,"tv":300.18,"id":25173012}]}]}
{"op":"mcm","clk":"11764809074","pt":1722690514098,"mc":[{"id":"1.231282333","rc":[{"batb":[[0,2.22,10]],"ltp":2.14,"tv":300.18,"id":25173012}]}]}
{"op":"mcm","clk":"11764809446","pt":1722690516401,"mc":[{"id":"1.231282333","rc":[{"batb":[[0,2.24,2],[1,2.22,10],[2,2.2,14.92]],"ltp":2.14,"tv":300.18,"id":25173012}]}]}
{"op":"mcm","clk":"11764809522","pt":1722690516928,"mc":[{"id":"1.231282333","rc":[{"batb":[[1,1.79,22.67]],"ltp":1.86,"tv":474.92,"id":71847983}]}]}
{"op":"mcm","clk":"11764809637","pt":1722690517507,"mc":[{"id":"1.231282333","rc":[{"batb":[[1,2.2,14.92],[2,2.18,15.18]],"ltp":2.14,"tv":300.18,"id":25173012}]}]}
{"op":"mcm","clk":"11764809884","pt":1722690518778,"mc":[{"id":"1.231282333","rc":[{"batb":[[0,2.2,14.92],[1,2.18,15.18],[2,2.16,15.44]],"ltp":2.14,"tv":300.18,"id":25173012}]}]}
{"op":"mcm","clk":"11764810531","pt":1722690522192,"mc":[{"id":"1.231282333","rc":[{"batb":[[1,1.79,78.98]],"ltp":1.86,"tv":474.92,"id":71847983},{"batb":[[0,2.22,12],[1,2.2,14.92],[2,2.18,15.18]],"ltp":2.14,"tv":300.18,"id":25173012}]}]}
{"op":"mcm","clk":"11764810957","pt":1722690524519,"mc":[{"id":"1.231282333","rc":[{"batb":[[0,2.22,10]],"ltp":2.14,"tv":300.18,"id":25173012}]}]}
{"op":"mcm","clk":"11764811143","pt":1722690525515,"mc":[{"id":"1.231282333","rc":[{"batb":[[0,2.2,14.92],[1,2.18,15.18],[2,2.16,15.44]],"ltp":2.14,"tv":300.18,"id":25173012}]}]}
{"op":"mcm","clk":"11764812490","pt":1722690532427,"mc":[{"id":"1.231282333","rc":[{"batb":[[0,2.22,12],[1,2.2,14.92],[2,2.18,15.18]],"ltp":2.14,"tv":300.18,"id":25173012}]}]}
{"op":"mcm","clk":"11764813053","pt":1722690534939,"mc":[{"id":"1.231282333","rc":[{"batb":[[0,2.22,10]],"ltp":2.14,"tv":300.18,"id":25173012}]}]}
{"op":"mcm","clk":"11764813227","pt":1722690535839,"mc":[{"id":"1.231282333","rc":[{"batb":[[0,2.2,14.92],[1,2.18,15.18],[2,2.16,15.44]],"ltp":2.14,"tv":300.18,"id":25173012}]}]}
{"op":"mcm","clk":"11764814407","pt":1722690542137,"mc":[{"id":"1.231282333","rc":[{"batb":[[0,2.22,12],[1,2.2,14.92],[2,2.18,15.18]],"ltp":2.14,"tv":300.18,"id":25173012}]}]}
{"op":"mcm","clk":"11764814879","pt":1722690544566,"mc":[{"id":"1.231282333","rc":[{"batb":[[0,2.22,10]],"ltp":2.14,"tv":300.18,"id":25173012}]}]}
{"op":"mcm","clk":"11764815115","pt":1722690545539,"mc":[{"id":"1.231282333","rc":[{"batb":[[0,2.2,14.92],[1,2.18,15.18],[2,2.16,15.44]],"ltp":2.14,"tv":300.18,"id":25173012}]}]}
{"op":"mcm","clk":"11764815427","pt":1722690547147,"mc":[{"id":"1.231282333","rc":[{"batb":[[0,2.22,2],[1,2.2,14.92],[2,2.18,15.18]],"ltp":2.14,"tv":300.18,"id":25173012}]}]}
{"op":"mcm","clk":"11764816075","pt":1722690550345,"mc":[{"id":"1.231282333","rc":[{"batb":[[0,2.22,10]],"ltp":2.14,"tv":300.18,"id":25173012}]}]}
{"op":"mcm","clk":"11764816430","pt":1722690552166,"mc":[{"id":"1.231282333","rc":[{"batb":[[1,1.79,22.67]],"ltp":1.86,"tv":474.92,"id":71847983},{"batb":[[0,2.24,2],[1,2.22,10],[2,2.2,14.92]],"ltp":2.14,"tv":300.18,"id":25173012}]}]}
{"op":"mcm","clk":"11764816684","pt":1722690553541,"mc":[{"id":"1.231282333","rc":[{"batb":[[1,2.2,14.92],[2,2.18,15.18]],"ltp":2.14,"tv":300.18,"id":25173012}]}]}
{"op":"mcm","clk":"11764816884","pt":1722690554558,"mc":[{"id":"1.231282333","rc":[{"batb":[[0,2.2,14.92],[1,2.18,15.18],[2,2.16,15.44]],"ltp":2.14,"tv":300.18,"id":25173012}]}]}
{"op":"mcm","clk":"11764817400","pt":1722690557055,"mc":[{"id":"1.231282333","rc":[{"batb":[[1,1.79,78.98]],"ltp":1.86,"tv":474.92,"id":71847983},{"batb":[[0,2.22,12],[1,2.2,14.92],[2,2.18,15.18]],"ltp":2.14,"tv":300.18,"id":25173012}]}]}
{"op":"mcm","clk":"11764818110","pt":1722690560356,"mc":[{"id":"1.231282333","rc":[{"batb":[[0,2.2,14.92],[1,2.18,15.18],[2,2.16,15.44]],"ltp":2.14,"tv":300.18,"id":25173012}]}]}
{"op":"mcm","clk":"11764818780","pt":1722690563569,"mc":[{"id":"1.231282333","rc":[{"batb":[[0,2.22,12],[1,2.2,14.92],[2,2.18,15.18]],"ltp":2.14,"tv":300.18,"id":25173012}]}]}
{"op":"mcm","clk":"11764819312","pt":1722690566053,"mc":[{"id":"1.231282333","rc":[{"batb":[[0,2.22,10]],"ltp":2.14,"tv":300.18,"id":25173012}]}]}
{"op":"mcm","clk":"11764819518","pt":1722690567113,"mc":[{"id":"1.231282333","rc":[{"batb":[[1,1.79,22.67]],"ltp":1.86,"tv":474.92,"id":71847983},{"batb":[[0,2.2,14.92],[1,2.18,15.18],[2,2.16,15.44]],"ltp":2.14,"tv":300.18,"id":25173012}]}]}
{"op":"mcm","clk":"11764820304","pt":1722690571275,"mc":[{"id":"1.231282333","rc":[{"batb":[[0,2.22,12],[1,2.2,14.92],[2,2.18,15.18]],"ltp":2.14,"tv":300.18,"id":25173012}]}]}
{"op":"mcm","clk":"11764820696","pt":1722690573580,"mc":[{"id":"1.231282333","rc":[{"batb":[[0,2.22,10]],"ltp":2.14,"tv":300.18,"id":25173012}]}]}
{"op":"mcm","clk":"11764820879","pt":1722690574486,"mc":[{"id":"1.231282333","rc":[{"batb":[[0,2.2,14.92],[1,2.18,15.18],[2,2.16,15.44]],"ltp":2.14,"tv":300.18,"id":25173012}]}]}
{"op":"mcm","clk":"11764821381","pt":1722690577185,"mc":[{"id":"1.231282333","rc":[{"batb":[[1,1.79,78.98]],"ltp":1.86,"tv":474.92,"id":71847983},{"batb":[[0,2.22,12],[1,2.2,14.92],[2,2.18,15.18]],"ltp":2.14,"tv":300.18,"id":25173012}]}]}
{"op":"mcm","clk":"11764821794","pt":1722690579474,"mc":[{"id":"1.231282333","rc":[{"batb":[[0,2.22,10]],"ltp":2.14,"tv":300.18,"id":25173012}]}]}
{"op":"mcm","clk":"11764822035","pt":1722690580560,"mc":[{"id":"1.231282333","rc":[{"batb":[[0,2.2,14.92],[1,2.18,15.18],[2,2.16,15.44]],"ltp":2.14,"tv":300.18,"id":25173012}]}]}
{"op":"mcm","clk":"11764824518","pt":1722690593201,"mc":[{"id":"1.231282333","rc":[{"batb":[[0,2.22,12],[1,2.2,14.92],[2,2.18,15.18]],"ltp":2.14,"tv":300.18,"id":25173012}]}]}
{"op":"mcm","clk":"11764824956","pt":1722690595403,"mc":[{"id":"1.231282333","rc":[{"batb":[[0,2.22,10]],"ltp":2.14,"tv":300.18,"id":25173012}]}]}
{"op":"mcm","clk":"11764825135","pt":1722690596481,"mc":[{"id":"1.231282333","rc":[{"batb":[[0,2.2,14.92],[1,2.18,15.18],[2,2.16,15.44]],"ltp":2.14,"tv":300.18,"id":25173012}]}]}
{"op":"mcm","clk":"11764825801","pt":1722690599789,"mc":[{"id":"1.231282333","rc":[{"batb":[[0,2.22,12],[1,2.2,14.92],[2,2.18,15.18]],"ltp":2.14,"tv":300.18,"id":25173012}]}]}
{"op":"mcm","clk":"11764826250","pt":1722690602223,"mc":[{"id":"1.231282333","rc":[{"batb":[[1,1.79,22.67]],"ltp":1.86,"tv":474.92,"id":71847983},{"batb":[[0,2.22,10]],"ltp":2.14,"tv":300.18,"id":25173012}]}]}
{"op":"mcm","clk":"11764826448","pt":1722690603203,"mc":[{"id":"1.231282333","rc":[{"batb":[[0,2.2,14.92],[1,2.18,15.18],[2,2.16,15.44]],"ltp":2.14,"tv":300.18,"id":25173012}]}]}
{"op":"mcm","clk":"11764827213","pt":1722690607207,"mc":[{"id":"1.231282333","rc":[{"batb":[[1,1.79,78.98]],"ltp":1.86,"tv":474.92,"id":71847983}]}]}
{"op":"mcm","clk":"11764827255","pt":1722690607406,"mc":[{"id":"1.231282333","rc":[{"batb":[[0,2.22,12],[1,2.2,14.92],[2,2.18,15.18]],"ltp":2.14,"tv":300.18,"id":25173012}]}]}
{"op":"mcm","clk":"11764827820","pt":1722690609819,"mc":[{"id":"1.231282333","rc":[{"batb":[[0,2.22,10]],"ltp":2.14,"tv":300.18,"id":25173012}]}]}
{"op":"mcm","clk":"11764827989","pt":1722690610589,"mc":[{"id":"1.231282333","rc":[{"batb":[[0,2.2,14.92],[1,2.18,15.18],[2,2.16,15.44]],"ltp":2.14,"tv":300.18,"id":25173012}]}]}
{"op":"mcm","clk":"11764828652","pt":1722690613733,"mc":[{"id":"1.231282333","rc":[{"batb":[[0,2.22,12],[1,2.2,14.92],[2,2.18,15.18]],"ltp":2.14,"tv":300.18,"id":25173012}]}]}
{"op":"mcm","clk":"11764829476","pt":1722690617299,"mc":[{"id":"1.231282333","rc":[{"batb":[[1,1.79,22.67]],"ltp":1.86,"tv":474.92,"id":71847983},{"batb":[[0,2.2,14.92],[1,2.18,15.18],[2,2.16,15.44]],"ltp":2.14,"tv":300.18,"id":25173012}]}]}
{"op":"mcm","clk":"11764830352","pt":1722690621419,"mc":[{"id":"1.231282333","rc":[{"batb":[[0,2.22,12],[1,2.2,14.92],[2,2.18,15.18]],"ltp":2.14,"tv":300.18,"id":25173012}]}]}
{"op":"mcm","clk":"11764830798","pt":1722690623740,"mc":[{"id":"1.231282333","rc":[{"batb":[[0,2.22,10]],"ltp":2.14,"tv":300.18,"id":25173012}]}]}
{"op":"mcm","clk":"11764831015","pt":1722690624855,"mc":[{"id":"1.231282333","rc":[{"batb":[[0,2.2,14.92],[1,2.18,15.18],[2,2.16,15.44]],"ltp":2.14,"tv":300.18,"id":25173012}]}]}
{"op":"mcm","clk":"11764831467","pt":1722690627258,"mc":[{"id":"1.231282333","rc":[{"batb":[[1,1.79,78.98]],"ltp":1.86,"tv":474.92,"id":71847983}]}]}
